Workbook

Sheet はじめに
B2: 売店発注ツール
D5: 毎日やること これだけです
D6: シートの①②③を左から順にやれば、その日の発注は終わります。
D7: 黄色いセルだけ入力します。それ以外のセルは触らないでください。
C9: ①今日の在庫を貼る | D9: 在庫システムから出した「今日の在庫一覧CSV」を貼る
D10: CSVを開いて、見出し行を除いたデータ部分をコピーし、A2セルに貼り付けます。
D11: 貼り付けたら、シート上部の「該当行数」が0以外になっているか見てください。
D12: 0のままなら貼り付けに失敗しています。もう一度やり直してください。
C13: ②発注数を決める | D13: 帯を見ながら、黄色の「発注数」に数字を入れる
D14: 帯が赤い商品は、今日発注しないと在庫が切れます。
D15: 迷ったら「推奨(ケース)」に出ている数字をそのまま入れて構いません。
D16: 数字を入れると帯が伸びます。伸びた先まで在庫が持つ、という意味です。
D17: 右上に「保管スペースの埋まり具合」が出ます。100%を超えると入りきりません。
C18: ③発注書 | D18: 発注先を選んで、印刷する
D19: ②で入れた数量がここに集まります。発注先を選ぶとその仕入先の分だけになります。
D20: そのまま印刷して、いつもの方法で発注してください。
D22: 発注したら「発注管理」シートに記録します。入荷したら入荷日も入れてください。
C24: 発注のしくみ | D24: 「何を計算しているのか」を図で見る（最初に1回だけ読めば十分です）
D25: 定数がどこにあるか、そこから発注数がどう出るかを1枚にまとめてあります。
D27: 色の意味
D28: 黄色のセル … 入力するところ
D29: 白・灰色のセル … 自動で計算されるところ（触らない）
D30: 赤い帯 … 今日発注しないと間に合わない
D31: オレンジの帯 … 次の発注までに在庫が切れる
D32: 緑の帯 … 在庫に余裕がある
D34: 社員の方がやること
C35: 月1回_前回の在庫を貼る | D35: 月に1回、2ヶ月前の在庫一覧CSVを貼り替える
D36: 今日の在庫と突き合わせて、期間の消費量を出します。
D37: 商品が入れ替わっても発注から漏れないよう、両方の商品を見ています。
C38: 随時_動員を入れる | D38: 大きな作品の公開週など、来場者の読みが変わる日に入力する
D39: 空欄の日は劇場の標準来場者数が自動で使われます。毎日入れる必要はありません。
C40: ダッシュボード | D40: 劇場全体の状況を確認する
C41: 商品マスタ | D41: リードタイム・最低ロット・PI値を登録する
C42: 定数マスタ | D42: 劇場・規模区分・季節の係数・保管設備を決める
D43: 人が決める数字はこの1枚に集めてあります。
D44: ⑤保管設備に冷蔵庫やストッカーを登録すると、収容ケース数が自動で集計され、
D45: ②の「保管スペースの埋まり具合」に反映されます。
C46: 設定（最初に1回） | D46: 対象の劇場と、発注数の算出基準を選ぶ
D48: 発注数はどう決まっているか
D49: この商品は1日に何個くらい減るか（実績、または来場者予測 × PI値）
...

Sheet 発注のしくみ
B2: 発注のしくみ
B3: このツールが何をしているかの説明です。最初に1回読めば、あとは②発注数を決めるシートだけ見れば発注できます。
B5: 発注は3つのことしかしていません
B6: ① 決めておく | M6: ➡ | O6: ② 今の在庫を読む | Z6: ➡ | AB6: ③ 足りない分だけ発注
B7: 「この商品は、いつも何個持っておくか」を先に決めておきます。これが定数です。毎日は変わりません。 | O7: 在庫システムのCSVを貼るだけです。総数（＝ケース×入数＋バラ）が、そのまま今の在庫になります。 | AB7: 持っておくべき数から、今の在庫と発注済みの分を引きます。残った数が、今日発注する数です。
B10: 置き場所： 定数マスタ ／ 商品マスタ | O10: 置き場所： ①今日の在庫を貼る | AB10: 置き場所： ②発注数を決める → ③発注書
B11: 触るのは社員だけ。ふだんは開きません。 | O11: 毎日やるのはここだけです。 | AB11: 数字は自動で出ます。そのまま入れて構いません。
B13: 1. 定数はどこにあるか
B14: 人が決める数字は、この2枚にしかありません。「今の値」はあなたの劇場の現在値です（設定シートで選んだ劇場）。
B15: 決めておくこと | J15: 置き場所 | P15: ブロック | V15: 今の値 | AB15: 見直す頻度 | AH15: 誰が決める
B16: 劇場の規模と、ドリンクの提供方式 | J16: 定数マスタ | P16: ① 劇場マスタ | V16: =IF('設定（最初に1回）'!$C$10="","未設定",'設定（最初に1回）'!$C$10&" ／ "&'設定（最初に1回）'!$C$11) -> 大規模 ／ 1杯売り | AB16: 開店時・方式の変更時 | AH16: 本社・支配人
B17: 規模ごとの標準来場者数 | J17: 定数マスタ | P17: ② 規模区分 | V17: ='設定（最初に1回）'!$C$14 -> 3000 | AB17: 年1回 | AH17: 本社
B18: 安全在庫日数（何日ぶん余裕を持つか） | J18: 定数マスタ | P18: ② 規模区分 | V18: ='設定（最初に1回）'!$C$12 -> 4 | AB18: 年1回 | AH18: 本社
B19: 月ごとの繁閑（季節係数） | J19: 定数マスタ | P19: ③ 月別係数 | V19: ='設定（最初に1回）'!$C$15 -> 1.45 | AB19: 年1回 | AH19: 本社
B20: GW・大型作品公開などの特別期間 | J20: 定数マスタ | P20: ④ 特別期間 | V20: =COUNTIF(定数マスタ!$W$6:$W$25,"?*")&" 件 登録済み" -> 3 件 登録済み | AB20: 都度 | AH20: 支配人・副支配人
B21: 冷蔵庫・ストッカーの容量（常温／冷蔵／冷凍） | J21: 定数マスタ | P21: ⑤ 保管設備 | V21: =IF('設定（最初に1回）'!$C$4="","",TEXT(SUMIFS(定数マスタ!$G$110:$G$309,定数マスタ!$B$110:$B$309,'設定（最初に1回）'!$C$4,定数マスタ!$C$110:$C$309,"常温"),"#,##0")&" ／ "&TEXT(SUMIFS(定数マスタ!$G$110:$G$309,定数マスタ!$B$110:$B$309,'設定（最初に1回）'!$C$4,定数マスタ!$C$110:$C$309,"冷蔵"),"#,##0")&" ／ "&TEXT(SUMIFS(定数マスタ!$G$110:$G$309,定数マスタ!$B$110:$B$309,'設定（最初に1回）'!$C$4,定数マスタ!$C$110:$C$309,"冷凍"),"#,##0")&" ケース") -> 2,400 ／ 720 ／ 320 ケース | AB21: 設備の入れ替え時 | AH21: 支配人・副支配人
B22: 発注できる曜日（グループごと） | J22: 定数マスタ | P22: ⑥ 発注サイクル | V22: ="冷凍 "&IFERROR(INDEX(定数マスタ!$S$110:$S$119,MATCH("冷凍品",定数マスタ!$J$110:$J$119,0)),"")&"日 ／ 包材 "&IFERROR(INDEX(定数マスタ!$S$110:$S$119,MATCH("常温包材",定数マスタ!$J$110:$J$119,0)),"")&"日" -> 冷凍 2.3日 ／ 包材 7日 | AB22: 便が変わったとき | AH22: 本社
B23: 入数・単価・リードタイム・最低ロット | J23: 商品マスタ | P23: （商品ごと） | V23: =SUMPRODUCT(--(商品マスタ!$B$6:$B$1005<>""))&" 商品 登録済み" -> 132 商品 登録済み | AB23: 商品の入れ替え時 | AH23: 社員
B24: 商品の保管区分と発注グループ | J24: 商品マスタ | P24: （商品ごと） | V24: =SUMPRODUCT(--(商品マスタ!$L$6:$L$1005<>""))&" 商品 設定済み" -> 132 商品 設定済み | AB24: 商品の入れ替え時 | AH24: 社員
B25: PI値（来場者100人あたりの消費数） | J25: 商品マスタ | P25: （商品ごと） | V25: =IF('設定（最初に1回）'!$C$9="実績消費","使っていません",SUMPRODUCT(--(商品マスタ!$M$6:$M$1005<>""))&" 商品 設定済み") -> 使っていません | AB25: PI値を使うときだけ | AH25: 社員
B27: ※ 黄色いシート名が置き場所です。定数はこの2枚以外にはありません。②発注数を決めるシートや発注計算シートに、直接数字を書き込む必要はありません。
B29: 2. その定数から、発注数が出るまで
B30: 1商品を選ぶと、その商品の実際の数字で順番に追えます。空欄のままなら、いま一番多く発注が必要な商品を自動で表示します。
B31: 追いかける商品 | R31: ▼から選べます。選び直すと下の数字がすべて入れ替わります。 | AN31: =IF($F$31="",IFERROR(INDEX(発注計算!$D$6:$D$405,MATCH(MAX(発注計算!$AH$6:$AH$405),発注計算!$AH$6:$AH$405,0)),""),$F$31) -> Ｒｅｉｓｔポップコーン豆
AN32: =IFERROR(MATCH($AN$31,発注計算!$D$6:$D$405,0),0) -> 40
D33: 見ている数字 | O33: 値 | T33: どこから来た数字か
B34: 定数 | D34: 1日にどれだけ減るか | O34: =IF($AN$32=0,"",INDEX(発注計算!$S$6:$S$405,$AN$32)) -> 3.7868852 | T34: =IF('設定（最初に1回）'!$C$9="実績消費","①今日の在庫 と 月1回_前回の在庫 の差から計算","商品マスタ の PI値 × 随時_動員を入れる の来場者予測") -> ①今日の在庫 と 月1回_前回の在庫 の差から計算
B35: 定数 | D35: 届くまでの日数（リードタイム） | O35: =IF($AN$32=0,"",INDEX(発注計算!$I$6:$I$405,$AN$32)) -> 2 | T35: ="商品マスタ の L/T日数" -> 商品マスタ の L/T日数
B36: 定数 | D36: 次の発注までの日数（発注サイクル） | O36: =IF($AN$32=0,"",INDEX(発注計算!$AG$6:$AG$405,$AN$32)) -> 7 | T36: =IF($AN$32=0,"","定数マスタ ⑥発注サイクル グループ："&INDEX(発注計算!$AF$6:$AF$405,$AN$32)) -> 定数マスタ ⑥発注サイクル グループ：その他常温
B37: 定数 | D37: 切らさないための余裕（安全在庫） | O37: =IF($AN$32=0,"",INDEX(発注計算!$U$6:$U$405,$AN$32)) -> 16 | T37: ="定数マスタ ②規模区分 の安全在庫日数 "&TEXT('設定（最初に1回）'!$C$12,"0.0")&"日ぶん" -> 定数マスタ ②規模区分 の安全在庫日数 4.0日ぶん
B38: ＝ | D38: 持っておくべき数（発注点） | O38: =IF($AN$32=0,"",INDEX(発注計算!$V$6:$V$405,$AN$32)) -> 51 | T38: ="1日に減る数 ×（届くまで＋次の発注まで）＋ 安全在庫" -> 1日に減る数 ×（届くまで＋次の発注まで）＋ 安全在庫
B39: 在庫 | D39: いま在庫にある数 | O39: =IF($AN$32=0,"",INDEX(発注計算!$K$6:$K$405,$AN$32)) -> 9 | T39: ="①今日の在庫を貼る（CSVの総数）" -> ①今日の在庫を貼る（CSVの総数）
B40: 在庫 | D40: 発注済みで、まだ届いていない数 | O40: =IF($AN$32=0,"",INDEX(発注計算!$W$6:$W$405,$AN$32)) -> 0 | T40: ="発注管理 の 発注済み" -> 発注管理 の 発注済み
B41: ＝ | D41: 足りない数 | O41: =IF($AN$32=0,"",INDEX(発注計算!$X$6:$X$405,$AN$32)) -> 42 | T41: ="持っておくべき数 − いまの在庫 − 発注済み" -> 持っておくべき数 − いまの在庫 − 発注済み
B42: 発注 | D42: 1ケースに何個入っているか（入数） | O42: =IF($AN$32=0,"",INDEX(発注計算!$G$6:$G$405,$AN$32)) -> 1 | T42: ="商品マスタ の 入数" -> 商品マスタ の 入数
B43: ＝ | D43: 発注する数（ケース） | O43: =IF($AN$32=0,"",INDEX(発注計算!$Y$6:$Y$405,$AN$32)) -> 42 | T43: ="足りない数 ÷ 入数 を切り上げ。最低ロットの単位に丸めます" -> 足りない数 ÷ 入数 を切り上げ。最低ロットの単位に丸めます
B45: 同じことを図にすると | AN45: =IF($AN$32=0,0,N(INDEX(発注計算!$V$6:$V$405,$AN$32))) -> 51
B46: 帯全体が「持っておくべき数（発注点）」です。緑がいまの在庫、黄が発注済みで届く分、赤が足りていない分＝今日発注する分です。 | AN46: =IF($AN$32=0,0,MAX(0,N(INDEX(発注計算!$K$6:$K$405,$AN$32)))) -> 9
AN47: =IF($AN$32=0,0,N(INDEX(発注計算!$W$6:$W$405,$AN$32))) -> 0
B48: 1 | C48: 2 | D48: 3 | E48: 4 | F48: 5 | G48: 6 | H48: 7 | I48: 8 | J48: 9 | K48: 10 | L48: 11 | M48: 12 | N48: 13 | O48: 14 | P48: 15 | Q48: 16 | R48: 17 | S48: 18 | T48: 19 | U48: 20 | V48: 21 | W48: 22 | X48: 23 | Y48: 24 | Z48: 25 | AA48: 26 | AB48: 27 | AC48: 28 | AD48: 29 | AE48: 30 | AF48: 31 | AG48: 32 | AH48: 33 | AI48: 34 | AJ48: 35 | AK48: 36 | AN48: =IF($AN$45<=0,36,MIN(36,ROUND($AN$46/$AN$45*36,0))) -> 6
...

Sheet ①今日の在庫を貼る
B2: 今日の在庫を貼る | H2: =IF(COUNTIF($B$6:$B$10005,'設定（最初に1回）'!$C$4)=0,"✖ まだ貼れていません","✔ "&COUNTIF($B$6:$B$10005,'設定（最初に1回）'!$C$4)&"行 読み込めました") -> ✔ 134行 読み込めました
B3: 在庫システムから出力した、今日の在庫一覧CSVです。これが理論在庫になります。 | H3: =IF(COUNTIF($B$6:$B$10005,'設定（最初に1回）'!$C$4)=0,"CSVの見出し行を除いたデータを A6 セルに貼り付けてください。貼ったのに0のままなら、劇場コードが数値になっています。","対象劇場：" & '設定（最初に1回）'!$C$4 & " " & '設定（最初に1回）'!$C$5) -> 対象劇場：0761 新宿
B4: CSVの見出し行を除いたデータを、A6 セルに貼り付けてください。
A5: 対象日付 | B5: 劇場コード | C5: 劇場名 | D5: 支払先コード | E5: 支払先名 | F5: 大分類コード | G5: 小分類コード | H5: 商品分類名 | I5: 商品コード | J5: 商品名 | K5: 入数 | L5: 在庫数ケース | M5: 在庫数バラ | N5: 総数 | O5: 規定数 | P5: 資産廃棄 | Q5: 税抜単価 | R5: 仕入税区分 | S5: 仕入税率 | U5: 連番(自動)
A6: 20260501 | B6: 0761 | C6: 新宿 | D6: 10400001 | E6: 株式会社 カクヤス | F6: 01 | G6: 04 | H6: アルコール | I6: 1812000008585 | J6: プレミアムモルツ ２０Ｌ | K6: 1 | L6: 4 | M6: 0 | N6: 4 | P6: 0 | Q6: 11300 | R6: 外税 | S6: 0.1 | U6: =IF($B6='設定（最初に1回）'!$C$4,N(U5)+1,N(U5)) -> 1
A7: 20260501 | B7: 0761 | C7: 新宿 | D7: 10400001 | E7: 株式会社 カクヤス | F7: 01 | G7: 04 | H7: アルコール | I7: 1812000010991 | J7: ミオネット ベビーボトル２００ｍ | K7: 24 | L7: 0 | M7: 0 | N7: 0 | P7: 0 | Q7: 587 | R7: 外税 | S7: 0.1 | U7: =IF($B7='設定（最初に1回）'!$C$4,N(U6)+1,N(U6)) -> 2
A8: 20260501 | B8: 0761 | C8: 新宿 | D8: 10400001 | E8: 株式会社 カクヤス | F8: 01 | G8: 04 | H8: アルコール | I8: 1812000011745 | J8: フォルタン リトラル 赤 | K8: 48 | L8: 0 | M8: 10 | N8: 10 | P8: 0 | Q8: 357 | R8: 外税 | S8: 0.1 | U8: =IF($B8='設定（最初に1回）'!$C$4,N(U7)+1,N(U7)) -> 3
A9: 20260501 | B9: 0761 | C9: 新宿 | D9: 10400001 | E9: 株式会社 カクヤス | F9: 01 | G9: 04 | H9: アルコール | I9: 1812000011752 | J9: フォルタン リトラル 白 | K9: 48 | L9: 0 | M9: 3 | N9: 3 | P9: 0 | Q9: 357 | R9: 外税 | S9: 0.1 | U9: =IF($B9='設定（最初に1回）'!$C$4,N(U8)+1,N(U8)) -> 4
A10: 20260501 | B10: 0761 | C10: 新宿 | D10: 10400001 | E10: 株式会社 カクヤス | F10: 01 | G10: 04 | H10: アルコール | I10: 1812000013343 | J10: フレシネコルドンネグロ２００ｍｌ | K10: 24 | L10: 2 | M10: 19 | N10: 67 | P10: 0 | Q10: 585 | R10: 外税 | S10: 0.1 | U10: =IF($B10='設定（最初に1回）'!$C$4,N(U9)+1,N(U9)) -> 5
A11: 20260501 | B11: 0761 | C11: 新宿 | D11: 10400001 | E11: 株式会社 カクヤス | F11: 01 | G11: 04 | H11: アルコール | I11: 1813000187270 | J11: サントリー角ハイボール | K11: 30 | L11: 6 | M11: 2 | N11: 182 | P11: 0 | Q11: 118 | R11: 外税 | S11: 0.1 | U11: =IF($B11='設定（最初に1回）'!$C$4,N(U10)+1,N(U10)) -> 6
A12: 20260501 | B12: 0761 | C12: 新宿 | D12: 19903001 | E12: オザックス株式会社 | F12: 01 | G12: 01 | H12: コールド | I12: 1812000000237 | J12: アイスティシロップ | K12: 1 | L12: 2 | M12: 0 | N12: 2 | P12: 0 | Q12: 3756 | R12: 外税 | S12: 0.08 | U12: =IF($B12='設定（最初に1回）'!$C$4,N(U11)+1,N(U11)) -> 7
A13: 20260501 | B13: 0761 | C13: 新宿 | D13: 19903001 | E13: オザックス株式会社 | F13: 01 | G13: 01 | H13: コールド | I13: 1812000000251 | J13: 烏龍茶１０倍シロップ | K13: 1 | L13: 2 | M13: 0 | N13: 2 | P13: 0 | Q13: 4382 | R13: 外税 | S13: 0.08 | U13: =IF($B13='設定（最初に1回）'!$C$4,N(U12)+1,N(U12)) -> 8
A14: 20260501 | B14: 0761 | C14: 新宿 | D14: 19903001 | E14: オザックス株式会社 | F14: 01 | G14: 01 | H14: コールド | I14: 1812000007441 | J14: ミニッツメイドオレンジＦＫＡ | K14: 1 | L14: 0 | M14: 0 | N14: 0 | P14: 0 | Q14: 2890 | R14: 外税 | S14: 0.08 | U14: =IF($B14='設定（最初に1回）'!$C$4,N(U13)+1,N(U13)) -> 9
A15: 20260501 | B15: 0761 | C15: 新宿 | D15: 19903001 | E15: オザックス株式会社 | F15: 01 | G15: 01 | H15: コールド | I15: 1812000013169 | J15: ミニッツメイドアップル | K15: 1 | L15: 2 | M15: 0 | N15: 2 | P15: 0 | Q15: 3636 | R15: 外税 | S15: 0.08 | U15: =IF($B15='設定（最初に1回）'!$C$4,N(U14)+1,N(U14)) -> 10
A16: 20260501 | B16: 0761 | C16: 新宿 | D16: 19903001 | E16: オザックス株式会社 | F16: 01 | G16: 01 | H16: コールド | I16: 4902102081283 | J16: ＰＸＴ爽健美茶１Ｇ | K16: 1 | L16: 73 | M16: 0 | N16: 73 | P16: 0 | Q16: 3756 | R16: 外税 | S16: 0.08 | U16: =IF($B16='設定（最初に1回）'!$C$4,N(U15)+1,N(U15)) -> 11
A17: 20260501 | B17: 0761 | C17: 新宿 | D17: 19903001 | E17: オザックス株式会社 | F17: 01 | G17: 01 | H17: コールド | I17: 4902102112901 | J17: フラットＢＩＢメロンＳ２．５Ｇ | K17: 1 | L17: 83 | M17: 0 | N17: 83 | P17: 0 | Q17: 7510 | R17: 外税 | S17: 0.08 | U17: =IF($B17='設定（最初に1回）'!$C$4,N(U16)+1,N(U16)) -> 12
... A310: 20260501 | B310: 0902 | C310: 郊外シネマ | D310: 10400001 | E310: 株式会社 カクヤス | F310: 01 | G310: 04 | H310: アルコール | I310: 9809020000002 | J310: （新商品）コラボカップ | K310: 1 | L310: 65 | M310: 0 | N310: 65 | P310: 0 | Q310: 118 | R310: 外税 | S310: 0.1 | U310: =IF($B310='設定（最初に1回）'!$C$4,N(U309)+1,N(U309)) -> 134
U311: =IF($B311='設定（最初に1回）'!$C$4,N(U310)+1,N(U310)) -> 134
U312: =IF($B312='設定（最初に1回）'!$C$4,N(U311)+1,N(U311)) -> 134
U313: =IF($B313='設定（最初に1回）'!$C$4,N(U312)+1,N(U312)) -> 134
U314: =IF($B314='設定（最初に1回）'!$C$4,N(U313)+1,N(U313)) -> 134
U315: =IF($B315='設定（最初に1回）'!$C$4,N(U314)+1,N(U314)) -> 134
U316: =IF($B316='設定（最初に1回）'!$C$4,N(U315)+1,N(U315)) -> 134
U317: =IF($B317='設定（最初に1回）'!$C$4,N(U316)+1,N(U316)) -> 134
U318: =IF($B318='設定（最初に1回）'!$C$4,N(U317)+1,N(U317)) -> 134
U319: =IF($B319='設定（最初に1回）'!$C$4,N(U318)+1,N(U318)) -> 134
U320: =IF($B320='設定（最初に1回）'!$C$4,N(U319)+1,N(U319)) -> 134
U321: =IF($B321='設定（最初に1回）'!$C$4,N(U320)+1,N(U320)) -> 134
U322: =IF($B322='設定（最初に1回）'!$C$4,N(U321)+1,N(U321)) -> 134
... U10005: =IF($B10005='設定（最初に1回）'!$C$4,N(U10004)+1,N(U10004)) -> 134

Sheet ②発注数を決める
B2: タイムテーブル
B4: 今日の結論 | G4: 発注予定額（税抜） | L4: 保管スペースの埋まり具合（今の在庫＋発注ぶん ÷ 収容ケース数）
B5: =COUNTIF(②発注数を決める!$G$10:$G$409,"今日が期限")+COUNTIF(②発注数を決める!$G$10:$G$409,"要発注") -> 45 | D5: 品目に発注が必要です | G5: =SUM(②発注数を決める!$K$10:$K$409) -> 158719 | L5: 常温 | P5: 冷蔵 | T5: 冷凍
L6: =IF(IFERROR(INDEX(定数マスタ!$I$6:$I$105,MATCH('設定（最初に1回）'!$C$4,定数マスタ!$B$6:$B$105,0)),0)=0,"収容未設定",(SUMIF(発注計算!$AD$6:$AD$405,"常温",発注計算!$AE$6:$AE$405)+SUMIF(発注計算!$AD$6:$AD$405,"常温",②発注数を決める!$J$10:$J$409))/IFERROR(INDEX(定数マスタ!$I$6:$I$105,MATCH('設定（最初に1回）'!$C$4,定数マスタ!$B$6:$B$105,0)),0)) -> 0.67458333 | P6: =IF(IFERROR(INDEX(定数マスタ!$J$6:$J$105,MATCH('設定（最初に1回）'!$C$4,定数マスタ!$B$6:$B$105,0)),0)=0,"収容未設定",(SUMIF(発注計算!$AD$6:$AD$405,"冷蔵",発注計算!$AE$6:$AE$405)+SUMIF(発注計算!$AD$6:$AD$405,"冷蔵",②発注数を決める!$J$10:$J$409))/IFERROR(INDEX(定数マスタ!$J$6:$J$105,MATCH('設定（最初に1回）'!$C$4,定数マスタ!$B$6:$B$105,0)),0)) -> 0.71805556 | T6: =IF(IFERROR(INDEX(定数マスタ!$K$6:$K$105,MATCH('設定（最初に1回）'!$C$4,定数マスタ!$B$6:$B$105,0)),0)=0,"収容未設定",(SUMIF(発注計算!$AD$6:$AD$405,"冷凍",発注計算!$AE$6:$AE$405)+SUMIF(発注計算!$AD$6:$AD$405,"冷凍",②発注数を決める!$J$10:$J$409))/IFERROR(INDEX(定数マスタ!$K$6:$K$105,MATCH('設定（最初に1回）'!$C$4,定数マスタ!$B$6:$B$105,0)),0)) -> 0.915625
B7: =IF($B$5=0,"すべての商品が発注サイクルを越える在庫を持っています。","うち "&COUNTIF(②発注数を決める!$G$10:$G$409,"今日が期限")&"品目は今日発注しないとリードタイムに間に合いません。 "&COUNTIF(②発注数を決める!$G$10:$G$409,"要発注")&"品目は次の発注サイクル（"&'設定（最初に1回）'!$C$13&"日）内に在庫が切れます。") -> うち 36品目は今日発注しないとリードタイムに間に合いません。 9品目は次の発注サイクル（7日）内に在庫が切れます。 | L7: =IF(IFERROR(INDEX(定数マスタ!$I$6:$I$105,MATCH('設定（最初に1回）'!$C$4,定数マスタ!$B$6:$B$105,0)),0)=0,"定数マスタ⑤に設備を登録してください",(SUMIF(発注計算!$AD$6:$AD$405,"常温",発注計算!$AE$6:$AE$405)+SUMIF(発注計算!$AD$6:$AD$405,"常温",②発注数を決める!$J$10:$J$409))&" / "&IFERROR(INDEX(定数マスタ!$I$6:$I$105,MATCH('設定（最初に1回）'!$C$4,定数マスタ!$B$6:$B$105,0)),0)&"ケース") -> 1619 / 2400ケース | P7: =IF(IFERROR(INDEX(定数マスタ!$J$6:$J$105,MATCH('設定（最初に1回）'!$C$4,定数マスタ!$B$6:$B$105,0)),0)=0,"定数マスタ⑤に設備を登録してください",(SUMIF(発注計算!$AD$6:$AD$405,"冷蔵",発注計算!$AE$6:$AE$405)+SUMIF(発注計算!$AD$6:$AD$405,"冷蔵",②発注数を決める!$J$10:$J$409))&" / "&IFERROR(INDEX(定数マスタ!$J$6:$J$105,MATCH('設定（最初に1回）'!$C$4,定数マスタ!$B$6:$B$105,0)),0)&"ケース") -> 517 / 720ケース | T7: =IF(IFERROR(INDEX(定数マスタ!$K$6:$K$105,MATCH('設定（最初に1回）'!$C$4,定数マスタ!$B$6:$B$105,0)),0)=0,"定数マスタ⑤に設備を登録してください",(SUMIF(発注計算!$AD$6:$AD$405,"冷凍",発注計算!$AE$6:$AE$405)+SUMIF(発注計算!$AD$6:$AD$405,"冷凍",②発注数を決める!$J$10:$J$409))&" / "&IFERROR(INDEX(定数マスタ!$K$6:$K$105,MATCH('設定（最初に1回）'!$C$4,定数マスタ!$B$6:$B$105,0)),0)&"ケース") -> 293 / 320ケース
B8: 自動 | C8: 自動 | D8: 自動 | E8: 自動 | F8: 自動 | G8: 自動 | H8: 自動 | I8: 自動 | J8: 入力 | K8: 自動 | L8: 1 | M8: 2 | N8: 3 | O8: 4 | P8: 5 | Q8: 6 | R8: 7 | S8: 8 | T8: 9 | U8: 10 | V8: 11 | W8: 12 | X8: 13 | Y8: 14
B9: No | C9: 商品名 | D9: 分類 | E9: 残り日数 | F9: デッドライン | G9: 状態 | H9: 発注後日数 | I9: 推奨(ケース) | J9: 発注数 | K9: 金額 | L9: =IF('設定（最初に1回）'!$C$6="","",'設定（最初に1回）'!$C$6+0) -> 46143 | M9: =IF('設定（最初に1回）'!$C$6="","",'設定（最初に1回）'!$C$6+1) -> 46144 | N9: =IF('設定（最初に1回）'!$C$6="","",'設定（最初に1回）'!$C$6+2) -> 46145 | O9: =IF('設定（最初に1回）'!$C$6="","",'設定（最初に1回）'!$C$6+3) -> 46146 | P9: =IF('設定（最初に1回）'!$C$6="","",'設定（最初に1回）'!$C$6+4) -> 46147 | Q9: =IF('設定（最初に1回）'!$C$6="","",'設定（最初に1回）'!$C$6+5) -> 46148 | R9: =IF('設定（最初に1回）'!$C$6="","",'設定（最初に1回）'!$C$6+6) -> 46149 | S9: =IF('設定（最初に1回）'!$C$6="","",'設定（最初に1回）'!$C$6+7) -> 46150 | T9: =IF('設定（最初に1回）'!$C$6="","",'設定（最初に1回）'!$C$6+8) -> 46151 | U9: =IF('設定（最初に1回）'!$C$6="","",'設定（最初に1回）'!$C$6+9) -> 46152 | V9: =IF('設定（最初に1回）'!$C$6="","",'設定（最初に1回）'!$C$6+10) -> 46153 | W9: =IF('設定（最初に1回）'!$C$6="","",'設定（最初に1回）'!$C$6+11) -> 46154 | X9: =IF('設定（最初に1回）'!$C$6="","",'設定（最初に1回）'!$C$6+12) -> 46155 | Y9: =IF('設定（最初に1回）'!$C$6="","",'設定（最初に1回）'!$C$6+13) -> 46156 | Z9: 発注書用
B10: 1 | C10: =IF(発注計算!$C6="","",発注計算!$D6) -> プレミアムモルツ ２０Ｌ | D10: =IF(発注計算!$C6="","",発注計算!$E6) -> アルコール | E10: =IF(発注計算!$C6="","",発注計算!$T6) -> 2.3461538 | F10: =IF(ISNUMBER($E10),$E10-N(発注計算!$I6),"") -> 0.34615385 | G10: =IF(発注計算!$C6="","",IF(NOT(ISNUMBER($F10)),"データなし",IF($F10<=0,"今日が期限",IF($F10<=N(発注計算!$AG6),"要発注","余裕")))) -> 要発注 | H10: =IF(OR(発注計算!$C6="",NOT(ISNUMBER(発注計算!$S6)),発注計算!$S6<=0),"",(発注計算!$K6+N($J10)*N(発注計算!$G6))/発注計算!$S6) -> 5.8653846 | I10: =IF(発注計算!$C6="","",発注計算!$Y6) -> 19 | J10: 6 | K10: =IF($J10="","",N($J10)*N(発注計算!$H6)) -> 67800 | Z10: =IF(OR(N($J10)<=0,AND(③発注書!$C$5<>"すべて",発注計算!$F6<>③発注書!$C$5)),N(Z9),N(Z9)+1) -> 1
B11: 2 | C11: =IF(発注計算!$C7="","",発注計算!$D7) -> ミオネット ベビーボトル２００ｍ | D11: =IF(発注計算!$C7="","",発注計算!$E7) -> アルコール | E11: =IF(発注計算!$C7="","",発注計算!$T7) -> 0 | F11: =IF(ISNUMBER($E11),$E11-N(発注計算!$I7),"") -> -3 | G11: =IF(発注計算!$C7="","",IF(NOT(ISNUMBER($F11)),"データなし",IF($F11<=0,"今日が期限",IF($F11<=N(発注計算!$AG7),"要発注","余裕")))) -> 今日が期限 | H11: =IF(OR(発注計算!$C7="",NOT(ISNUMBER(発注計算!$S7)),発注計算!$S7<=0),"",(発注計算!$K7+N($J11)*N(発注計算!$G7))/発注計算!$S7) -> 2196 | I11: =IF(発注計算!$C7="","",発注計算!$Y7) -> 1 | J11: 3 | K11: =IF($J11="","",N($J11)*N(発注計算!$H7)) -> 1761 | Z11: =IF(OR(N($J11)<=0,AND(③発注書!$C$5<>"すべて",発注計算!$F7<>③発注書!$C$5)),N(Z10),N(Z10)+1) -> 2
B12: 3 | C12: =IF(発注計算!$C8="","",発注計算!$D8) -> フォルタン リトラル 赤 | D12: =IF(発注計算!$C8="","",発注計算!$E8) -> アルコール | E12: =IF(発注計算!$C8="","",発注計算!$T8) -> 13.863636 | F12: =IF(ISNUMBER($E12),$E12-N(発注計算!$I8),"") -> 10.863636 | G12: =IF(発注計算!$C8="","",IF(NOT(ISNUMBER($F12)),"データなし",IF($F12<=0,"今日が期限",IF($F12<=N(発注計算!$AG8),"要発注","余裕")))) -> 余裕 | H12: =IF(OR(発注計算!$C8="",NOT(ISNUMBER(発注計算!$S8)),発注計算!$S8<=0),"",(発注計算!$K8+N($J12)*N(発注計算!$G8))/発注計算!$S8) -> 679.31818 | I12: =IF(発注計算!$C8="","",発注計算!$Y8) -> 5 | J12: 10 | K12: =IF($J12="","",N($J12)*N(発注計算!$H8)) -> 3570 | Z12: =IF(OR(N($J12)<=0,AND(③発注書!$C$5<>"すべて",発注計算!$F8<>③発注書!$C$5)),N(Z11),N(Z11)+1) -> 3
B13: 4 | C13: =IF(発注計算!$C9="","",発注計算!$D9) -> フォルタン リトラル 白 | D13: =IF(発注計算!$C9="","",発注計算!$E9) -> アルコール | E13: =IF(発注計算!$C9="","",発注計算!$T9) -> 2.3461538 | F13: =IF(ISNUMBER($E13),$E13-N(発注計算!$I9),"") -> -0.65384615 | G13: =IF(発注計算!$C9="","",IF(NOT(ISNUMBER($F13)),"データなし",IF($F13<=0,"今日が期限",IF($F13<=N(発注計算!$AG9),"要発注","余裕")))) -> 今日が期限 | H13: =IF(OR(発注計算!$C9="",NOT(ISNUMBER(発注計算!$S9)),発注計算!$S9<=0),"",(発注計算!$K9+N($J13)*N(発注計算!$G9))/発注計算!$S9) -> 2.3461538 | I13: =IF(発注計算!$C9="","",発注計算!$Y9) -> 2 | K13: =IF($J13="","",N($J13)*N(発注計算!$H9)) | Z13: =IF(OR(N($J13)<=0,AND(③発注書!$C$5<>"すべて",発注計算!$F9<>③発注書!$C$5)),N(Z12),N(Z12)+1) -> 3
B14: 5 | C14: =IF(発注計算!$C10="","",発注計算!$D10) -> フレシネコルドンネグロ２００ｍｌ | D14: =IF(発注計算!$C10="","",発注計算!$E10) -> アルコール | E14: =IF(発注計算!$C10="","",発注計算!$T10) -> 20.232673 | F14: =IF(ISNUMBER($E14),$E14-N(発注計算!$I10),"") -> 16.232673 | G14: =IF(発注計算!$C10="","",IF(NOT(ISNUMBER($F14)),"データなし",IF($F14<=0,"今日が期限",IF($F14<=N(発注計算!$AG10),"要発注","余裕")))) -> 余裕 | H14: =IF(OR(発注計算!$C10="",NOT(ISNUMBER(発注計算!$S10)),発注計算!$S10<=0),"",(発注計算!$K10+N($J14)*N(発注計算!$G10))/発注計算!$S10) -> 49.222772 | I14: =IF(発注計算!$C10="","",発注計算!$Y10) -> 0 | J14: 4 | K14: =IF($J14="","",N($J14)*N(発注計算!$H10)) -> 2340 | Z14: =IF(OR(N($J14)<=0,AND(③発注書!$C$5<>"すべて",発注計算!$F10<>③発注書!$C$5)),N(Z13),N(Z13)+1) -> 4
B15: 6 | C15: =IF(発注計算!$C11="","",発注計算!$D11) -> サントリー角ハイボール | D15: =IF(発注計算!$C11="","",発注計算!$E11) -> アルコール | E15: =IF(発注計算!$C11="","",発注計算!$T11) -> 10.644295 | F15: =IF(ISNUMBER($E15),$E15-N(発注計算!$I11),"") -> 7.6442953 | G15: =IF(発注計算!$C11="","",IF(NOT(ISNUMBER($F15)),"データなし",IF($F15<=0,"今日が期限",IF($F15<=N(発注計算!$AG11),"要発注","余裕")))) -> 余裕 | H15: =IF(OR(発注計算!$C11="",NOT(ISNUMBER(発注計算!$S11)),発注計算!$S11<=0),"",(発注計算!$K11+N($J15)*N(発注計算!$G11))/発注計算!$S11) -> 10.644295 | I15: =IF(発注計算!$C11="","",発注計算!$Y11) -> 2 | K15: =IF($J15="","",N($J15)*N(発注計算!$H11)) | Z15: =IF(OR(N($J15)<=0,AND(③発注書!$C$5<>"すべて",発注計算!$F11<>③発注書!$C$5)),N(Z14),N(Z14)+1) -> 4
B16: 7 | C16: =IF(発注計算!$C12="","",発注計算!$D12) -> アイスティシロップ | D16: =IF(発注計算!$C12="","",発注計算!$E12) -> コールド | E16: =IF(発注計算!$C12="","",発注計算!$T12) -> 1.2708333 | F16: =IF(ISNUMBER($E16),$E16-N(発注計算!$I12),"") -> -0.72916667 | G16: =IF(発注計算!$C12="","",IF(NOT(ISNUMBER($F16)),"データなし",IF($F16<=0,"今日が期限",IF($F16<=N(発注計算!$AG12),"要発注","余裕")))) -> 今日が期限 | H16: =IF(OR(発注計算!$C12="",NOT(ISNUMBER(発注計算!$S12)),発注計算!$S12<=0),"",(発注計算!$K12+N($J16)*N(発注計算!$G12))/発注計算!$S12) -> 1.2708333 | I16: =IF(発注計算!$C12="","",発注計算!$Y12) -> 12 | K16: =IF($J16="","",N($J16)*N(発注計算!$H12)) | Z16: =IF(OR(N($J16)<=0,AND(③発注書!$C$5<>"すべて",発注計算!$F12<>③発注書!$C$5)),N(Z15),N(Z15)+1) -> 4
B17: 8 | C17: =IF(発注計算!$C13="","",発注計算!$D13) -> 烏龍茶１０倍シロップ | D17: =IF(発注計算!$C13="","",発注計算!$E13) -> コールド | E17: =IF(発注計算!$C13="","",発注計算!$T13) -> 1.7941176 | F17: =IF(ISNUMBER($E17),$E17-N(発注計算!$I13),"") -> -3.2058824 | G17: =IF(発注計算!$C13="","",IF(NOT(ISNUMBER($F17)),"データなし",IF($F17<=0,"今日が期限",IF($F17<=N(発注計算!$AG13),"要発注","余裕")))) -> 今日が期限 | H17: =IF(OR(発注計算!$C13="",NOT(ISNUMBER(発注計算!$S13)),発注計算!$S13<=0),"",(発注計算!$K13+N($J17)*N(発注計算!$G13))/発注計算!$S13) -> 8.9705882 | I17: =IF(発注計算!$C13="","",発注計算!$Y13) -> 12 | J17: 8 | K17: =IF($J17="","",N($J17)*N(発注計算!$H13)) -> 35056 | Z17: =IF(OR(N($J17)<=0,AND(③発注書!$C$5<>"すべて",発注計算!$F13<>③発注書!$C$5)),N(Z16),N(Z16)+1) -> 5
B18: 9 | C18: =IF(発注計算!$C14="","",発注計算!$D14) -> ミニッツメイドオレンジＦＫＡ | D18: =IF(発注計算!$C14="","",発注計算!$E14) -> コールド | E18: =IF(発注計算!$C14="","",発注計算!$T14) -> 0 | F18: =IF(ISNUMBER($E18),$E18-N(発注計算!$I14),"") -> -3 | G18: =IF(発注計算!$C14="","",IF(NOT(ISNUMBER($F18)),"データなし",IF($F18<=0,"今日が期限",IF($F18<=N(発注計算!$AG14),"要発注","余裕")))) -> 今日が期限 | H18: =IF(OR(発注計算!$C14="",NOT(ISNUMBER(発注計算!$S14)),発注計算!$S14<=0),"",(発注計算!$K14+N($J18)*N(発注計算!$G14))/発注計算!$S14) -> 0 | I18: =IF(発注計算!$C14="","",発注計算!$Y14) -> 2 | K18: =IF($J18="","",N($J18)*N(発注計算!$H14)) | Z18: =IF(OR(N($J18)<=0,AND(③発注書!$C$5<>"すべて",発注計算!$F14<>③発注書!$C$5)),N(Z17),N(Z17)+1) -> 5
B19: 10 | C19: =IF(発注計算!$C15="","",発注計算!$D15) -> ミニッツメイドアップル | D19: =IF(発注計算!$C15="","",発注計算!$E15) -> コールド | E19: =IF(発注計算!$C15="","",発注計算!$T15) -> 61 | F19: =IF(ISNUMBER($E19),$E19-N(発注計算!$I15),"") -> 58 | G19: =IF(発注計算!$C15="","",IF(NOT(ISNUMBER($F19)),"データなし",IF($F19<=0,"今日が期限",IF($F19<=N(発注計算!$AG15),"要発注","余裕")))) -> 余裕 | H19: =IF(OR(発注計算!$C15="",NOT(ISNUMBER(発注計算!$S15)),発注計算!$S15<=0),"",(発注計算!$K15+N($J19)*N(発注計算!$G15))/発注計算!$S15) -> 61 | I19: =IF(発注計算!$C15="","",発注計算!$Y15) -> 0 | K19: =IF($J19="","",N($J19)*N(発注計算!$H15)) | Z19: =IF(OR(N($J19)<=0,AND(③発注書!$C$5<>"すべて",発注計算!$F15<>③発注書!$C$5)),N(Z18),N(Z18)+1) -> 5
B20: 11 | C20: =IF(発注計算!$C16="","",発注計算!$D16) -> ＰＸＴ爽健美茶１Ｇ | D20: =IF(発注計算!$C16="","",発注計算!$E16) -> コールド | E20: =IF(発注計算!$C16="","",発注計算!$T16) -> 42.409524 | F20: =IF(ISNUMBER($E20),$E20-N(発注計算!$I16),"") -> 37.409524 | G20: =IF(発注計算!$C16="","",IF(NOT(ISNUMBER($F20)),"データなし",IF($F20<=0,"今日が期限",IF($F20<=N(発注計算!$AG16),"要発注","余裕")))) -> 余裕 | H20: =IF(OR(発注計算!$C16="",NOT(ISNUMBER(発注計算!$S16)),発注計算!$S16<=0),"",(発注計算!$K16+N($J20)*N(発注計算!$G16))/発注計算!$S16) -> 43.571429 | I20: =IF(発注計算!$C16="","",発注計算!$Y16) -> 0 | J20: 2 | K20: =IF($J20="","",N($J20)*N(発注計算!$H16)) -> 7512 | Z20: =IF(OR(N($J20)<=0,AND(③発注書!$C$5<>"すべて",発注計算!$F16<>③発注書!$C$5)),N(Z19),N(Z19)+1) -> 6
B21: 12 | C21: =IF(発注計算!$C17="","",発注計算!$D17) -> フラットＢＩＢメロンＳ２．５Ｇ | D21: =IF(発注計算!$C17="","",発注計算!$E17) -> コールド | E21: =IF(発注計算!$C17="","",発注計算!$T17) -> 120.54762 | F21: =IF(ISNUMBER($E21),$E21-N(発注計算!$I17),"") -> 113.54762 | G21: =IF(発注計算!$C17="","",IF(NOT(ISNUMBER($F21)),"データなし",IF($F21<=0,"今日が期限",IF($F21<=N(発注計算!$AG17),"要発注","余裕")))) -> 余裕 | H21: =IF(OR(発注計算!$C17="",NOT(ISNUMBER(発注計算!$S17)),発注計算!$S17<=0),"",(発注計算!$K17+N($J21)*N(発注計算!$G17))/発注計算!$S17) -> 120.54762 | I21: =IF(発注計算!$C17="","",発注計算!$Y17) -> 0 | K21: =IF($J21="","",N($J21)*N(発注計算!$H17)) | Z21: =IF(OR(N($J21)<=0,AND(③発注書!$C$5<>"すべて",発注計算!$F17<>③発注書!$C$5)),N(Z20),N(Z20)+1) -> 6
B22: 13 | C22: =IF(発注計算!$C18="","",発注計算!$D18) -> フラットＢＩＢコカコーラ２．５Ｇ | D22: =IF(発注計算!$C18="","",発注計算!$E18) -> コールド | E22: =IF(発注計算!$C18="","",発注計算!$T18) -> 76.604651 | F22: =IF(ISNUMBER($E22),$E22-N(発注計算!$I18),"") -> 72.604651 | G22: =IF(発注計算!$C18="","",IF(NOT(ISNUMBER($F22)),"データなし",IF($F22<=0,"今日が期限",IF($F22<=N(発注計算!$AG18),"要発注","余裕")))) -> 余裕 | H22: =IF(OR(発注計算!$C18="",NOT(ISNUMBER(発注計算!$S18)),発注計算!$S18<=0),"",(発注計算!$K18+N($J22)*N(発注計算!$G18))/発注計算!$S18) -> 76.604651 | I22: =IF(発注計算!$C18="","",発注計算!$Y18) -> 0 | K22: =IF($J22="","",N($J22)*N(発注計算!$H18)) | Z22: =IF(OR(N($J22)<=0,AND(③発注書!$C$5<>"すべて",発注計算!$F18<>③発注書!$C$5)),N(Z21),N(Z21)+1) -> 6
B23: 14 | C23: =IF(発注計算!$C19="","",発注計算!$D19) -> フラットＢＩＢコーラゼロ２．５Ｇ | D23: =IF(発注計算!$C19="","",発注計算!$E19) -> コールド | E23: =IF(発注計算!$C19="","",発注計算!$T19) -> 123.96774 | F23: =IF(ISNUMBER($E23),$E23-N(発注計算!$I19),"") -> 121.96774 | G23: =IF(発注計算!$C19="","",IF(NOT(ISNUMBER($F23)),"データなし",IF($F23<=0,"今日が期限",IF($F23<=N(発注計算!$AG19),"要発注","余裕")))) -> 余裕 | H23: =IF(OR(発注計算!$C19="",NOT(ISNUMBER(発注計算!$S19)),発注計算!$S19<=0),"",(発注計算!$K19+N($J23)*N(発注計算!$G19))/発注計算!$S19) -> 133.80645 | I23: =IF(発注計算!$C19="","",発注計算!$Y19) -> 0 | J23: 5 | K23: =IF($J23="","",N($J23)*N(発注計算!$H19)) -> 40680 | Z23: =IF(OR(N($J23)<=0,AND(③発注書!$C$5<>"すべて",発注計算!$F19<>③発注書!$C$5)),N(Z22),N(Z22)+1) -> 7
B24: 15 | C24: =IF(発注計算!$C20="","",発注計算!$D20) -> フラットＢＩＢジンジャー２．５Ｇ | D24: =IF(発注計算!$C20="","",発注計算!$E20) -> コールド | E24: =IF(発注計算!$C20="","",発注計算!$T20) -> 24.206349 | F24: =IF(ISNUMBER($E24),$E24-N(発注計算!$I20),"") -> 17.206349 | G24: =IF(発注計算!$C20="","",IF(NOT(ISNUMBER($F24)),"データなし",IF($F24<=0,"今日が期限",IF($F24<=N(発注計算!$AG20),"要発注","余裕")))) -> 余裕 | H24: =IF(OR(発注計算!$C20="",NOT(ISNUMBER(発注計算!$S20)),発注計算!$S20<=0),"",(発注計算!$K20+N($J24)*N(発注計算!$G20))/発注計算!$S20) -> 24.206349 | I24: =IF(発注計算!$C20="","",発注計算!$Y20) -> 0 | K24: =IF($J24="","",N($J24)*N(発注計算!$H20)) | Z24: =IF(OR(N($J24)<=0,AND(③発注書!$C$5<>"すべて",発注計算!$F20<>③発注書!$C$5)),N(Z23),N(Z23)+1) -> 7
B25: 16 | C25: =IF(発注計算!$C21="","",発注計算!$D21) -> フラットＢＩＢスプライト２．５Ｇ | D25: =IF(発注計算!$C21="","",発注計算!$E21) -> コールド | E25: =IF(発注計算!$C21="","",発注計算!$T21) -> 0.66304348 | F25: =IF(ISNUMBER($E25),$E25-N(発注計算!$I21),"") -> -6.3369565 | G25: =IF(発注計算!$C21="","",IF(NOT(ISNUMBER($F25)),"データなし",IF($F25<=0,"今日が期限",IF($F25<=N(発注計算!$AG21),"要発注","余裕")))) -> 今日が期限 | H25: =IF(OR(発注計算!$C21="",NOT(ISNUMBER(発注計算!$S21)),発注計算!$S21<=0),"",(発注計算!$K21+N($J25)*N(発注計算!$G21))/発注計算!$S21) -> 0.66304348 | I25: =IF(発注計算!$C21="","",発注計算!$Y21) -> 21 | K25: =IF($J25="","",N($J25)*N(発注計算!$H21)) | Z25: =IF(OR(N($J25)<=0,AND(③発注書!$C$5<>"すべて",発注計算!$F21<>③発注書!$C$5)),N(Z24),N(Z24)+1) -> 7
B26: 17 | C26: =IF(発注計算!$C22="","",発注計算!$D22) -> フラットＢＩＢカルピス２．５Ｇ | D26: =IF(発注計算!$C22="","",発注計算!$E22) -> コールド | E26: =IF(発注計算!$C22="","",発注計算!$T22) -> 3.2972973 | F26: =IF(ISNUMBER($E26),$E26-N(発注計算!$I22),"") -> -1.7027027 | G26: =IF(発注計算!$C22="","",IF(NOT(ISNUMBER($F26)),"データなし",IF($F26<=0,"今日が期限",IF($F26<=N(発注計算!$AG22),"要発注","余裕")))) -> 今日が期限 | H26: =IF(OR(発注計算!$C22="",NOT(ISNUMBER(発注計算!$S22)),発注計算!$S22<=0),"",(発注計算!$K22+N($J26)*N(発注計算!$G22))/発注計算!$S22) -> 3.2972973 | I26: =IF(発注計算!$C22="","",発注計算!$Y22) -> 6 | K26: =IF($J26="","",N($J26)*N(発注計算!$H22)) | Z26: =IF(OR(N($J26)<=0,AND(③発注書!$C$5<>"すべて",発注計算!$F22<>③発注書!$C$5)),N(Z25),N(Z25)+1) -> 7
B27: 18 | C27: =IF(発注計算!$C23="","",発注計算!$D23) -> （コスタ）新コーヒー豆 | D27: =IF(発注計算!$C23="","",発注計算!$E23) -> コーヒー | E27: =IF(発注計算!$C23="","",発注計算!$T23) -> 53.906977 | F27: =IF(ISNUMBER($E27),$E27-N(発注計算!$I23),"") -> 46.906977 | G27: =IF(発注計算!$C23="","",IF(NOT(ISNUMBER($F27)),"データなし",IF($F27<=0,"今日が期限",IF($F27<=N(発注計算!$AG23),"要発注","余裕")))) -> 余裕 | H27: =IF(OR(発注計算!$C23="",NOT(ISNUMBER(発注計算!$S23)),発注計算!$S23<=0),"",(発注計算!$K23+N($J27)*N(発注計算!$G23))/発注計算!$S23) -> 53.906977 | I27: =IF(発注計算!$C23="","",発注計算!$Y23) -> 0 | K27: =IF($J27="","",N($J27)*N(発注計算!$H23)) | Z27: =IF(OR(N($J27)<=0,AND(③発注書!$C$5<>"すべて",発注計算!$F23<>③発注書!$C$5)),N(Z26),N(Z26)+1) -> 7
B28: 19 | C28: =IF(発注計算!$C24="","",発注計算!$D24) -> めいらく北海道特選３．６牛乳 | D28: =IF(発注計算!$C24="","",発注計算!$E24) -> コーヒー | E28: =IF(発注計算!$C24="","",発注計算!$T24) -> 7.5703013 | F28: =IF(ISNUMBER($E28),$E28-N(発注計算!$I24),"") -> 2.5703013 | G28: =IF(発注計算!$C24="","",IF(NOT(ISNUMBER($F28)),"データなし",IF($F28<=0,"今日が期限",IF($F28<=N(発注計算!$AG24),"要発注","余裕")))) -> 要発注 | H28: =IF(OR(発注計算!$C24="",NOT(ISNUMBER(発注計算!$S24)),発注計算!$S24<=0),"",(発注計算!$K24+N($J28)*N(発注計算!$G24))/発注計算!$S24) -> 7.5703013 | I28: =IF(発注計算!$C24="","",発注計算!$Y24) -> 20 | K28: =IF($J28="","",N($J28)*N(発注計算!$H24)) | Z28: =IF(OR(N($J28)<=0,AND(③発注書!$C$5<>"すべて",発注計算!$F24<>③発注書!$C$5)),N(Z27),N(Z27)+1) -> 7
B29: 20 | C29: =IF(発注計算!$C25="","",発注計算!$D25) -> ミルクティーパウダー | D29: =IF(発注計算!$C25="","",発注計算!$E25) -> ホット | E29: =IF(発注計算!$C25="","",発注計算!$T25) -> 60.164384 | F29: =IF(ISNUMBER($E29),$E29-N(発注計算!$I25),"") -> 56.164384 | G29: =IF(発注計算!$C25="","",IF(NOT(ISNUMBER($F29)),"データなし",IF($F29<=0,"今日が期限",IF($F29<=N(発注計算!$AG25),"要発注","余裕")))) -> 余裕 | H29: =IF(OR(発注計算!$C25="",NOT(ISNUMBER(発注計算!$S25)),発注計算!$S25<=0),"",(発注計算!$K25+N($J29)*N(発注計算!$G25))/発注計算!$S25) -> 60.164384 | I29: =IF(発注計算!$C25="","",発注計算!$Y25) -> 0 | K29: =IF($J29="","",N($J29)*N(発注計算!$H25)) | Z29: =IF(OR(N($J29)<=0,AND(③発注書!$C$5<>"すべて",発注計算!$F25<>③発注書!$C$5)),N(Z28),N(Z28)+1) -> 7
B30: 21 | C30: =IF(発注計算!$C26="","",発注計算!$D26) -> ココアカントリーＫオフパウダー | D30: =IF(発注計算!$C26="","",発注計算!$E26) -> ホット | E30: =IF(発注計算!$C26="","",発注計算!$T26) -> 109.8 | F30: =IF(ISNUMBER($E30),$E30-N(発注計算!$I26),"") -> 104.8 | G30: =IF(発注計算!$C26="","",IF(NOT(ISNUMBER($F30)),"データなし",IF($F30<=0,"今日が期限",IF($F30<=N(発注計算!$AG26),"要発注","余裕")))) -> 余裕 | H30: =IF(OR(発注計算!$C26="",NOT(ISNUMBER(発注計算!$S26)),発注計算!$S26<=0),"",(発注計算!$K26+N($J30)*N(発注計算!$G26))/発注計算!$S26) -> 109.8 | I30: =IF(発注計算!$C26="","",発注計算!$Y26) -> 0 | K30: =IF($J30="","",N($J30)*N(発注計算!$H26)) | Z30: =IF(OR(N($J30)<=0,AND(③発注書!$C$5<>"すべて",発注計算!$F26<>③発注書!$C$5)),N(Z29),N(Z29)+1) -> 7
B31: 22 | C31: =IF(発注計算!$C27="","",発注計算!$D27) -> ミレイユ抹茶オレ パウダー | D31: =IF(発注計算!$C27="","",発注計算!$E27) -> ホット | E31: =IF(発注計算!$C27="","",発注計算!$T27) -> 77.636364 | F31: =IF(ISNUMBER($E31),$E31-N(発注計算!$I27),"") -> 75.636364 | G31: =IF(発注計算!$C27="","",IF(NOT(ISNUMBER($F31)),"データなし",IF($F31<=0,"今日が期限",IF($F31<=N(発注計算!$AG27),"要発注","余裕")))) -> 余裕 | H31: =IF(OR(発注計算!$C27="",NOT(ISNUMBER(発注計算!$S27)),発注計算!$S27<=0),"",(発注計算!$K27+N($J31)*N(発注計算!$G27))/発注計算!$S27) -> 77.636364 | I31: =IF(発注計算!$C27="","",発注計算!$Y27) -> 0 | K31: =IF($J31="","",N($J31)*N(発注計算!$H27)) | Z31: =IF(OR(N($J31)<=0,AND(③発注書!$C$5<>"すべて",発注計算!$F27<>③発注書!$C$5)),N(Z30),N(Z30)+1) -> 7
B32: 23 | C32: =IF(発注計算!$C28="","",発注計算!$D28) -> 台湾レモン ナタデココ 入り | D32: =IF(発注計算!$C28="","",発注計算!$E28) -> その他ドリンク | E32: =IF(発注計算!$C28="","",発注計算!$T28) -> 46.345345 | F32: =IF(ISNUMBER($E32),$E32-N(発注計算!$I28),"") -> 39.345345 | G32: =IF(発注計算!$C28="","",IF(NOT(ISNUMBER($F32)),"データなし",IF($F32<=0,"今日が期限",IF($F32<=N(発注計算!$AG28),"要発注","余裕")))) -> 余裕 | H32: =IF(OR(発注計算!$C28="",NOT(ISNUMBER(発注計算!$S28)),発注計算!$S28<=0),"",(発注計算!$K28+N($J32)*N(発注計算!$G28))/発注計算!$S28) -> 46.345345 | I32: =IF(発注計算!$C28="","",発注計算!$Y28) -> 0 | K32: =IF($J32="","",N($J32)*N(発注計算!$H28)) | Z32: =IF(OR(N($J32)<=0,AND(③発注書!$C$5<>"すべて",発注計算!$F28<>③発注書!$C$5)),N(Z31),N(Z31)+1) -> 7
B33: 24 | C33: =IF(発注計算!$C29="","",発注計算!$D29) -> 黒糖ブラックタピオカ | D33: =IF(発注計算!$C29="","",発注計算!$E29) -> その他ドリンク | E33: =IF(発注計算!$C29="","",発注計算!$T29) -> 5.3203008 | F33: =IF(ISNUMBER($E33),$E33-N(発注計算!$I29),"") -> -1.6796992 | G33: =IF(発注計算!$C29="","",IF(NOT(ISNUMBER($F33)),"データなし",IF($F33<=0,"今日が期限",IF($F33<=N(発注計算!$AG29),"要発注","余裕")))) -> 今日が期限 | H33: =IF(OR(発注計算!$C29="",NOT(ISNUMBER(発注計算!$S29)),発注計算!$S29<=0),"",(発注計算!$K29+N($J33)*N(発注計算!$G29))/発注計算!$S29) -> 5.3203008 | I33: =IF(発注計算!$C29="","",発注計算!$Y29) -> 1 | K33: =IF($J33="","",N($J33)*N(発注計算!$H29)) | Z33: =IF(OR(N($J33)<=0,AND(③発注書!$C$5<>"すべて",発注計算!$F29<>③発注書!$C$5)),N(Z32),N(Z32)+1) -> 7
B34: 25 | C34: =IF(発注計算!$C30="","",発注計算!$D30) -> とろけるフローズンゼリマスカット | D34: =IF(発注計算!$C30="","",発注計算!$E30) -> その他ドリンク | E34: =IF(発注計算!$C30="","",発注計算!$T30) -> 61 | F34: =IF(ISNUMBER($E34),$E34-N(発注計算!$I30),"") -> 58 | G34: =IF(発注計算!$C30="","",IF(NOT(ISNUMBER($F34)),"データなし",IF($F34<=0,"今日が期限",IF($F34<=N(発注計算!$AG30),"要発注","余裕")))) -> 余裕 | H34: =IF(OR(発注計算!$C30="",NOT(ISNUMBER(発注計算!$S30)),発注計算!$S30<=0),"",(発注計算!$K30+N($J34)*N(発注計算!$G30))/発注計算!$S30) -> 61 | I34: =IF(発注計算!$C30="","",発注計算!$Y30) -> 5 | K34: =IF($J34="","",N($J34)*N(発注計算!$H30)) | Z34: =IF(OR(N($J34)<=0,AND(③発注書!$C$5<>"すべて",発注計算!$F30<>③発注書!$C$5)),N(Z33),N(Z33)+1) -> 7
B35: 26 | C35: =IF(発注計算!$C31="","",発注計算!$D31) -> 超ストロベリーフローズン | D35: =IF(発注計算!$C31="","",発注計算!$E31) -> その他ドリンク | E35: =IF(発注計算!$C31="","",発注計算!$T31) -> 1.6397849 | F35: =IF(ISNUMBER($E35),$E35-N(発注計算!$I31),"") -> -2.3602151 | G35: =IF(発注計算!$C31="","",IF(NOT(ISNUMBER($F35)),"データなし",IF($F35<=0,"今日が期限",IF($F35<=N(発注計算!$AG31),"要発注","余裕")))) -> 今日が期限 | H35: =IF(OR(発注計算!$C31="",NOT(ISNUMBER(発注計算!$S31)),発注計算!$S31<=0),"",(発注計算!$K31+N($J35)*N(発注計算!$G31))/発注計算!$S31) -> 1.6397849 | I35: =IF(発注計算!$C31="","",発注計算!$Y31) -> 1 | K35: =IF($J35="","",N($J35)*N(発注計算!$H31)) | Z35: =IF(OR(N($J35)<=0,AND(③発注書!$C$5<>"すべて",発注計算!$F31<>③発注書!$C$5)),N(Z34),N(Z34)+1) -> 7
... B409: 400 | C409: =IF(発注計算!$C405="","",発注計算!$D405) | D409: =IF(発注計算!$C405="","",発注計算!$E405) | E409: =IF(発注計算!$C405="","",発注計算!$T405) | F409: =IF(ISNUMBER($E409),$E409-N(発注計算!$I405),"") | G409: =IF(発注計算!$C405="","",IF(NOT(ISNUMBER($F409)),"データなし",IF($F409<=0,"今日が期限",IF($F409<=N(発注計算!$AG405),"要発注","余裕")))) | H409: =IF(OR(発注計算!$C405="",NOT(ISNUMBER(発注計算!$S405)),発注計算!$S405<=0),"",(発注計算!$K405+N($J409)*N(発注計算!$G405))/発注計算!$S405) | I409: =IF(発注計算!$C405="","",発注計算!$Y405) | K409: =IF($J409="","",N($J409)*N(発注計算!$H405)) | Z409: =IF(OR(N($J409)<=0,AND(③発注書!$C$5<>"すべて",発注計算!$F405<>③発注書!$C$5)),N(Z408),N(Z408)+1) -> 7
M411: 今日が期限（今日発注しないと間に合わない）
M412: 要発注（発注サイクル内に在庫が切れる）
M413: 余裕
M414: 発注すると伸びる分
L415: │ | M415: 発注デッドライン（在庫が尽きる日 − リードタイム）
L417: 横軸は当日基準日からの14日間です。帯の長さがその商品の在庫が持つ日数を表します。
...

Sheet ③発注書
B2: 発 注 書
B3: タイムテーブルで入れた発注数がここに集まります。発注先を選んで印刷してください。
N4: 発注先の選択肢
B5: 発注先 | C5: すべて | G5: ← ここを選ぶ | N5: すべて
B6: 発注日 | C6: =IF('設定（最初に1回）'!$C$6="","",TEXT('設定（最初に1回）'!$C$6,"yyyy/m/d")&"（"&CHOOSE(WEEKDAY('設定（最初に1回）'!$C$6),"日","月","火","水","木","金","土")&"）") -> 2026/5/1（金） | G6: 自動 | N6: オザックス株式会社
B7: 発注元 | C7: =IF('設定（最初に1回）'!$C$5="","",'設定（最初に1回）'!$C$4&" "&'設定（最初に1回）'!$C$5) -> 0761 新宿 | G7: 自動 | N7: 株式会社 カクヤス
B8: 担当者 | C8: ='設定（最初に1回）'!$C$16 -> 笹川 | G8: 自動 | N8: エパックス（株）
B9: 自動 | C9: 自動 | D9: 自動 | E9: 自動 | F9: 自動 | G9: 自動 | H9: 自動 | I9: 自動 | J9: 自動 | N9: 松竹株式会社（コンセ）
B10: No | C10: 仕入先 | D10: 商品コード | E10: 商品名 | F10: 発注単位 | G10: 入数 | H10: 発注数 | I10: 単価 | J10: 金額 | N10: 株式会社ムービック【コンセ】
B11: =IF(1<=MAX(②発注数を決める!$Z$10:$Z$409),1,"") -> 1 | C11: =IF($B11="","",IFERROR(INDEX(発注計算!$F$6:$F$405,MATCH(1,②発注数を決める!$Z$10:$Z$409,0)),"")) -> 株式会社 カクヤス | D11: =IF($B11="","",IFERROR(INDEX(発注計算!$C$6:$C$405,MATCH(1,②発注数を決める!$Z$10:$Z$409,0))&"","")) -> 1812000008585 | E11: =IF($B11="","",IFERROR(INDEX(②発注数を決める!$C$10:$C$409,MATCH(1,②発注数を決める!$Z$10:$Z$409,0))&"","")) -> プレミアムモルツ ２０Ｌ | F11: =IF($B11="","",IFERROR(INDEX(商品マスタ!$J$6:$J$1005,MATCH($D11,商品マスタ!$B$6:$B$1005,0)),"ケース")) -> ケース | G11: =IF($B11="","",IFERROR(INDEX(発注計算!$G$6:$G$405,MATCH(1,②発注数を決める!$Z$10:$Z$409,0)),"")) -> 1 | H11: =IF($B11="","",IFERROR(INDEX(②発注数を決める!$J$10:$J$409,MATCH(1,②発注数を決める!$Z$10:$Z$409,0)),"")) -> 6 | I11: =IF($B11="","",IFERROR(INDEX(発注計算!$H$6:$H$405,MATCH(1,②発注数を決める!$Z$10:$Z$409,0)),"")) -> 11300 | J11: =IF($B11="","",N($H11)*N($I11)) -> 67800 | N11: 東映ジョイ（コンセ）
B12: =IF(2<=MAX(②発注数を決める!$Z$10:$Z$409),2,"") -> 2 | C12: =IF($B12="","",IFERROR(INDEX(発注計算!$F$6:$F$405,MATCH(2,②発注数を決める!$Z$10:$Z$409,0)),"")) -> 株式会社 カクヤス | D12: =IF($B12="","",IFERROR(INDEX(発注計算!$C$6:$C$405,MATCH(2,②発注数を決める!$Z$10:$Z$409,0))&"","")) -> 1812000010991 | E12: =IF($B12="","",IFERROR(INDEX(②発注数を決める!$C$10:$C$409,MATCH(2,②発注数を決める!$Z$10:$Z$409,0))&"","")) -> ミオネット ベビーボトル２００ｍ | F12: =IF($B12="","",IFERROR(INDEX(商品マスタ!$J$6:$J$1005,MATCH($D12,商品マスタ!$B$6:$B$1005,0)),"ケース")) -> ケース | G12: =IF($B12="","",IFERROR(INDEX(発注計算!$G$6:$G$405,MATCH(2,②発注数を決める!$Z$10:$Z$409,0)),"")) -> 24 | H12: =IF($B12="","",IFERROR(INDEX(②発注数を決める!$J$10:$J$409,MATCH(2,②発注数を決める!$Z$10:$Z$409,0)),"")) -> 3 | I12: =IF($B12="","",IFERROR(INDEX(発注計算!$H$6:$H$405,MATCH(2,②発注数を決める!$Z$10:$Z$409,0)),"")) -> 587 | J12: =IF($B12="","",N($H12)*N($I12)) -> 1761 | N12: ㈱トップス
B13: =IF(3<=MAX(②発注数を決める!$Z$10:$Z$409),3,"") -> 3 | C13: =IF($B13="","",IFERROR(INDEX(発注計算!$F$6:$F$405,MATCH(3,②発注数を決める!$Z$10:$Z$409,0)),"")) -> 株式会社 カクヤス | D13: =IF($B13="","",IFERROR(INDEX(発注計算!$C$6:$C$405,MATCH(3,②発注数を決める!$Z$10:$Z$409,0))&"","")) -> 1812000011745 | E13: =IF($B13="","",IFERROR(INDEX(②発注数を決める!$C$10:$C$409,MATCH(3,②発注数を決める!$Z$10:$Z$409,0))&"","")) -> フォルタン リトラル 赤 | F13: =IF($B13="","",IFERROR(INDEX(商品マスタ!$J$6:$J$1005,MATCH($D13,商品マスタ!$B$6:$B$1005,0)),"ケース")) -> ケース | G13: =IF($B13="","",IFERROR(INDEX(発注計算!$G$6:$G$405,MATCH(3,②発注数を決める!$Z$10:$Z$409,0)),"")) -> 48 | H13: =IF($B13="","",IFERROR(INDEX(②発注数を決める!$J$10:$J$409,MATCH(3,②発注数を決める!$Z$10:$Z$409,0)),"")) -> 10 | I13: =IF($B13="","",IFERROR(INDEX(発注計算!$H$6:$H$405,MATCH(3,②発注数を決める!$Z$10:$Z$409,0)),"")) -> 357 | J13: =IF($B13="","",N($H13)*N($I13)) -> 3570 | N13: ㈱そごう・西武
B14: =IF(4<=MAX(②発注数を決める!$Z$10:$Z$409),4,"") -> 4 | C14: =IF($B14="","",IFERROR(INDEX(発注計算!$F$6:$F$405,MATCH(4,②発注数を決める!$Z$10:$Z$409,0)),"")) -> 株式会社 カクヤス | D14: =IF($B14="","",IFERROR(INDEX(発注計算!$C$6:$C$405,MATCH(4,②発注数を決める!$Z$10:$Z$409,0))&"","")) -> 1812000013343 | E14: =IF($B14="","",IFERROR(INDEX(②発注数を決める!$C$10:$C$409,MATCH(4,②発注数を決める!$Z$10:$Z$409,0))&"","")) -> フレシネコルドンネグロ２００ｍｌ | F14: =IF($B14="","",IFERROR(INDEX(商品マスタ!$J$6:$J$1005,MATCH($D14,商品マスタ!$B$6:$B$1005,0)),"ケース")) -> ケース | G14: =IF($B14="","",IFERROR(INDEX(発注計算!$G$6:$G$405,MATCH(4,②発注数を決める!$Z$10:$Z$409,0)),"")) -> 24 | H14: =IF($B14="","",IFERROR(INDEX(②発注数を決める!$J$10:$J$409,MATCH(4,②発注数を決める!$Z$10:$Z$409,0)),"")) -> 4 | I14: =IF($B14="","",IFERROR(INDEX(発注計算!$H$6:$H$405,MATCH(4,②発注数を決める!$Z$10:$Z$409,0)),"")) -> 585 | J14: =IF($B14="","",N($H14)*N($I14)) -> 2340 | N14: 本社 番組編成部 マーケティング室
B15: =IF(5<=MAX(②発注数を決める!$Z$10:$Z$409),5,"") -> 5 | C15: =IF($B15="","",IFERROR(INDEX(発注計算!$F$6:$F$405,MATCH(5,②発注数を決める!$Z$10:$Z$409,0)),"")) -> オザックス株式会社 | D15: =IF($B15="","",IFERROR(INDEX(発注計算!$C$6:$C$405,MATCH(5,②発注数を決める!$Z$10:$Z$409,0))&"","")) -> 1812000000251 | E15: =IF($B15="","",IFERROR(INDEX(②発注数を決める!$C$10:$C$409,MATCH(5,②発注数を決める!$Z$10:$Z$409,0))&"","")) -> 烏龍茶１０倍シロップ | F15: =IF($B15="","",IFERROR(INDEX(商品マスタ!$J$6:$J$1005,MATCH($D15,商品マスタ!$B$6:$B$1005,0)),"ケース")) -> ケース | G15: =IF($B15="","",IFERROR(INDEX(発注計算!$G$6:$G$405,MATCH(5,②発注数を決める!$Z$10:$Z$409,0)),"")) -> 1 | H15: =IF($B15="","",IFERROR(INDEX(②発注数を決める!$J$10:$J$409,MATCH(5,②発注数を決める!$Z$10:$Z$409,0)),"")) -> 8 | I15: =IF($B15="","",IFERROR(INDEX(発注計算!$H$6:$H$405,MATCH(5,②発注数を決める!$Z$10:$Z$409,0)),"")) -> 4382 | J15: =IF($B15="","",N($H15)*N($I15)) -> 35056
B16: =IF(6<=MAX(②発注数を決める!$Z$10:$Z$409),6,"") -> 6 | C16: =IF($B16="","",IFERROR(INDEX(発注計算!$F$6:$F$405,MATCH(6,②発注数を決める!$Z$10:$Z$409,0)),"")) -> オザックス株式会社 | D16: =IF($B16="","",IFERROR(INDEX(発注計算!$C$6:$C$405,MATCH(6,②発注数を決める!$Z$10:$Z$409,0))&"","")) -> 4902102081283 | E16: =IF($B16="","",IFERROR(INDEX(②発注数を決める!$C$10:$C$409,MATCH(6,②発注数を決める!$Z$10:$Z$409,0))&"","")) -> ＰＸＴ爽健美茶１Ｇ | F16: =IF($B16="","",IFERROR(INDEX(商品マスタ!$J$6:$J$1005,MATCH($D16,商品マスタ!$B$6:$B$1005,0)),"ケース")) -> ケース | G16: =IF($B16="","",IFERROR(INDEX(発注計算!$G$6:$G$405,MATCH(6,②発注数を決める!$Z$10:$Z$409,0)),"")) -> 1 | H16: =IF($B16="","",IFERROR(INDEX(②発注数を決める!$J$10:$J$409,MATCH(6,②発注数を決める!$Z$10:$Z$409,0)),"")) -> 2 | I16: =IF($B16="","",IFERROR(INDEX(発注計算!$H$6:$H$405,MATCH(6,②発注数を決める!$Z$10:$Z$409,0)),"")) -> 3756 | J16: =IF($B16="","",N($H16)*N($I16)) -> 7512
B17: =IF(7<=MAX(②発注数を決める!$Z$10:$Z$409),7,"") -> 7 | C17: =IF($B17="","",IFERROR(INDEX(発注計算!$F$6:$F$405,MATCH(7,②発注数を決める!$Z$10:$Z$409,0)),"")) -> オザックス株式会社 | D17: =IF($B17="","",IFERROR(INDEX(発注計算!$C$6:$C$405,MATCH(7,②発注数を決める!$Z$10:$Z$409,0))&"","")) -> 4902102113014 | E17: =IF($B17="","",IFERROR(INDEX(②発注数を決める!$C$10:$C$409,MATCH(7,②発注数を決める!$Z$10:$Z$409,0))&"","")) -> フラットＢＩＢコーラゼロ２．５Ｇ | F17: =IF($B17="","",IFERROR(INDEX(商品マスタ!$J$6:$J$1005,MATCH($D17,商品マスタ!$B$6:$B$1005,0)),"ケース")) -> ケース | G17: =IF($B17="","",IFERROR(INDEX(発注計算!$G$6:$G$405,MATCH(7,②発注数を決める!$Z$10:$Z$409,0)),"")) -> 1 | H17: =IF($B17="","",IFERROR(INDEX(②発注数を決める!$J$10:$J$409,MATCH(7,②発注数を決める!$Z$10:$Z$409,0)),"")) -> 5 | I17: =IF($B17="","",IFERROR(INDEX(発注計算!$H$6:$H$405,MATCH(7,②発注数を決める!$Z$10:$Z$409,0)),"")) -> 8136 | J17: =IF($B17="","",N($H17)*N($I17)) -> 40680
B18: =IF(8<=MAX(②発注数を決める!$Z$10:$Z$409),8,"") | C18: =IF($B18="","",IFERROR(INDEX(発注計算!$F$6:$F$405,MATCH(8,②発注数を決める!$Z$10:$Z$409,0)),"")) | D18: =IF($B18="","",IFERROR(INDEX(発注計算!$C$6:$C$405,MATCH(8,②発注数を決める!$Z$10:$Z$409,0))&"","")) | E18: =IF($B18="","",IFERROR(INDEX(②発注数を決める!$C$10:$C$409,MATCH(8,②発注数を決める!$Z$10:$Z$409,0))&"","")) | F18: =IF($B18="","",IFERROR(INDEX(商品マスタ!$J$6:$J$1005,MATCH($D18,商品マスタ!$B$6:$B$1005,0)),"ケース")) | G18: =IF($B18="","",IFERROR(INDEX(発注計算!$G$6:$G$405,MATCH(8,②発注数を決める!$Z$10:$Z$409,0)),"")) | H18: =IF($B18="","",IFERROR(INDEX(②発注数を決める!$J$10:$J$409,MATCH(8,②発注数を決める!$Z$10:$Z$409,0)),"")) | I18: =IF($B18="","",IFERROR(INDEX(発注計算!$H$6:$H$405,MATCH(8,②発注数を決める!$Z$10:$Z$409,0)),"")) | J18: =IF($B18="","",N($H18)*N($I18))
B19: =IF(9<=MAX(②発注数を決める!$Z$10:$Z$409),9,"") | C19: =IF($B19="","",IFERROR(INDEX(発注計算!$F$6:$F$405,MATCH(9,②発注数を決める!$Z$10:$Z$409,0)),"")) | D19: =IF($B19="","",IFERROR(INDEX(発注計算!$C$6:$C$405,MATCH(9,②発注数を決める!$Z$10:$Z$409,0))&"","")) | E19: =IF($B19="","",IFERROR(INDEX(②発注数を決める!$C$10:$C$409,MATCH(9,②発注数を決める!$Z$10:$Z$409,0))&"","")) | F19: =IF($B19="","",IFERROR(INDEX(商品マスタ!$J$6:$J$1005,MATCH($D19,商品マスタ!$B$6:$B$1005,0)),"ケース")) | G19: =IF($B19="","",IFERROR(INDEX(発注計算!$G$6:$G$405,MATCH(9,②発注数を決める!$Z$10:$Z$409,0)),"")) | H19: =IF($B19="","",IFERROR(INDEX(②発注数を決める!$J$10:$J$409,MATCH(9,②発注数を決める!$Z$10:$Z$409,0)),"")) | I19: =IF($B19="","",IFERROR(INDEX(発注計算!$H$6:$H$405,MATCH(9,②発注数を決める!$Z$10:$Z$409,0)),"")) | J19: =IF($B19="","",N($H19)*N($I19))
B20: =IF(10<=MAX(②発注数を決める!$Z$10:$Z$409),10,"") | C20: =IF($B20="","",IFERROR(INDEX(発注計算!$F$6:$F$405,MATCH(10,②発注数を決める!$Z$10:$Z$409,0)),"")) | D20: =IF($B20="","",IFERROR(INDEX(発注計算!$C$6:$C$405,MATCH(10,②発注数を決める!$Z$10:$Z$409,0))&"","")) | E20: =IF($B20="","",IFERROR(INDEX(②発注数を決める!$C$10:$C$409,MATCH(10,②発注数を決める!$Z$10:$Z$409,0))&"","")) | F20: =IF($B20="","",IFERROR(INDEX(商品マスタ!$J$6:$J$1005,MATCH($D20,商品マスタ!$B$6:$B$1005,0)),"ケース")) | G20: =IF($B20="","",IFERROR(INDEX(発注計算!$G$6:$G$405,MATCH(10,②発注数を決める!$Z$10:$Z$409,0)),"")) | H20: =IF($B20="","",IFERROR(INDEX(②発注数を決める!$J$10:$J$409,MATCH(10,②発注数を決める!$Z$10:$Z$409,0)),"")) | I20: =IF($B20="","",IFERROR(INDEX(発注計算!$H$6:$H$405,MATCH(10,②発注数を決める!$Z$10:$Z$409,0)),"")) | J20: =IF($B20="","",N($H20)*N($I20))
B21: =IF(11<=MAX(②発注数を決める!$Z$10:$Z$409),11,"") | C21: =IF($B21="","",IFERROR(INDEX(発注計算!$F$6:$F$405,MATCH(11,②発注数を決める!$Z$10:$Z$409,0)),"")) | D21: =IF($B21="","",IFERROR(INDEX(発注計算!$C$6:$C$405,MATCH(11,②発注数を決める!$Z$10:$Z$409,0))&"","")) | E21: =IF($B21="","",IFERROR(INDEX(②発注数を決める!$C$10:$C$409,MATCH(11,②発注数を決める!$Z$10:$Z$409,0))&"","")) | F21: =IF($B21="","",IFERROR(INDEX(商品マスタ!$J$6:$J$1005,MATCH($D21,商品マスタ!$B$6:$B$1005,0)),"ケース")) | G21: =IF($B21="","",IFERROR(INDEX(発注計算!$G$6:$G$405,MATCH(11,②発注数を決める!$Z$10:$Z$409,0)),"")) | H21: =IF($B21="","",IFERROR(INDEX(②発注数を決める!$J$10:$J$409,MATCH(11,②発注数を決める!$Z$10:$Z$409,0)),"")) | I21: =IF($B21="","",IFERROR(INDEX(発注計算!$H$6:$H$405,MATCH(11,②発注数を決める!$Z$10:$Z$409,0)),"")) | J21: =IF($B21="","",N($H21)*N($I21))
B22: =IF(12<=MAX(②発注数を決める!$Z$10:$Z$409),12,"") | C22: =IF($B22="","",IFERROR(INDEX(発注計算!$F$6:$F$405,MATCH(12,②発注数を決める!$Z$10:$Z$409,0)),"")) | D22: =IF($B22="","",IFERROR(INDEX(発注計算!$C$6:$C$405,MATCH(12,②発注数を決める!$Z$10:$Z$409,0))&"","")) | E22: =IF($B22="","",IFERROR(INDEX(②発注数を決める!$C$10:$C$409,MATCH(12,②発注数を決める!$Z$10:$Z$409,0))&"","")) | F22: =IF($B22="","",IFERROR(INDEX(商品マスタ!$J$6:$J$1005,MATCH($D22,商品マスタ!$B$6:$B$1005,0)),"ケース")) | G22: =IF($B22="","",IFERROR(INDEX(発注計算!$G$6:$G$405,MATCH(12,②発注数を決める!$Z$10:$Z$409,0)),"")) | H22: =IF($B22="","",IFERROR(INDEX(②発注数を決める!$J$10:$J$409,MATCH(12,②発注数を決める!$Z$10:$Z$409,0)),"")) | I22: =IF($B22="","",IFERROR(INDEX(発注計算!$H$6:$H$405,MATCH(12,②発注数を決める!$Z$10:$Z$409,0)),"")) | J22: =IF($B22="","",N($H22)*N($I22))
B23: =IF(13<=MAX(②発注数を決める!$Z$10:$Z$409),13,"") | C23: =IF($B23="","",IFERROR(INDEX(発注計算!$F$6:$F$405,MATCH(13,②発注数を決める!$Z$10:$Z$409,0)),"")) | D23: =IF($B23="","",IFERROR(INDEX(発注計算!$C$6:$C$405,MATCH(13,②発注数を決める!$Z$10:$Z$409,0))&"","")) | E23: =IF($B23="","",IFERROR(INDEX(②発注数を決める!$C$10:$C$409,MATCH(13,②発注数を決める!$Z$10:$Z$409,0))&"","")) | F23: =IF($B23="","",IFERROR(INDEX(商品マスタ!$J$6:$J$1005,MATCH($D23,商品マスタ!$B$6:$B$1005,0)),"ケース")) | G23: =IF($B23="","",IFERROR(INDEX(発注計算!$G$6:$G$405,MATCH(13,②発注数を決める!$Z$10:$Z$409,0)),"")) | H23: =IF($B23="","",IFERROR(INDEX(②発注数を決める!$J$10:$J$409,MATCH(13,②発注数を決める!$Z$10:$Z$409,0)),"")) | I23: =IF($B23="","",IFERROR(INDEX(発注計算!$H$6:$H$405,MATCH(13,②発注数を決める!$Z$10:$Z$409,0)),"")) | J23: =IF($B23="","",N($H23)*N($I23))
B24: =IF(14<=MAX(②発注数を決める!$Z$10:$Z$409),14,"") | C24: =IF($B24="","",IFERROR(INDEX(発注計算!$F$6:$F$405,MATCH(14,②発注数を決める!$Z$10:$Z$409,0)),"")) | D24: =IF($B24="","",IFERROR(INDEX(発注計算!$C$6:$C$405,MATCH(14,②発注数を決める!$Z$10:$Z$409,0))&"","")) | E24: =IF($B24="","",IFERROR(INDEX(②発注数を決める!$C$10:$C$409,MATCH(14,②発注数を決める!$Z$10:$Z$409,0))&"","")) | F24: =IF($B24="","",IFERROR(INDEX(商品マスタ!$J$6:$J$1005,MATCH($D24,商品マスタ!$B$6:$B$1005,0)),"ケース")) | G24: =IF($B24="","",IFERROR(INDEX(発注計算!$G$6:$G$405,MATCH(14,②発注数を決める!$Z$10:$Z$409,0)),"")) | H24: =IF($B24="","",IFERROR(INDEX(②発注数を決める!$J$10:$J$409,MATCH(14,②発注数を決める!$Z$10:$Z$409,0)),"")) | I24: =IF($B24="","",IFERROR(INDEX(発注計算!$H$6:$H$405,MATCH(14,②発注数を決める!$Z$10:$Z$409,0)),"")) | J24: =IF($B24="","",N($H24)*N($I24))
B25: =IF(15<=MAX(②発注数を決める!$Z$10:$Z$409),15,"") | C25: =IF($B25="","",IFERROR(INDEX(発注計算!$F$6:$F$405,MATCH(15,②発注数を決める!$Z$10:$Z$409,0)),"")) | D25: =IF($B25="","",IFERROR(INDEX(発注計算!$C$6:$C$405,MATCH(15,②発注数を決める!$Z$10:$Z$409,0))&"","")) | E25: =IF($B25="","",IFERROR(INDEX(②発注数を決める!$C$10:$C$409,MATCH(15,②発注数を決める!$Z$10:$Z$409,0))&"","")) | F25: =IF($B25="","",IFERROR(INDEX(商品マスタ!$J$6:$J$1005,MATCH($D25,商品マスタ!$B$6:$B$1005,0)),"ケース")) | G25: =IF($B25="","",IFERROR(INDEX(発注計算!$G$6:$G$405,MATCH(15,②発注数を決める!$Z$10:$Z$409,0)),"")) | H25: =IF($B25="","",IFERROR(INDEX(②発注数を決める!$J$10:$J$409,MATCH(15,②発注数を決める!$Z$10:$Z$409,0)),"")) | I25: =IF($B25="","",IFERROR(INDEX(発注計算!$H$6:$H$405,MATCH(15,②発注数を決める!$Z$10:$Z$409,0)),"")) | J25: =IF($B25="","",N($H25)*N($I25))
B26: =IF(16<=MAX(②発注数を決める!$Z$10:$Z$409),16,"") | C26: =IF($B26="","",IFERROR(INDEX(発注計算!$F$6:$F$405,MATCH(16,②発注数を決める!$Z$10:$Z$409,0)),"")) | D26: =IF($B26="","",IFERROR(INDEX(発注計算!$C$6:$C$405,MATCH(16,②発注数を決める!$Z$10:$Z$409,0))&"","")) | E26: =IF($B26="","",IFERROR(INDEX(②発注数を決める!$C$10:$C$409,MATCH(16,②発注数を決める!$Z$10:$Z$409,0))&"","")) | F26: =IF($B26="","",IFERROR(INDEX(商品マスタ!$J$6:$J$1005,MATCH($D26,商品マスタ!$B$6:$B$1005,0)),"ケース")) | G26: =IF($B26="","",IFERROR(INDEX(発注計算!$G$6:$G$405,MATCH(16,②発注数を決める!$Z$10:$Z$409,0)),"")) | H26: =IF($B26="","",IFERROR(INDEX(②発注数を決める!$J$10:$J$409,MATCH(16,②発注数を決める!$Z$10:$Z$409,0)),"")) | I26: =IF($B26="","",IFERROR(INDEX(発注計算!$H$6:$H$405,MATCH(16,②発注数を決める!$Z$10:$Z$409,0)),"")) | J26: =IF($B26="","",N($H26)*N($I26))
B27: =IF(17<=MAX(②発注数を決める!$Z$10:$Z$409),17,"") | C27: =IF($B27="","",IFERROR(INDEX(発注計算!$F$6:$F$405,MATCH(17,②発注数を決める!$Z$10:$Z$409,0)),"")) | D27: =IF($B27="","",IFERROR(INDEX(発注計算!$C$6:$C$405,MATCH(17,②発注数を決める!$Z$10:$Z$409,0))&"","")) | E27: =IF($B27="","",IFERROR(INDEX(②発注数を決める!$C$10:$C$409,MATCH(17,②発注数を決める!$Z$10:$Z$409,0))&"","")) | F27: =IF($B27="","",IFERROR(INDEX(商品マスタ!$J$6:$J$1005,MATCH($D27,商品マスタ!$B$6:$B$1005,0)),"ケース")) | G27: =IF($B27="","",IFERROR(INDEX(発注計算!$G$6:$G$405,MATCH(17,②発注数を決める!$Z$10:$Z$409,0)),"")) | H27: =IF($B27="","",IFERROR(INDEX(②発注数を決める!$J$10:$J$409,MATCH(17,②発注数を決める!$Z$10:$Z$409,0)),"")) | I27: =IF($B27="","",IFERROR(INDEX(発注計算!$H$6:$H$405,MATCH(17,②発注数を決める!$Z$10:$Z$409,0)),"")) | J27: =IF($B27="","",N($H27)*N($I27))
B28: =IF(18<=MAX(②発注数を決める!$Z$10:$Z$409),18,"") | C28: =IF($B28="","",IFERROR(INDEX(発注計算!$F$6:$F$405,MATCH(18,②発注数を決める!$Z$10:$Z$409,0)),"")) | D28: =IF($B28="","",IFERROR(INDEX(発注計算!$C$6:$C$405,MATCH(18,②発注数を決める!$Z$10:$Z$409,0))&"","")) | E28: =IF($B28="","",IFERROR(INDEX(②発注数を決める!$C$10:$C$409,MATCH(18,②発注数を決める!$Z$10:$Z$409,0))&"","")) | F28: =IF($B28="","",IFERROR(INDEX(商品マスタ!$J$6:$J$1005,MATCH($D28,商品マスタ!$B$6:$B$1005,0)),"ケース")) | G28: =IF($B28="","",IFERROR(INDEX(発注計算!$G$6:$G$405,MATCH(18,②発注数を決める!$Z$10:$Z$409,0)),"")) | H28: =IF($B28="","",IFERROR(INDEX(②発注数を決める!$J$10:$J$409,MATCH(18,②発注数を決める!$Z$10:$Z$409,0)),"")) | I28: =IF($B28="","",IFERROR(INDEX(発注計算!$H$6:$H$405,MATCH(18,②発注数を決める!$Z$10:$Z$409,0)),"")) | J28: =IF($B28="","",N($H28)*N($I28))
B29: =IF(19<=MAX(②発注数を決める!$Z$10:$Z$409),19,"") | C29: =IF($B29="","",IFERROR(INDEX(発注計算!$F$6:$F$405,MATCH(19,②発注数を決める!$Z$10:$Z$409,0)),"")) | D29: =IF($B29="","",IFERROR(INDEX(発注計算!$C$6:$C$405,MATCH(19,②発注数を決める!$Z$10:$Z$409,0))&"","")) | E29: =IF($B29="","",IFERROR(INDEX(②発注数を決める!$C$10:$C$409,MATCH(19,②発注数を決める!$Z$10:$Z$409,0))&"","")) | F29: =IF($B29="","",IFERROR(INDEX(商品マスタ!$J$6:$J$1005,MATCH($D29,商品マスタ!$B$6:$B$1005,0)),"ケース")) | G29: =IF($B29="","",IFERROR(INDEX(発注計算!$G$6:$G$405,MATCH(19,②発注数を決める!$Z$10:$Z$409,0)),"")) | H29: =IF($B29="","",IFERROR(INDEX(②発注数を決める!$J$10:$J$409,MATCH(19,②発注数を決める!$Z$10:$Z$409,0)),"")) | I29: =IF($B29="","",IFERROR(INDEX(発注計算!$H$6:$H$405,MATCH(19,②発注数を決める!$Z$10:$Z$409,0)),"")) | J29: =IF($B29="","",N($H29)*N($I29))
B30: =IF(20<=MAX(②発注数を決める!$Z$10:$Z$409),20,"") | C30: =IF($B30="","",IFERROR(INDEX(発注計算!$F$6:$F$405,MATCH(20,②発注数を決める!$Z$10:$Z$409,0)),"")) | D30: =IF($B30="","",IFERROR(INDEX(発注計算!$C$6:$C$405,MATCH(20,②発注数を決める!$Z$10:$Z$409,0))&"","")) | E30: =IF($B30="","",IFERROR(INDEX(②発注数を決める!$C$10:$C$409,MATCH(20,②発注数を決める!$Z$10:$Z$409,0))&"","")) | F30: =IF($B30="","",IFERROR(INDEX(商品マスタ!$J$6:$J$1005,MATCH($D30,商品マスタ!$B$6:$B$1005,0)),"ケース")) | G30: =IF($B30="","",IFERROR(INDEX(発注計算!$G$6:$G$405,MATCH(20,②発注数を決める!$Z$10:$Z$409,0)),"")) | H30: =IF($B30="","",IFERROR(INDEX(②発注数を決める!$J$10:$J$409,MATCH(20,②発注数を決める!$Z$10:$Z$409,0)),"")) | I30: =IF($B30="","",IFERROR(INDEX(発注計算!$H$6:$H$405,MATCH(20,②発注数を決める!$Z$10:$Z$409,0)),"")) | J30: =IF($B30="","",N($H30)*N($I30))
B31: =IF(21<=MAX(②発注数を決める!$Z$10:$Z$409),21,"") | C31: =IF($B31="","",IFERROR(INDEX(発注計算!$F$6:$F$405,MATCH(21,②発注数を決める!$Z$10:$Z$409,0)),"")) | D31: =IF($B31="","",IFERROR(INDEX(発注計算!$C$6:$C$405,MATCH(21,②発注数を決める!$Z$10:$Z$409,0))&"","")) | E31: =IF($B31="","",IFERROR(INDEX(②発注数を決める!$C$10:$C$409,MATCH(21,②発注数を決める!$Z$10:$Z$409,0))&"","")) | F31: =IF($B31="","",IFERROR(INDEX(商品マスタ!$J$6:$J$1005,MATCH($D31,商品マスタ!$B$6:$B$1005,0)),"ケース")) | G31: =IF($B31="","",IFERROR(INDEX(発注計算!$G$6:$G$405,MATCH(21,②発注数を決める!$Z$10:$Z$409,0)),"")) | H31: =IF($B31="","",IFERROR(INDEX(②発注数を決める!$J$10:$J$409,MATCH(21,②発注数を決める!$Z$10:$Z$409,0)),"")) | I31: =IF($B31="","",IFERROR(INDEX(発注計算!$H$6:$H$405,MATCH(21,②発注数を決める!$Z$10:$Z$409,0)),"")) | J31: =IF($B31="","",N($H31)*N($I31))
B32: =IF(22<=MAX(②発注数を決める!$Z$10:$Z$409),22,"") | C32: =IF($B32="","",IFERROR(INDEX(発注計算!$F$6:$F$405,MATCH(22,②発注数を決める!$Z$10:$Z$409,0)),"")) | D32: =IF($B32="","",IFERROR(INDEX(発注計算!$C$6:$C$405,MATCH(22,②発注数を決める!$Z$10:$Z$409,0))&"","")) | E32: =IF($B32="","",IFERROR(INDEX(②発注数を決める!$C$10:$C$409,MATCH(22,②発注数を決める!$Z$10:$Z$409,0))&"","")) | F32: =IF($B32="","",IFERROR(INDEX(商品マスタ!$J$6:$J$1005,MATCH($D32,商品マスタ!$B$6:$B$1005,0)),"ケース")) | G32: =IF($B32="","",IFERROR(INDEX(発注計算!$G$6:$G$405,MATCH(22,②発注数を決める!$Z$10:$Z$409,0)),"")) | H32: =IF($B32="","",IFERROR(INDEX(②発注数を決める!$J$10:$J$409,MATCH(22,②発注数を決める!$Z$10:$Z$409,0)),"")) | I32: =IF($B32="","",IFERROR(INDEX(発注計算!$H$6:$H$405,MATCH(22,②発注数を決める!$Z$10:$Z$409,0)),"")) | J32: =IF($B32="","",N($H32)*N($I32))
B33: =IF(23<=MAX(②発注数を決める!$Z$10:$Z$409),23,"") | C33: =IF($B33="","",IFERROR(INDEX(発注計算!$F$6:$F$405,MATCH(23,②発注数を決める!$Z$10:$Z$409,0)),"")) | D33: =IF($B33="","",IFERROR(INDEX(発注計算!$C$6:$C$405,MATCH(23,②発注数を決める!$Z$10:$Z$409,0))&"","")) | E33: =IF($B33="","",IFERROR(INDEX(②発注数を決める!$C$10:$C$409,MATCH(23,②発注数を決める!$Z$10:$Z$409,0))&"","")) | F33: =IF($B33="","",IFERROR(INDEX(商品マスタ!$J$6:$J$1005,MATCH($D33,商品マスタ!$B$6:$B$1005,0)),"ケース")) | G33: =IF($B33="","",IFERROR(INDEX(発注計算!$G$6:$G$405,MATCH(23,②発注数を決める!$Z$10:$Z$409,0)),"")) | H33: =IF($B33="","",IFERROR(INDEX(②発注数を決める!$J$10:$J$409,MATCH(23,②発注数を決める!$Z$10:$Z$409,0)),"")) | I33: =IF($B33="","",IFERROR(INDEX(発注計算!$H$6:$H$405,MATCH(23,②発注数を決める!$Z$10:$Z$409,0)),"")) | J33: =IF($B33="","",N($H33)*N($I33))
B34: =IF(24<=MAX(②発注数を決める!$Z$10:$Z$409),24,"") | C34: =IF($B34="","",IFERROR(INDEX(発注計算!$F$6:$F$405,MATCH(24,②発注数を決める!$Z$10:$Z$409,0)),"")) | D34: =IF($B34="","",IFERROR(INDEX(発注計算!$C$6:$C$405,MATCH(24,②発注数を決める!$Z$10:$Z$409,0))&"","")) | E34: =IF($B34="","",IFERROR(INDEX(②発注数を決める!$C$10:$C$409,MATCH(24,②発注数を決める!$Z$10:$Z$409,0))&"","")) | F34: =IF($B34="","",IFERROR(INDEX(商品マスタ!$J$6:$J$1005,MATCH($D34,商品マスタ!$B$6:$B$1005,0)),"ケース")) | G34: =IF($B34="","",IFERROR(INDEX(発注計算!$G$6:$G$405,MATCH(24,②発注数を決める!$Z$10:$Z$409,0)),"")) | H34: =IF($B34="","",IFERROR(INDEX(②発注数を決める!$J$10:$J$409,MATCH(24,②発注数を決める!$Z$10:$Z$409,0)),"")) | I34: =IF($B34="","",IFERROR(INDEX(発注計算!$H$6:$H$405,MATCH(24,②発注数を決める!$Z$10:$Z$409,0)),"")) | J34: =IF($B34="","",N($H34)*N($I34))
B35: =IF(25<=MAX(②発注数を決める!$Z$10:$Z$409),25,"") | C35: =IF($B35="","",IFERROR(INDEX(発注計算!$F$6:$F$405,MATCH(25,②発注数を決める!$Z$10:$Z$409,0)),"")) | D35: =IF($B35="","",IFERROR(INDEX(発注計算!$C$6:$C$405,MATCH(25,②発注数を決める!$Z$10:$Z$409,0))&"","")) | E35: =IF($B35="","",IFERROR(INDEX(②発注数を決める!$C$10:$C$409,MATCH(25,②発注数を決める!$Z$10:$Z$409,0))&"","")) | F35: =IF($B35="","",IFERROR(INDEX(商品マスタ!$J$6:$J$1005,MATCH($D35,商品マスタ!$B$6:$B$1005,0)),"ケース")) | G35: =IF($B35="","",IFERROR(INDEX(発注計算!$G$6:$G$405,MATCH(25,②発注数を決める!$Z$10:$Z$409,0)),"")) | H35: =IF($B35="","",IFERROR(INDEX(②発注数を決める!$J$10:$J$409,MATCH(25,②発注数を決める!$Z$10:$Z$409,0)),"")) | I35: =IF($B35="","",IFERROR(INDEX(発注計算!$H$6:$H$405,MATCH(25,②発注数を決める!$Z$10:$Z$409,0)),"")) | J35: =IF($B35="","",N($H35)*N($I35))
B36: =IF(26<=MAX(②発注数を決める!$Z$10:$Z$409),26,"") | C36: =IF($B36="","",IFERROR(INDEX(発注計算!$F$6:$F$405,MATCH(26,②発注数を決める!$Z$10:$Z$409,0)),"")) | D36: =IF($B36="","",IFERROR(INDEX(発注計算!$C$6:$C$405,MATCH(26,②発注数を決める!$Z$10:$Z$409,0))&"","")) | E36: =IF($B36="","",IFERROR(INDEX(②発注数を決める!$C$10:$C$409,MATCH(26,②発注数を決める!$Z$10:$Z$409,0))&"","")) | F36: =IF($B36="","",IFERROR(INDEX(商品マスタ!$J$6:$J$1005,MATCH($D36,商品マスタ!$B$6:$B$1005,0)),"ケース")) | G36: =IF($B36="","",IFERROR(INDEX(発注計算!$G$6:$G$405,MATCH(26,②発注数を決める!$Z$10:$Z$409,0)),"")) | H36: =IF($B36="","",IFERROR(INDEX(②発注数を決める!$J$10:$J$409,MATCH(26,②発注数を決める!$Z$10:$Z$409,0)),"")) | I36: =IF($B36="","",IFERROR(INDEX(発注計算!$H$6:$H$405,MATCH(26,②発注数を決める!$Z$10:$Z$409,0)),"")) | J36: =IF($B36="","",N($H36)*N($I36))
B37: =IF(27<=MAX(②発注数を決める!$Z$10:$Z$409),27,"") | C37: =IF($B37="","",IFERROR(INDEX(発注計算!$F$6:$F$405,MATCH(27,②発注数を決める!$Z$10:$Z$409,0)),"")) | D37: =IF($B37="","",IFERROR(INDEX(発注計算!$C$6:$C$405,MATCH(27,②発注数を決める!$Z$10:$Z$409,0))&"","")) | E37: =IF($B37="","",IFERROR(INDEX(②発注数を決める!$C$10:$C$409,MATCH(27,②発注数を決める!$Z$10:$Z$409,0))&"","")) | F37: =IF($B37="","",IFERROR(INDEX(商品マスタ!$J$6:$J$1005,MATCH($D37,商品マスタ!$B$6:$B$1005,0)),"ケース")) | G37: =IF($B37="","",IFERROR(INDEX(発注計算!$G$6:$G$405,MATCH(27,②発注数を決める!$Z$10:$Z$409,0)),"")) | H37: =IF($B37="","",IFERROR(INDEX(②発注数を決める!$J$10:$J$409,MATCH(27,②発注数を決める!$Z$10:$Z$409,0)),"")) | I37: =IF($B37="","",IFERROR(INDEX(発注計算!$H$6:$H$405,MATCH(27,②発注数を決める!$Z$10:$Z$409,0)),"")) | J37: =IF($B37="","",N($H37)*N($I37))
B38: =IF(28<=MAX(②発注数を決める!$Z$10:$Z$409),28,"") | C38: =IF($B38="","",IFERROR(INDEX(発注計算!$F$6:$F$405,MATCH(28,②発注数を決める!$Z$10:$Z$409,0)),"")) | D38: =IF($B38="","",IFERROR(INDEX(発注計算!$C$6:$C$405,MATCH(28,②発注数を決める!$Z$10:$Z$409,0))&"","")) | E38: =IF($B38="","",IFERROR(INDEX(②発注数を決める!$C$10:$C$409,MATCH(28,②発注数を決める!$Z$10:$Z$409,0))&"","")) | F38: =IF($B38="","",IFERROR(INDEX(商品マスタ!$J$6:$J$1005,MATCH($D38,商品マスタ!$B$6:$B$1005,0)),"ケース")) | G38: =IF($B38="","",IFERROR(INDEX(発注計算!$G$6:$G$405,MATCH(28,②発注数を決める!$Z$10:$Z$409,0)),"")) | H38: =IF($B38="","",IFERROR(INDEX(②発注数を決める!$J$10:$J$409,MATCH(28,②発注数を決める!$Z$10:$Z$409,0)),"")) | I38: =IF($B38="","",IFERROR(INDEX(発注計算!$H$6:$H$405,MATCH(28,②発注数を決める!$Z$10:$Z$409,0)),"")) | J38: =IF($B38="","",N($H38)*N($I38))
B39: =IF(29<=MAX(②発注数を決める!$Z$10:$Z$409),29,"") | C39: =IF($B39="","",IFERROR(INDEX(発注計算!$F$6:$F$405,MATCH(29,②発注数を決める!$Z$10:$Z$409,0)),"")) | D39: =IF($B39="","",IFERROR(INDEX(発注計算!$C$6:$C$405,MATCH(29,②発注数を決める!$Z$10:$Z$409,0))&"","")) | E39: =IF($B39="","",IFERROR(INDEX(②発注数を決める!$C$10:$C$409,MATCH(29,②発注数を決める!$Z$10:$Z$409,0))&"","")) | F39: =IF($B39="","",IFERROR(INDEX(商品マスタ!$J$6:$J$1005,MATCH($D39,商品マスタ!$B$6:$B$1005,0)),"ケース")) | G39: =IF($B39="","",IFERROR(INDEX(発注計算!$G$6:$G$405,MATCH(29,②発注数を決める!$Z$10:$Z$409,0)),"")) | H39: =IF($B39="","",IFERROR(INDEX(②発注数を決める!$J$10:$J$409,MATCH(29,②発注数を決める!$Z$10:$Z$409,0)),"")) | I39: =IF($B39="","",IFERROR(INDEX(発注計算!$H$6:$H$405,MATCH(29,②発注数を決める!$Z$10:$Z$409,0)),"")) | J39: =IF($B39="","",N($H39)*N($I39))
B40: =IF(30<=MAX(②発注数を決める!$Z$10:$Z$409),30,"") | C40: =IF($B40="","",IFERROR(INDEX(発注計算!$F$6:$F$405,MATCH(30,②発注数を決める!$Z$10:$Z$409,0)),"")) | D40: =IF($B40="","",IFERROR(INDEX(発注計算!$C$6:$C$405,MATCH(30,②発注数を決める!$Z$10:$Z$409,0))&"","")) | E40: =IF($B40="","",IFERROR(INDEX(②発注数を決める!$C$10:$C$409,MATCH(30,②発注数を決める!$Z$10:$Z$409,0))&"","")) | F40: =IF($B40="","",IFERROR(INDEX(商品マスタ!$J$6:$J$1005,MATCH($D40,商品マスタ!$B$6:$B$1005,0)),"ケース")) | G40: =IF($B40="","",IFERROR(INDEX(発注計算!$G$6:$G$405,MATCH(30,②発注数を決める!$Z$10:$Z$409,0)),"")) | H40: =IF($B40="","",IFERROR(INDEX(②発注数を決める!$J$10:$J$409,MATCH(30,②発注数を決める!$Z$10:$Z$409,0)),"")) | I40: =IF($B40="","",IFERROR(INDEX(発注計算!$H$6:$H$405,MATCH(30,②発注数を決める!$Z$10:$Z$409,0)),"")) | J40: =IF($B40="","",N($H40)*N($I40))
B41: =IF(31<=MAX(②発注数を決める!$Z$10:$Z$409),31,"") | C41: =IF($B41="","",IFERROR(INDEX(発注計算!$F$6:$F$405,MATCH(31,②発注数を決める!$Z$10:$Z$409,0)),"")) | D41: =IF($B41="","",IFERROR(INDEX(発注計算!$C$6:$C$405,MATCH(31,②発注数を決める!$Z$10:$Z$409,0))&"","")) | E41: =IF($B41="","",IFERROR(INDEX(②発注数を決める!$C$10:$C$409,MATCH(31,②発注数を決める!$Z$10:$Z$409,0))&"","")) | F41: =IF($B41="","",IFERROR(INDEX(商品マスタ!$J$6:$J$1005,MATCH($D41,商品マスタ!$B$6:$B$1005,0)),"ケース")) | G41: =IF($B41="","",IFERROR(INDEX(発注計算!$G$6:$G$405,MATCH(31,②発注数を決める!$Z$10:$Z$409,0)),"")) | H41: =IF($B41="","",IFERROR(INDEX(②発注数を決める!$J$10:$J$409,MATCH(31,②発注数を決める!$Z$10:$Z$409,0)),"")) | I41: =IF($B41="","",IFERROR(INDEX(発注計算!$H$6:$H$405,MATCH(31,②発注数を決める!$Z$10:$Z$409,0)),"")) | J41: =IF($B41="","",N($H41)*N($I41))
...

Sheet 月1回_前回の在庫を貼る
B2: 前回の在庫を貼る（月1回） | H2: =IF(COUNTIF($B$6:$B$10005,'設定（最初に1回）'!$C$4)=0,"✖ まだ貼れていません","✔ "&COUNTIF($B$6:$B$10005,'設定（最初に1回）'!$C$4)&"行 読み込めました") -> ✔ 134行 読み込めました
B3: 当月を含まない直近2ヶ月前の1日時点の在庫一覧です。今日の在庫と突き合わせて、期間の消費量と商品の入れ替わりを見ます。 | H3: =IF(COUNTIF($B$6:$B$10005,'設定（最初に1回）'!$C$4)=0,"CSVの見出し行を除いたデータを A6 セルに貼り付けてください。貼ったのに0のままなら、劇場コードが数値になっています。","対象劇場：" & '設定（最初に1回）'!$C$4 & " " & '設定（最初に1回）'!$C$5) -> 対象劇場：0761 新宿
B4: 月に1回、A6 セルに貼り替えてください。
A5: 対象日付 | B5: 劇場コード | C5: 劇場名 | D5: 支払先コード | E5: 支払先名 | F5: 大分類コード | G5: 小分類コード | H5: 商品分類名 | I5: 商品コード | J5: 商品名 | K5: 入数 | L5: 在庫数ケース | M5: 在庫数バラ | N5: 総数 | O5: 規定数 | P5: 資産廃棄 | Q5: 税抜単価 | R5: 仕入税区分 | S5: 仕入税率 | U5: 連番(自動)
A6: 20260301 | B6: 0761 | C6: 新宿 | D6: 10400001 | E6: 株式会社 カクヤス | F6: 01 | G6: 04 | H6: アルコール | I6: 1812000008585 | J6: プレミアムモルツ ２０Ｌ | K6: 1 | L6: 108 | M6: 0 | N6: 108 | P6: 0 | Q6: 11300 | R6: 外税 | S6: 0.1 | U6: =IF($B6<>'設定（最初に1回）'!$C$4,N(U5),IF(COUNTIFS(①今日の在庫を貼る!$B$6:$B$10005,$B6,①今日の在庫を貼る!$I$6:$I$10005,$I6)>0,N(U5),N(U5)+1)) -> 0
A7: 20260301 | B7: 0761 | C7: 新宿 | D7: 10400001 | E7: 株式会社 カクヤス | F7: 01 | G7: 04 | H7: アルコール | I7: 1812000010991 | J7: ミオネット ベビーボトル２００ｍ | K7: 24 | L7: 0 | M7: 2 | N7: 2 | P7: 0 | Q7: 587 | R7: 外税 | S7: 0.1 | U7: =IF($B7<>'設定（最初に1回）'!$C$4,N(U6),IF(COUNTIFS(①今日の在庫を貼る!$B$6:$B$10005,$B7,①今日の在庫を貼る!$I$6:$I$10005,$I7)>0,N(U6),N(U6)+1)) -> 0
A8: 20260301 | B8: 0761 | C8: 新宿 | D8: 10400001 | E8: 株式会社 カクヤス | F8: 01 | G8: 04 | H8: アルコール | I8: 1812000011745 | J8: フォルタン リトラル 赤 | K8: 48 | L8: 1 | M8: 6 | N8: 54 | P8: 0 | Q8: 357 | R8: 外税 | S8: 0.1 | U8: =IF($B8<>'設定（最初に1回）'!$C$4,N(U7),IF(COUNTIFS(①今日の在庫を貼る!$B$6:$B$10005,$B8,①今日の在庫を貼る!$I$6:$I$10005,$I8)>0,N(U7),N(U7)+1)) -> 0
A9: 20260301 | B9: 0761 | C9: 新宿 | D9: 10400001 | E9: 株式会社 カクヤス | F9: 01 | G9: 04 | H9: アルコール | I9: 1812000011752 | J9: フォルタン リトラル 白 | K9: 48 | L9: 1 | M9: 33 | N9: 81 | P9: 0 | Q9: 357 | R9: 外税 | S9: 0.1 | U9: =IF($B9<>'設定（最初に1回）'!$C$4,N(U8),IF(COUNTIFS(①今日の在庫を貼る!$B$6:$B$10005,$B9,①今日の在庫を貼る!$I$6:$I$10005,$I9)>0,N(U8),N(U8)+1)) -> 0
