Workbook

Sheet ホーム
B1: ホーム
B2: 売店発注ツール
B3: =IF('設定'!$C$6="","まだ在庫CSVが貼られていません","きょう "&TEXT('設定'!$C$6,"m/d")&"("&CHOOSE(WEEKDAY('設定'!$C$6),"日","月","火","水","木","金","土")&")"&" "&'設定'!$C$5&" "&'設定'!$C$4)
B5: 毎日やること 上から順に
C7: STEP 1 在庫を貼る › | D7: =COUNTIF('①在庫を貼る'!$V$6:$V$10005,'設定'!$C$4)
C8: 在庫システムの在庫一覧CSVを貼ります。 | D8: 読み込めた行
C9: =IF(COUNTIF('①在庫を貼る'!$V$6:$V$10005,'設定'!$C$4)=0,"● まだ貼られていません",IF('設定'!$C$6<TODAY()-1,"● 在庫が "&TEXT('設定'!$C$6,"m/d")&" のものです（"&(TODAY()-'設定'!$C$6)&"日前）。今日のCSVを貼ってください","○ 貼れています（"&TEXT('設定'!$C$6,"m/d")&" の在庫）"))
C12: STEP 2 発注する › | D12: =COUNTIF('②発注する'!$H$10:$H$409,"●*")
C13: 「切れる日」を見て、黄色の「入庫日・入庫数」を入れます。 | D13: 今日発注が必要
C14: =IF('計算'!$B$3=0,"● 動員が入っていません → 動員を入れる",IF('計算'!$B$2=1,"● これから14日が動員の表の外です → 動員を入れる の「表の開始日」を直す",IF(COUNTIF('②発注する'!$H$10:$H$409,"●*")>0,"● 赤 "&COUNTIF('②発注する'!$H$10:$H$409,"●*")&"品目は今日中に発注。橙 "&COUNTIF('②発注する'!$H$10:$H$409,"△*")&"品目も近く切れます",IF(COUNTIF('②発注する'!$H$10:$H$409,"△*")>0,"△ 今日は急ぎなし。橙 "&COUNTIF('②発注する'!$H$10:$H$409,"△*")&"品目が近く切れます","○ 14日以内に切れる商品はありません"))))
C17: STEP 3 発注書を印刷する › | D17: =SUM('計算'!$CN$6:$CN$405)
C18: 入庫を入れた商品が発注書に集まります。仕入先を選んで印刷。 | D18: 発注予定額（税抜）
C19: =IF(COUNTIF('②発注する'!$O$10:$O$409,"⚠*")>0,"● ⚠ が "&COUNTIF('②発注する'!$O$10:$O$409,"⚠*")&"件あります。STEP 2 で直すまで発注書に載りません",IF(SUM('計算'!$CM$6:$CM$405)=0,"入庫を入れた商品はまだありません","○ "&SUM('計算'!$CM$6:$CM$405)&"品目を発注します"))
B21: 随時
C23: 動員を入れる › | D23: =COUNTIFS('動員を入れる'!$B$16:$B$415,">="&N('設定'!$C$6),'動員を入れる'!$B$16:$B$415,"<="&(N('設定'!$C$6)+13),'動員を入れる'!$D$16:$D$415,">0")
C24: 予測動員を入れると減り数のスピードが変わります。実績は月1回まとめてでも。 | D24: これから14日で予測が入っている日
C25: =IF('計算'!$B$2=1,"● これから14日が表の外です。「表の開始日」を今年の日付にしてください",IF('計算'!$B$3=0,"● 動員が0です。標準の動員（設定）か予測を入れてください",IF(COUNTIFS('動員を入れる'!$B$16:$B$415,">="&N('設定'!$C$6),'動員を入れる'!$B$16:$B$415,"<="&(N('設定'!$C$6)+13),'動員を入れる'!$D$16:$D$415,">0")<14,"△ 予測が無い日は曜日の実績平均（無ければ標準の動員）を使います","○ 14日分そろっています")))
B27: 月1回・社員
C28: 月1回_1ヶ月前の在庫 › | D28: =IF(COUNTIF('月1回_1ヶ月前の在庫'!$V$6:$V$10005,'設定'!$C$4)=0,"未使用（貼らなくても動きます）","○ 貼れています（"&TEXT('設定'!$C$12,"m/d")&" の在庫）")
C29: 取扱商品が変わっていないかの確認用。1ヶ月前の在庫CSVを貼り替えます。
C30: 月1回_2ヶ月前の在庫 › | D30: =IF(COUNTIF('月1回_2ヶ月前の在庫'!$V$6:$V$10005,'設定'!$C$4)=0,"未使用（貼らなくても動きます）","○ 貼れています（"&TEXT('設定'!$C$13,"m/d")&" の在庫）")
C31: 同じく2ヶ月前の在庫CSV。半年ごとに入れ替わる商品もこれで漏れません。
C32: 商品マスタ › | D32: =IF('設定'!$C$11=0,"",IF('設定'!$C$17+'設定'!$C$18+'設定'!$C$19>0,"● マスタに無い商品が "&('設定'!$C$17+'設定'!$C$18+'設定'!$C$19)&"件（②の末尾に出ています）→ マスタに追加して減り数を入れる",IF('設定'!$C$14<'設定'!$C$20,"● 減り数が未設定の商品が "&('設定'!$C$20-'設定'!$C$14)&"件あります","○ 減り数はすべて設定済み（定数 "&'設定'!$C$15&"/"&'設定'!$C$20&"）")))
C33: 定数（最大保管数）と、100人あたりの減り数を商品ごとに決めます。
C34: 劇場マスタ ›
C35: 劇場コードと名前。CSVの劇場コードと一致しているか照合できます。
C36: 設定 ›
C37: 対象劇場・発注から入庫までの日数・標準の動員・担当者・仕入先一覧。
C38: つかいかた ›
C39: 色の意味と、迷ったときの読み方。
B41: 黄色のセルだけ入力します。それ以外は保護されていて書き換えられません。

Sheet ①在庫を貼る
B1: STEP 1 在庫を貼る | N1: ◀ ホーム
B2: 在庫を貼る | H2: =IF(COUNTIF($V$6:$V$10005,'設定'!$C$4)=0,"✖ まだ貼れていません","✔ "&COUNTIF($V$6:$V$10005,'設定'!$C$4)&"行 読み込めました")
B3: 在庫システムから出した「今日の在庫一覧CSV」を貼ります。これが今の在庫になります。 | H3: =IF(COUNTIF($V$6:$V$10005,'設定'!$C$4)=0,"CSVの見出し行を除いたデータを A6 セルに貼り付けてください。貼ったのに0のままなら、設定の劇場コードとCSVの劇場コードが違います。",IF('設定'!$C$11>400,"⚠ 取扱商品が "&'設定'!$C$11&" 件あります。計算できるのは 400 件までなので、超えた分は発注画面に出ません。",IF(COUNTIF($A$6:$A$10005,"<>"&INDEX($A$6:$A$10005,MATCH('設定'!$C$4,$V$6:$V$10005,0)))-COUNTBLANK($A$6:$A$10005)>0,"⚠ 日付の違う行が混ざっています。前のデータを消してから同じ日のCSVだけを貼ってください。",IF('設定'!$C$21>0,"⚠ 同じ商品コードの行が "&'設定'!$C$21&" 件重なっています（在庫は合算して1行で出します）。貼り替えのときに前のデータを消し忘れていませんか。","対象劇場："&'設定'!$C$4&" "&'設定'!$C$5&" CSVの日付："&TEXT('設定'!$C$6,"yyyy/m/d")))))
B4: CSVの見出し行を除いたデータを、A6 セルに貼り付けてください。貼り替えは A6 から S 列までを消してから。 | U4: ← この右の3列は自動です。消さないでください（消えたら社員に）。
A5: 対象日付 | B5: 劇場コード | C5: 劇場名 | D5: 支払先コード | E5: 支払先名 | F5: 大分類コード | G5: 小分類コード | H5: 商品分類名 | I5: 商品コード | J5: 商品名 | K5: 入数 | L5: 在庫数ケース | M5: 在庫数バラ | N5: 総数 | O5: 規定数 | P5: 資産廃棄 | Q5: 税抜単価 | R5: 仕入税区分 | S5: 仕入税率 | U5: マスタに無い商品の連番(自動) | V5: 劇場コード(自動) | W5: 商品コード(自動)
U6: =IF(AND($V6='設定'!$C$4,COUNTIF('商品マスタ'!$B$6:$B$1005,$W6)=0),N(U5)+1,N(U5)) | V6: =IF($B6="","",TEXT($B6,"0000")) | W6: =IF($I6="","",IF(ISNUMBER($I6),TEXT($I6,"0"),$I6))
U7: =IF(AND($V7='設定'!$C$4,COUNTIF('商品マスタ'!$B$6:$B$1005,$W7)=0),N(U6)+1,N(U6)) | V7: =IF($B7="","",TEXT($B7,"0000")) | W7: =IF($I7="","",IF(ISNUMBER($I7),TEXT($I7,"0"),$I7))
U8: =IF(AND($V8='設定'!$C$4,COUNTIF('商品マスタ'!$B$6:$B$1005,$W8)=0),N(U7)+1,N(U7)) | V8: =IF($B8="","",TEXT($B8,"0000")) | W8: =IF($I8="","",IF(ISNUMBER($I8),TEXT($I8,"0"),$I8))
U9: =IF(AND($V9='設定'!$C$4,COUNTIF('商品マスタ'!$B$6:$B$1005,$W9)=0),N(U8)+1,N(U8)) | V9: =IF($B9="","",TEXT($B9,"0000")) | W9: =IF($I9="","",IF(ISNUMBER($I9),TEXT($I9,"0"),$I9))
U10: =IF(AND($V10='設定'!$C$4,COUNTIF('商品マスタ'!$B$6:$B$1005,$W10)=0),N(U9)+1,N(U9)) | V10: =IF($B10="","",TEXT($B10,"0000")) | W10: =IF($I10="","",IF(ISNUMBER($I10),TEXT($I10,"0"),$I10))
U11: =IF(AND($V11='設定'!$C$4,COUNTIF('商品マスタ'!$B$6:$B$1005,$W11)=0),N(U10)+1,N(U10)) | V11: =IF($B11="","",TEXT($B11,"0000")) | W11: =IF($I11="","",IF(ISNUMBER($I11),TEXT($I11,"0"),$I11))
U12: =IF(AND($V12='設定'!$C$4,COUNTIF('商品マスタ'!$B$6:$B$1005,$W12)=0),N(U11)+1,N(U11)) | V12: =IF($B12="","",TEXT($B12,"0000")) | W12: =IF($I12="","",IF(ISNUMBER($I12),TEXT($I12,"0"),$I12))
U13: =IF(AND($V13='設定'!$C$4,COUNTIF('商品マスタ'!$B$6:$B$1005,$W13)=0),N(U12)+1,N(U12)) | V13: =IF($B13="","",TEXT($B13,"0000")) | W13: =IF($I13="","",IF(ISNUMBER($I13),TEXT($I13,"0"),$I13))
U14: =IF(AND($V14='設定'!$C$4,COUNTIF('商品マスタ'!$B$6:$B$1005,$W14)=0),N(U13)+1,N(U13)) | V14: =IF($B14="","",TEXT($B14,"0000")) | W14: =IF($I14="","",IF(ISNUMBER($I14),TEXT($I14,"0"),$I14))
U15: =IF(AND($V15='設定'!$C$4,COUNTIF('商品マスタ'!$B$6:$B$1005,$W15)=0),N(U14)+1,N(U14)) | V15: =IF($B15="","",TEXT($B15,"0000")) | W15: =IF($I15="","",IF(ISNUMBER($I15),TEXT($I15,"0"),$I15))
U16: =IF(AND($V16='設定'!$C$4,COUNTIF('商品マスタ'!$B$6:$B$1005,$W16)=0),N(U15)+1,N(U15)) | V16: =IF($B16="","",TEXT($B16,"0000")) | W16: =IF($I16="","",IF(ISNUMBER($I16),TEXT($I16,"0"),$I16))
U17: =IF(AND($V17='設定'!$C$4,COUNTIF('商品マスタ'!$B$6:$B$1005,$W17)=0),N(U16)+1,N(U16)) | V17: =IF($B17="","",TEXT($B17,"0000")) | W17: =IF($I17="","",IF(ISNUMBER($I17),TEXT($I17,"0"),$I17))
... U10005: =IF(AND($V10005='設定'!$C$4,COUNTIF('商品マスタ'!$B$6:$B$1005,$W10005)=0),N(U10004)+1,N(U10004)) | V10005: =IF($B10005="","",TEXT($B10005,"0000")) | W10005: =IF($I10005="","",IF(ISNUMBER($I10005),TEXT($I10005,"0"),$I10005))

Sheet ②発注する
B1: STEP 2 発注する | AH1: ◀ ホーム
B2: 発注する | E2: =IF('設定'!$C$6="","← まず ①在庫を貼る",IF('設定'!$C$6<TODAY()-1,"⚠ 在庫が "&TEXT('設定'!$C$6,"m/d")&" のものです（"&(TODAY()-'設定'!$C$6)&"日前）→ 今日のCSVを ①在庫を貼る に貼ってください","きょう "&TEXT('設定'!$C$6,"m/d")&"("&CHOOSE(WEEKDAY('設定'!$C$6),"日","月","火","水","木","金","土")&")"&" "&'設定'!$C$5&" CSV "&'設定'!$C$10&"行"))
C4: ● 今日発注しないと間に合わない | D4: △ 近く切れる | H4: ⚠ 直すところ（直すまで発注書に載らない） | I4: 入庫を入れた（発注書に載る） | M4: 発注予定額（税抜） | P4: =IF('計算'!$B$2=1,"⚠ これから14日が動員の表の外です。「動員を入れる」の表の開始日を今年の日付にしてください。",IF('計算'!$B$3=0,"⚠ 動員が入っていません。減り数が計算できないので「動員を入れる」か「設定」の標準の動員を入れてください。","これから14日の動員：平均 "&TEXT('設定'!$C$16,"#,##0")&" 人/日 "&"数字はその日の終わりの在庫。× は切れている。黄色は入庫の日。"))
C5: =COUNTIF($H$10:$H$409,"●*") | D5: =COUNTIF($H$10:$H$409,"△*") | H5: =COUNTIF($O$10:$O$409,"⚠*") | I5: =SUM('計算'!$CM$6:$CM$405) | M5: =SUM('計算'!$CN$6:$CN$405)
B7: 読み方：左から順に。「このままだと」が ● か △ なら、黄色の入庫日（▼で選ぶ）と入庫数を入れる → 「入庫を入れると」で結果を確認。迷ったら「目安」の数。⚠ は直す。2便目は14日のうちに2回入るときだけ。 | O7: 動員 → | P7: =IF(P9="","",'計算'!V$4) | Q7: =IF(Q9="","",'計算'!W$4) | R7: =IF(R9="","",'計算'!X$4) | S7: =IF(S9="","",'計算'!Y$4) | T7: =IF(T9="","",'計算'!Z$4) | U7: =IF(U9="","",'計算'!AA$4) | V7: =IF(V9="","",'計算'!AB$4) | W7: =IF(W9="","",'計算'!AC$4) | ... AC7: =IF(AC9="","",'計算'!AI$4)
D8: 自動 | E8: 自動 | F8: 自動 | G8: 自動 | H8: 自動 | I8: 入力 | J8: 入力 | K8: 自動 | L8: 自動 | M8: 任意 | N8: 任意 | O8: 自動 | P8: =IF(P9="","",CHOOSE(WEEKDAY(P9),"日","月","火","水","木","金","土")) | Q8: =IF(Q9="","",CHOOSE(WEEKDAY(Q9),"日","月","火","水","木","金","土")) | R8: =IF(R9="","",CHOOSE(WEEKDAY(R9),"日","月","火","水","木","金","土")) | S8: =IF(S9="","",CHOOSE(WEEKDAY(S9),"日","月","火","水","木","金","土")) | T8: =IF(T9="","",CHOOSE(WEEKDAY(T9),"日","月","火","水","木","金","土")) | U8: =IF(U9="","",CHOOSE(WEEKDAY(U9),"日","月","火","水","木","金","土")) | V8: =IF(V9="","",CHOOSE(WEEKDAY(V9),"日","月","火","水","木","金","土")) | W8: =IF(W9="","",CHOOSE(WEEKDAY(W9),"日","月","火","水","木","金","土")) | ... AC8: =IF(AC9="","",CHOOSE(WEEKDAY(AC9),"日","月","火","水","木","金","土")) | AD8: 任意 | AE8: 任意 | AF8: 自動 | AG8: 自動
B9: No | C9: 商品名 | D9: 定数(個) | E9: 在庫(個) | F9: 減り数/日 | G9: 切れる日 | H9: このままだと | I9: 入庫日 (届く日) | J9: 入庫数 | K9: 単位 | L9: 目安 | M9: 2便目 入庫日 | N9: 2便目 入庫数 | O9: 入庫を入れると | P9: =IF('設定'!$C$6="","",'設定'!$C$6+0) | Q9: =IF('設定'!$C$6="","",'設定'!$C$6+1) | R9: =IF('設定'!$C$6="","",'設定'!$C$6+2) | S9: =IF('設定'!$C$6="","",'設定'!$C$6+3) | T9: =IF('設定'!$C$6="","",'設定'!$C$6+4) | U9: =IF('設定'!$C$6="","",'設定'!$C$6+5) | V9: =IF('設定'!$C$6="","",'設定'!$C$6+6) | W9: =IF('設定'!$C$6="","",'設定'!$C$6+7) | X9: =IF('設定'!$C$6="","",'設定'!$C$6+8) | Y9: =IF('設定'!$C$6="","",'設定'!$C$6+9) | Z9: =IF('設定'!$C$6="","",'設定'!$C$6+10) | AA9: =IF('設定'!$C$6="","",'設定'!$C$6+11) | AB9: =IF('設定'!$C$6="","",'設定'!$C$6+12) | AC9: =IF('設定'!$C$6="","",'設定'!$C$6+13) | AD9: 数えた在庫 | AE9: 数えた日 | AF9: 商品コード | AG9: 仕入先
B10: =IF('計算'!$C6="","",'計算'!$B6) | C10: =IF('計算'!$C6="","",'計算'!$D6) | D10: =IF('計算'!$C6="","",'計算'!$O6) | E10: =IF('計算'!$C6="","",'計算'!$L6) | F10: =IF('計算'!$C6="","",'計算'!$CD6) | G10: =IF('計算'!$C6="","",'計算'!$CA6) | H10: =IF('計算'!$C6="","",'計算'!$CP6) | K10: =IF('計算'!$C6="","",'計算'!$CR6) | L10: =IF('計算'!$C6="","",'計算'!$CF6) | O10: =IF('計算'!$C6="","",'計算'!$CQ6) | P10: =IF('計算'!$C6="","",IF('計算'!$M6="","",'計算'!$AX6)) | Q10: =IF('計算'!$C6="","",IF('計算'!$M6="","",'計算'!$AY6)) | R10: =IF('計算'!$C6="","",IF('計算'!$M6="","",'計算'!$AZ6)) | S10: =IF('計算'!$C6="","",IF('計算'!$M6="","",'計算'!$BA6)) | T10: =IF('計算'!$C6="","",IF('計算'!$M6="","",'計算'!$BB6)) | U10: =IF('計算'!$C6="","",IF('計算'!$M6="","",'計算'!$BC6)) | V10: =IF('計算'!$C6="","",IF('計算'!$M6="","",'計算'!$BD6)) | W10: =IF('計算'!$C6="","",IF('計算'!$M6="","",'計算'!$BE6)) | X10: =IF('計算'!$C6="","",IF('計算'!$M6="","",'計算'!$BF6)) | Y10: =IF('計算'!$C6="","",IF('計算'!$M6="","",'計算'!$BG6)) | Z10: =IF('計算'!$C6="","",IF('計算'!$M6="","",'計算'!$BH6)) | AA10: =IF('計算'!$C6="","",IF('計算'!$M6="","",'計算'!$BI6)) | AB10: =IF('計算'!$C6="","",IF('計算'!$M6="","",'計算'!$BJ6)) | AC10: =IF('計算'!$C6="","",IF('計算'!$M6="","",'計算'!$BK6)) | AF10: =IF('計算'!$C6="","",'計算'!$C6) | AG10: =IF('計算'!$C6="","",'計算'!$F6)
B11: =IF('計算'!$C7="","",'計算'!$B7) | C11: =IF('計算'!$C7="","",'計算'!$D7) | D11: =IF('計算'!$C7="","",'計算'!$O7) | E11: =IF('計算'!$C7="","",'計算'!$L7) | F11: =IF('計算'!$C7="","",'計算'!$CD7) | G11: =IF('計算'!$C7="","",'計算'!$CA7) | H11: =IF('計算'!$C7="","",'計算'!$CP7) | K11: =IF('計算'!$C7="","",'計算'!$CR7) | L11: =IF('計算'!$C7="","",'計算'!$CF7) | O11: =IF('計算'!$C7="","",'計算'!$CQ7) | P11: =IF('計算'!$C7="","",IF('計算'!$M7="","",'計算'!$AX7)) | Q11: =IF('計算'!$C7="","",IF('計算'!$M7="","",'計算'!$AY7)) | R11: =IF('計算'!$C7="","",IF('計算'!$M7="","",'計算'!$AZ7)) | S11: =IF('計算'!$C7="","",IF('計算'!$M7="","",'計算'!$BA7)) | T11: =IF('計算'!$C7="","",IF('計算'!$M7="","",'計算'!$BB7)) | U11: =IF('計算'!$C7="","",IF('計算'!$M7="","",'計算'!$BC7)) | V11: =IF('計算'!$C7="","",IF('計算'!$M7="","",'計算'!$BD7)) | W11: =IF('計算'!$C7="","",IF('計算'!$M7="","",'計算'!$BE7)) | X11: =IF('計算'!$C7="","",IF('計算'!$M7="","",'計算'!$BF7)) | Y11: =IF('計算'!$C7="","",IF('計算'!$M7="","",'計算'!$BG7)) | Z11: =IF('計算'!$C7="","",IF('計算'!$M7="","",'計算'!$BH7)) | AA11: =IF('計算'!$C7="","",IF('計算'!$M7="","",'計算'!$BI7)) | AB11: =IF('計算'!$C7="","",IF('計算'!$M7="","",'計算'!$BJ7)) | AC11: =IF('計算'!$C7="","",IF('計算'!$M7="","",'計算'!$BK7)) | AF11: =IF('計算'!$C7="","",'計算'!$C7) | AG11: =IF('計算'!$C7="","",'計算'!$F7)
B12: =IF('計算'!$C8="","",'計算'!$B8) | C12: =IF('計算'!$C8="","",'計算'!$D8) | D12: =IF('計算'!$C8="","",'計算'!$O8) | E12: =IF('計算'!$C8="","",'計算'!$L8) | F12: =IF('計算'!$C8="","",'計算'!$CD8) | G12: =IF('計算'!$C8="","",'計算'!$CA8) | H12: =IF('計算'!$C8="","",'計算'!$CP8) | K12: =IF('計算'!$C8="","",'計算'!$CR8) | L12: =IF('計算'!$C8="","",'計算'!$CF8) | O12: =IF('計算'!$C8="","",'計算'!$CQ8) | P12: =IF('計算'!$C8="","",IF('計算'!$M8="","",'計算'!$AX8)) | Q12: =IF('計算'!$C8="","",IF('計算'!$M8="","",'計算'!$AY8)) | R12: =IF('計算'!$C8="","",IF('計算'!$M8="","",'計算'!$AZ8)) | S12: =IF('計算'!$C8="","",IF('計算'!$M8="","",'計算'!$BA8)) | T12: =IF('計算'!$C8="","",IF('計算'!$M8="","",'計算'!$BB8)) | U12: =IF('計算'!$C8="","",IF('計算'!$M8="","",'計算'!$BC8)) | V12: =IF('計算'!$C8="","",IF('計算'!$M8="","",'計算'!$BD8)) | W12: =IF('計算'!$C8="","",IF('計算'!$M8="","",'計算'!$BE8)) | X12: =IF('計算'!$C8="","",IF('計算'!$M8="","",'計算'!$BF8)) | Y12: =IF('計算'!$C8="","",IF('計算'!$M8="","",'計算'!$BG8)) | Z12: =IF('計算'!$C8="","",IF('計算'!$M8="","",'計算'!$BH8)) | AA12: =IF('計算'!$C8="","",IF('計算'!$M8="","",'計算'!$BI8)) | AB12: =IF('計算'!$C8="","",IF('計算'!$M8="","",'計算'!$BJ8)) | AC12: =IF('計算'!$C8="","",IF('計算'!$M8="","",'計算'!$BK8)) | AF12: =IF('計算'!$C8="","",'計算'!$C8) | AG12: =IF('計算'!$C8="","",'計算'!$F8)
B13: =IF('計算'!$C9="","",'計算'!$B9) | C13: =IF('計算'!$C9="","",'計算'!$D9) | D13: =IF('計算'!$C9="","",'計算'!$O9) | E13: =IF('計算'!$C9="","",'計算'!$L9) | F13: =IF('計算'!$C9="","",'計算'!$CD9) | G13: =IF('計算'!$C9="","",'計算'!$CA9) | H13: =IF('計算'!$C9="","",'計算'!$CP9) | K13: =IF('計算'!$C9="","",'計算'!$CR9) | L13: =IF('計算'!$C9="","",'計算'!$CF9) | O13: =IF('計算'!$C9="","",'計算'!$CQ9) | P13: =IF('計算'!$C9="","",IF('計算'!$M9="","",'計算'!$AX9)) | Q13: =IF('計算'!$C9="","",IF('計算'!$M9="","",'計算'!$AY9)) | R13: =IF('計算'!$C9="","",IF('計算'!$M9="","",'計算'!$AZ9)) | S13: =IF('計算'!$C9="","",IF('計算'!$M9="","",'計算'!$BA9)) | T13: =IF('計算'!$C9="","",IF('計算'!$M9="","",'計算'!$BB9)) | U13: =IF('計算'!$C9="","",IF('計算'!$M9="","",'計算'!$BC9)) | V13: =IF('計算'!$C9="","",IF('計算'!$M9="","",'計算'!$BD9)) | W13: =IF('計算'!$C9="","",IF('計算'!$M9="","",'計算'!$BE9)) | X13: =IF('計算'!$C9="","",IF('計算'!$M9="","",'計算'!$BF9)) | Y13: =IF('計算'!$C9="","",IF('計算'!$M9="","",'計算'!$BG9)) | Z13: =IF('計算'!$C9="","",IF('計算'!$M9="","",'計算'!$BH9)) | AA13: =IF('計算'!$C9="","",IF('計算'!$M9="","",'計算'!$BI9)) | AB13: =IF('計算'!$C9="","",IF('計算'!$M9="","",'計算'!$BJ9)) | AC13: =IF('計算'!$C9="","",IF('計算'!$M9="","",'計算'!$BK9)) | AF13: =IF('計算'!$C9="","",'計算'!$C9) | AG13: =IF('計算'!$C9="","",'計算'!$F9)
B14: =IF('計算'!$C10="","",'計算'!$B10) | C14: =IF('計算'!$C10="","",'計算'!$D10) | D14: =IF('計算'!$C10="","",'計算'!$O10) | E14: =IF('計算'!$C10="","",'計算'!$L10) | F14: =IF('計算'!$C10="","",'計算'!$CD10) | G14: =IF('計算'!$C10="","",'計算'!$CA10) | H14: =IF('計算'!$C10="","",'計算'!$CP10) | K14: =IF('計算'!$C10="","",'計算'!$CR10) | L14: =IF('計算'!$C10="","",'計算'!$CF10) | O14: =IF('計算'!$C10="","",'計算'!$CQ10) | P14: =IF('計算'!$C10="","",IF('計算'!$M10="","",'計算'!$AX10)) | Q14: =IF('計算'!$C10="","",IF('計算'!$M10="","",'計算'!$AY10)) | R14: =IF('計算'!$C10="","",IF('計算'!$M10="","",'計算'!$AZ10)) | S14: =IF('計算'!$C10="","",IF('計算'!$M10="","",'計算'!$BA10)) | T14: =IF('計算'!$C10="","",IF('計算'!$M10="","",'計算'!$BB10)) | U14: =IF('計算'!$C10="","",IF('計算'!$M10="","",'計算'!$BC10)) | V14: =IF('計算'!$C10="","",IF('計算'!$M10="","",'計算'!$BD10)) | W14: =IF('計算'!$C10="","",IF('計算'!$M10="","",'計算'!$BE10)) | X14: =IF('計算'!$C10="","",IF('計算'!$M10="","",'計算'!$BF10)) | Y14: =IF('計算'!$C10="","",IF('計算'!$M10="","",'計算'!$BG10)) | Z14: =IF('計算'!$C10="","",IF('計算'!$M10="","",'計算'!$BH10)) | AA14: =IF('計算'!$C10="","",IF('計算'!$M10="","",'計算'!$BI10)) | AB14: =IF('計算'!$C10="","",IF('計算'!$M10="","",'計算'!$BJ10)) | AC14: =IF('計算'!$C10="","",IF('計算'!$M10="","",'計算'!$BK10)) | AF14: =IF('計算'!$C10="","",'計算'!$C10) | AG14: =IF('計算'!$C10="","",'計算'!$F10)
B15: =IF('計算'!$C11="","",'計算'!$B11) | C15: =IF('計算'!$C11="","",'計算'!$D11) | D15: =IF('計算'!$C11="","",'計算'!$O11) | E15: =IF('計算'!$C11="","",'計算'!$L11) | F15: =IF('計算'!$C11="","",'計算'!$CD11) | G15: =IF('計算'!$C11="","",'計算'!$CA11) | H15: =IF('計算'!$C11="","",'計算'!$CP11) | K15: =IF('計算'!$C11="","",'計算'!$CR11) | L15: =IF('計算'!$C11="","",'計算'!$CF11) | O15: =IF('計算'!$C11="","",'計算'!$CQ11) | P15: =IF('計算'!$C11="","",IF('計算'!$M11="","",'計算'!$AX11)) | Q15: =IF('計算'!$C11="","",IF('計算'!$M11="","",'計算'!$AY11)) | R15: =IF('計算'!$C11="","",IF('計算'!$M11="","",'計算'!$AZ11)) | S15: =IF('計算'!$C11="","",IF('計算'!$M11="","",'計算'!$BA11)) | T15: =IF('計算'!$C11="","",IF('計算'!$M11="","",'計算'!$BB11)) | U15: =IF('計算'!$C11="","",IF('計算'!$M11="","",'計算'!$BC11)) | V15: =IF('計算'!$C11="","",IF('計算'!$M11="","",'計算'!$BD11)) | W15: =IF('計算'!$C11="","",IF('計算'!$M11="","",'計算'!$BE11)) | X15: =IF('計算'!$C11="","",IF('計算'!$M11="","",'計算'!$BF11)) | Y15: =IF('計算'!$C11="","",IF('計算'!$M11="","",'計算'!$BG11)) | Z15: =IF('計算'!$C11="","",IF('計算'!$M11="","",'計算'!$BH11)) | AA15: =IF('計算'!$C11="","",IF('計算'!$M11="","",'計算'!$BI11)) | AB15: =IF('計算'!$C11="","",IF('計算'!$M11="","",'計算'!$BJ11)) | AC15: =IF('計算'!$C11="","",IF('計算'!$M11="","",'計算'!$BK11)) | AF15: =IF('計算'!$C11="","",'計算'!$C11) | AG15: =IF('計算'!$C11="","",'計算'!$F11)
B16: =IF('計算'!$C12="","",'計算'!$B12) | C16: =IF('計算'!$C12="","",'計算'!$D12) | D16: =IF('計算'!$C12="","",'計算'!$O12) | E16: =IF('計算'!$C12="","",'計算'!$L12) | F16: =IF('計算'!$C12="","",'計算'!$CD12) | G16: =IF('計算'!$C12="","",'計算'!$CA12) | H16: =IF('計算'!$C12="","",'計算'!$CP12) | K16: =IF('計算'!$C12="","",'計算'!$CR12) | L16: =IF('計算'!$C12="","",'計算'!$CF12) | O16: =IF('計算'!$C12="","",'計算'!$CQ12) | P16: =IF('計算'!$C12="","",IF('計算'!$M12="","",'計算'!$AX12)) | Q16: =IF('計算'!$C12="","",IF('計算'!$M12="","",'計算'!$AY12)) | R16: =IF('計算'!$C12="","",IF('計算'!$M12="","",'計算'!$AZ12)) | S16: =IF('計算'!$C12="","",IF('計算'!$M12="","",'計算'!$BA12)) | T16: =IF('計算'!$C12="","",IF('計算'!$M12="","",'計算'!$BB12)) | U16: =IF('計算'!$C12="","",IF('計算'!$M12="","",'計算'!$BC12)) | V16: =IF('計算'!$C12="","",IF('計算'!$M12="","",'計算'!$BD12)) | W16: =IF('計算'!$C12="","",IF('計算'!$M12="","",'計算'!$BE12)) | X16: =IF('計算'!$C12="","",IF('計算'!$M12="","",'計算'!$BF12)) | Y16: =IF('計算'!$C12="","",IF('計算'!$M12="","",'計算'!$BG12)) | Z16: =IF('計算'!$C12="","",IF('計算'!$M12="","",'計算'!$BH12)) | AA16: =IF('計算'!$C12="","",IF('計算'!$M12="","",'計算'!$BI12)) | AB16: =IF('計算'!$C12="","",IF('計算'!$M12="","",'計算'!$BJ12)) | AC16: =IF('計算'!$C12="","",IF('計算'!$M12="","",'計算'!$BK12)) | AF16: =IF('計算'!$C12="","",'計算'!$C12) | AG16: =IF('計算'!$C12="","",'計算'!$F12)
B17: =IF('計算'!$C13="","",'計算'!$B13) | C17: =IF('計算'!$C13="","",'計算'!$D13) | D17: =IF('計算'!$C13="","",'計算'!$O13) | E17: =IF('計算'!$C13="","",'計算'!$L13) | F17: =IF('計算'!$C13="","",'計算'!$CD13) | G17: =IF('計算'!$C13="","",'計算'!$CA13) | H17: =IF('計算'!$C13="","",'計算'!$CP13) | K17: =IF('計算'!$C13="","",'計算'!$CR13) | L17: =IF('計算'!$C13="","",'計算'!$CF13) | O17: =IF('計算'!$C13="","",'計算'!$CQ13) | P17: =IF('計算'!$C13="","",IF('計算'!$M13="","",'計算'!$AX13)) | Q17: =IF('計算'!$C13="","",IF('計算'!$M13="","",'計算'!$AY13)) | R17: =IF('計算'!$C13="","",IF('計算'!$M13="","",'計算'!$AZ13)) | S17: =IF('計算'!$C13="","",IF('計算'!$M13="","",'計算'!$BA13)) | T17: =IF('計算'!$C13="","",IF('計算'!$M13="","",'計算'!$BB13)) | U17: =IF('計算'!$C13="","",IF('計算'!$M13="","",'計算'!$BC13)) | V17: =IF('計算'!$C13="","",IF('計算'!$M13="","",'計算'!$BD13)) | W17: =IF('計算'!$C13="","",IF('計算'!$M13="","",'計算'!$BE13)) | X17: =IF('計算'!$C13="","",IF('計算'!$M13="","",'計算'!$BF13)) | Y17: =IF('計算'!$C13="","",IF('計算'!$M13="","",'計算'!$BG13)) | Z17: =IF('計算'!$C13="","",IF('計算'!$M13="","",'計算'!$BH13)) | AA17: =IF('計算'!$C13="","",IF('計算'!$M13="","",'計算'!$BI13)) | AB17: =IF('計算'!$C13="","",IF('計算'!$M13="","",'計算'!$BJ13)) | AC17: =IF('計算'!$C13="","",IF('計算'!$M13="","",'計算'!$BK13)) | AF17: =IF('計算'!$C13="","",'計算'!$C13) | AG17: =IF('計算'!$C13="","",'計算'!$F13)
B18: =IF('計算'!$C14="","",'計算'!$B14) | C18: =IF('計算'!$C14="","",'計算'!$D14) | D18: =IF('計算'!$C14="","",'計算'!$O14) | E18: =IF('計算'!$C14="","",'計算'!$L14) | F18: =IF('計算'!$C14="","",'計算'!$CD14) | G18: =IF('計算'!$C14="","",'計算'!$CA14) | H18: =IF('計算'!$C14="","",'計算'!$CP14) | K18: =IF('計算'!$C14="","",'計算'!$CR14) | L18: =IF('計算'!$C14="","",'計算'!$CF14) | O18: =IF('計算'!$C14="","",'計算'!$CQ14) | P18: =IF('計算'!$C14="","",IF('計算'!$M14="","",'計算'!$AX14)) | Q18: =IF('計算'!$C14="","",IF('計算'!$M14="","",'計算'!$AY14)) | R18: =IF('計算'!$C14="","",IF('計算'!$M14="","",'計算'!$AZ14)) | S18: =IF('計算'!$C14="","",IF('計算'!$M14="","",'計算'!$BA14)) | T18: =IF('計算'!$C14="","",IF('計算'!$M14="","",'計算'!$BB14)) | U18: =IF('計算'!$C14="","",IF('計算'!$M14="","",'計算'!$BC14)) | V18: =IF('計算'!$C14="","",IF('計算'!$M14="","",'計算'!$BD14)) | W18: =IF('計算'!$C14="","",IF('計算'!$M14="","",'計算'!$BE14)) | X18: =IF('計算'!$C14="","",IF('計算'!$M14="","",'計算'!$BF14)) | Y18: =IF('計算'!$C14="","",IF('計算'!$M14="","",'計算'!$BG14)) | Z18: =IF('計算'!$C14="","",IF('計算'!$M14="","",'計算'!$BH14)) | AA18: =IF('計算'!$C14="","",IF('計算'!$M14="","",'計算'!$BI14)) | AB18: =IF('計算'!$C14="","",IF('計算'!$M14="","",'計算'!$BJ14)) | AC18: =IF('計算'!$C14="","",IF('計算'!$M14="","",'計算'!$BK14)) | AF18: =IF('計算'!$C14="","",'計算'!$C14) | AG18: =IF('計算'!$C14="","",'計算'!$F14)
B19: =IF('計算'!$C15="","",'計算'!$B15) | C19: =IF('計算'!$C15="","",'計算'!$D15) | D19: =IF('計算'!$C15="","",'計算'!$O15) | E19: =IF('計算'!$C15="","",'計算'!$L15) | F19: =IF('計算'!$C15="","",'計算'!$CD15) | G19: =IF('計算'!$C15="","",'計算'!$CA15) | H19: =IF('計算'!$C15="","",'計算'!$CP15) | K19: =IF('計算'!$C15="","",'計算'!$CR15) | L19: =IF('計算'!$C15="","",'計算'!$CF15) | O19: =IF('計算'!$C15="","",'計算'!$CQ15) | P19: =IF('計算'!$C15="","",IF('計算'!$M15="","",'計算'!$AX15)) | Q19: =IF('計算'!$C15="","",IF('計算'!$M15="","",'計算'!$AY15)) | R19: =IF('計算'!$C15="","",IF('計算'!$M15="","",'計算'!$AZ15)) | S19: =IF('計算'!$C15="","",IF('計算'!$M15="","",'計算'!$BA15)) | T19: =IF('計算'!$C15="","",IF('計算'!$M15="","",'計算'!$BB15)) | U19: =IF('計算'!$C15="","",IF('計算'!$M15="","",'計算'!$BC15)) | V19: =IF('計算'!$C15="","",IF('計算'!$M15="","",'計算'!$BD15)) | W19: =IF('計算'!$C15="","",IF('計算'!$M15="","",'計算'!$BE15)) | X19: =IF('計算'!$C15="","",IF('計算'!$M15="","",'計算'!$BF15)) | Y19: =IF('計算'!$C15="","",IF('計算'!$M15="","",'計算'!$BG15)) | Z19: =IF('計算'!$C15="","",IF('計算'!$M15="","",'計算'!$BH15)) | AA19: =IF('計算'!$C15="","",IF('計算'!$M15="","",'計算'!$BI15)) | AB19: =IF('計算'!$C15="","",IF('計算'!$M15="","",'計算'!$BJ15)) | AC19: =IF('計算'!$C15="","",IF('計算'!$M15="","",'計算'!$BK15)) | AF19: =IF('計算'!$C15="","",'計算'!$C15) | AG19: =IF('計算'!$C15="","",'計算'!$F15)
B20: =IF('計算'!$C16="","",'計算'!$B16) | C20: =IF('計算'!$C16="","",'計算'!$D16) | D20: =IF('計算'!$C16="","",'計算'!$O16) | E20: =IF('計算'!$C16="","",'計算'!$L16) | F20: =IF('計算'!$C16="","",'計算'!$CD16) | G20: =IF('計算'!$C16="","",'計算'!$CA16) | H20: =IF('計算'!$C16="","",'計算'!$CP16) | K20: =IF('計算'!$C16="","",'計算'!$CR16) | L20: =IF('計算'!$C16="","",'計算'!$CF16) | O20: =IF('計算'!$C16="","",'計算'!$CQ16) | P20: =IF('計算'!$C16="","",IF('計算'!$M16="","",'計算'!$AX16)) | Q20: =IF('計算'!$C16="","",IF('計算'!$M16="","",'計算'!$AY16)) | R20: =IF('計算'!$C16="","",IF('計算'!$M16="","",'計算'!$AZ16)) | S20: =IF('計算'!$C16="","",IF('計算'!$M16="","",'計算'!$BA16)) | T20: =IF('計算'!$C16="","",IF('計算'!$M16="","",'計算'!$BB16)) | U20: =IF('計算'!$C16="","",IF('計算'!$M16="","",'計算'!$BC16)) | V20: =IF('計算'!$C16="","",IF('計算'!$M16="","",'計算'!$BD16)) | W20: =IF('計算'!$C16="","",IF('計算'!$M16="","",'計算'!$BE16)) | X20: =IF('計算'!$C16="","",IF('計算'!$M16="","",'計算'!$BF16)) | Y20: =IF('計算'!$C16="","",IF('計算'!$M16="","",'計算'!$BG16)) | Z20: =IF('計算'!$C16="","",IF('計算'!$M16="","",'計算'!$BH16)) | AA20: =IF('計算'!$C16="","",IF('計算'!$M16="","",'計算'!$BI16)) | AB20: =IF('計算'!$C16="","",IF('計算'!$M16="","",'計算'!$BJ16)) | AC20: =IF('計算'!$C16="","",IF('計算'!$M16="","",'計算'!$BK16)) | AF20: =IF('計算'!$C16="","",'計算'!$C16) | AG20: =IF('計算'!$C16="","",'計算'!$F16)
B21: =IF('計算'!$C17="","",'計算'!$B17) | C21: =IF('計算'!$C17="","",'計算'!$D17) | D21: =IF('計算'!$C17="","",'計算'!$O17) | E21: =IF('計算'!$C17="","",'計算'!$L17) | F21: =IF('計算'!$C17="","",'計算'!$CD17) | G21: =IF('計算'!$C17="","",'計算'!$CA17) | H21: =IF('計算'!$C17="","",'計算'!$CP17) | K21: =IF('計算'!$C17="","",'計算'!$CR17) | L21: =IF('計算'!$C17="","",'計算'!$CF17) | O21: =IF('計算'!$C17="","",'計算'!$CQ17) | P21: =IF('計算'!$C17="","",IF('計算'!$M17="","",'計算'!$AX17)) | Q21: =IF('計算'!$C17="","",IF('計算'!$M17="","",'計算'!$AY17)) | R21: =IF('計算'!$C17="","",IF('計算'!$M17="","",'計算'!$AZ17)) | S21: =IF('計算'!$C17="","",IF('計算'!$M17="","",'計算'!$BA17)) | T21: =IF('計算'!$C17="","",IF('計算'!$M17="","",'計算'!$BB17)) | U21: =IF('計算'!$C17="","",IF('計算'!$M17="","",'計算'!$BC17)) | V21: =IF('計算'!$C17="","",IF('計算'!$M17="","",'計算'!$BD17)) | W21: =IF('計算'!$C17="","",IF('計算'!$M17="","",'計算'!$BE17)) | X21: =IF('計算'!$C17="","",IF('計算'!$M17="","",'計算'!$BF17)) | Y21: =IF('計算'!$C17="","",IF('計算'!$M17="","",'計算'!$BG17)) | Z21: =IF('計算'!$C17="","",IF('計算'!$M17="","",'計算'!$BH17)) | AA21: =IF('計算'!$C17="","",IF('計算'!$M17="","",'計算'!$BI17)) | AB21: =IF('計算'!$C17="","",IF('計算'!$M17="","",'計算'!$BJ17)) | AC21: =IF('計算'!$C17="","",IF('計算'!$M17="","",'計算'!$BK17)) | AF21: =IF('計算'!$C17="","",'計算'!$C17) | AG21: =IF('計算'!$C17="","",'計算'!$F17)
... B409: =IF('計算'!$C405="","",'計算'!$B405) | C409: =IF('計算'!$C405="","",'計算'!$D405) | D409: =IF('計算'!$C405="","",'計算'!$O405) | E409: =IF('計算'!$C405="","",'計算'!$L405) | F409: =IF('計算'!$C405="","",'計算'!$CD405) | G409: =IF('計算'!$C405="","",'計算'!$CA405) | H409: =IF('計算'!$C405="","",'計算'!$CP405) | K409: =IF('計算'!$C405="","",'計算'!$CR405) | L409: =IF('計算'!$C405="","",'計算'!$CF405) | O409: =IF('計算'!$C405="","",'計算'!$CQ405) | P409: =IF('計算'!$C405="","",IF('計算'!$M405="","",'計算'!$AX405)) | Q409: =IF('計算'!$C405="","",IF('計算'!$M405="","",'計算'!$AY405)) | R409: =IF('計算'!$C405="","",IF('計算'!$M405="","",'計算'!$AZ405)) | S409: =IF('計算'!$C405="","",IF('計算'!$M405="","",'計算'!$BA405)) | T409: =IF('計算'!$C405="","",IF('計算'!$M405="","",'計算'!$BB405)) | U409: =IF('計算'!$C405="","",IF('計算'!$M405="","",'計算'!$BC405)) | V409: =IF('計算'!$C405="","",IF('計算'!$M405="","",'計算'!$BD405)) | W409: =IF('計算'!$C405="","",IF('計算'!$M405="","",'計算'!$BE405)) | X409: =IF('計算'!$C405="","",IF('計算'!$M405="","",'計算'!$BF405)) | Y409: =IF('計算'!$C405="","",IF('計算'!$M405="","",'計算'!$BG405)) | Z409: =IF('計算'!$C405="","",IF('計算'!$M405="","",'計算'!$BH405)) | AA409: =IF('計算'!$C405="","",IF('計算'!$M405="","",'計算'!$BI405)) | AB409: =IF('計算'!$C405="","",IF('計算'!$M405="","",'計算'!$BJ405)) | AC409: =IF('計算'!$C405="","",IF('計算'!$M405="","",'計算'!$BK405)) | AF409: =IF('計算'!$C405="","",'計算'!$C405) | AG409: =IF('計算'!$C405="","",'計算'!$F405)

Sheet ③発注書
B1: STEP 3 発注書を印刷する | K1: ◀ ホーム
B2: 発 注 書
B3: STEP 2 で入庫を入れた商品がここに集まります（⚠ の行は載りません）。仕入先を選んで印刷してください。
B4: 仕入先 | C4: すべて | G4: ← ここを選ぶ
B5: 発注日 | C5: ='設定'!$C$6
B6: 発注元 | C6: ='設定'!$C$4&" "&'設定'!$C$5
B7: 担当者 | C7: ='設定'!$C$9
H8: 合計（税抜） | J8: =SUM($J$11:$J$110)
B10: No | C10: 仕入先 | D10: 商品コード | E10: 商品名 | F10: 入庫日(届く日) | G10: 単位 | H10: 発注数 | I10: 単価 | J10: 金額
B11: =IF(1<=MAX('計算'!$CT$6:$CT$405)+MAX('計算'!$CU$6:$CU$405),1,"") | C11: =IF($B11="","",IF(1<=MAX('計算'!$CT$6:$CT$405),IFERROR(INDEX('計算'!$F$6:$F$405,MATCH(1,'計算'!$CT$6:$CT$405,0)),""),IFERROR(INDEX('計算'!$F$6:$F$405,MATCH(1-MAX('計算'!$CT$6:$CT$405),'計算'!$CU$6:$CU$405,0)),""))) | D11: =IF($B11="","",IF(1<=MAX('計算'!$CT$6:$CT$405),IFERROR(INDEX('計算'!$C$6:$C$405,MATCH(1,'計算'!$CT$6:$CT$405,0))&"",""),IFERROR(INDEX('計算'!$C$6:$C$405,MATCH(1-MAX('計算'!$CT$6:$CT$405),'計算'!$CU$6:$CU$405,0))&"",""))) | E11: =IF($B11="","",IF(1<=MAX('計算'!$CT$6:$CT$405),IFERROR(INDEX('計算'!$D$6:$D$405,MATCH(1,'計算'!$CT$6:$CT$405,0)),""),IFERROR(INDEX('計算'!$D$6:$D$405,MATCH(1-MAX('計算'!$CT$6:$CT$405),'計算'!$CU$6:$CU$405,0)),""))) | F11: =IF($B11="","",IF(1<=MAX('計算'!$CT$6:$CT$405),IFERROR(INDEX('計算'!$P$6:$P$405,MATCH(1,'計算'!$CT$6:$CT$405,0)),""),IFERROR(INDEX('計算'!$S$6:$S$405,MATCH(1-MAX('計算'!$CT$6:$CT$405),'計算'!$CU$6:$CU$405,0)),""))) | G11: =IF($B11="","",IF(1<=MAX('計算'!$CT$6:$CT$405),IFERROR(INDEX('計算'!$CR$6:$CR$405,MATCH(1,'計算'!$CT$6:$CT$405,0)),""),IFERROR(INDEX('計算'!$CR$6:$CR$405,MATCH(1-MAX('計算'!$CT$6:$CT$405),'計算'!$CU$6:$CU$405,0)),""))) | H11: =IF($B11="","",IF(1<=MAX('計算'!$CT$6:$CT$405),IFERROR(INDEX('計算'!$Q$6:$Q$405,MATCH(1,'計算'!$CT$6:$CT$405,0)),""),IFERROR(INDEX('計算'!$T$6:$T$405,MATCH(1-MAX('計算'!$CT$6:$CT$405),'計算'!$CU$6:$CU$405,0)),""))) | I11: =IF($B11="","",IF(1<=MAX('計算'!$CT$6:$CT$405),IFERROR(INDEX('計算'!$H$6:$H$405,MATCH(1,'計算'!$CT$6:$CT$405,0)),""),IFERROR(INDEX('計算'!$H$6:$H$405,MATCH(1-MAX('計算'!$CT$6:$CT$405),'計算'!$CU$6:$CU$405,0)),""))) | J11: =IF($B11="","",N($H11)*IFERROR(INDEX('計算'!$G$6:$G$405,IF(1<=MAX('計算'!$CT$6:$CT$405),MATCH(1,'計算'!$CT$6:$CT$405,0),MATCH(1-MAX('計算'!$CT$6:$CT$405),'計算'!$CU$6:$CU$405,0))),1)*N($I11))
B12: =IF(2<=MAX('計算'!$CT$6:$CT$405)+MAX('計算'!$CU$6:$CU$405),2,"") | C12: =IF($B12="","",IF(2<=MAX('計算'!$CT$6:$CT$405),IFERROR(INDEX('計算'!$F$6:$F$405,MATCH(2,'計算'!$CT$6:$CT$405,0)),""),IFERROR(INDEX('計算'!$F$6:$F$405,MATCH(2-MAX('計算'!$CT$6:$CT$405),'計算'!$CU$6:$CU$405,0)),""))) | D12: =IF($B12="","",IF(2<=MAX('計算'!$CT$6:$CT$405),IFERROR(INDEX('計算'!$C$6:$C$405,MATCH(2,'計算'!$CT$6:$CT$405,0))&"",""),IFERROR(INDEX('計算'!$C$6:$C$405,MATCH(2-MAX('計算'!$CT$6:$CT$405),'計算'!$CU$6:$CU$405,0))&"",""))) | E12: =IF($B12="","",IF(2<=MAX('計算'!$CT$6:$CT$405),IFERROR(INDEX('計算'!$D$6:$D$405,MATCH(2,'計算'!$CT$6:$CT$405,0)),""),IFERROR(INDEX('計算'!$D$6:$D$405,MATCH(2-MAX('計算'!$CT$6:$CT$405),'計算'!$CU$6:$CU$405,0)),""))) | F12: =IF($B12="","",IF(2<=MAX('計算'!$CT$6:$CT$405),IFERROR(INDEX('計算'!$P$6:$P$405,MATCH(2,'計算'!$CT$6:$CT$405,0)),""),IFERROR(INDEX('計算'!$S$6:$S$405,MATCH(2-MAX('計算'!$CT$6:$CT$405),'計算'!$CU$6:$CU$405,0)),""))) | G12: =IF($B12="","",IF(2<=MAX('計算'!$CT$6:$CT$405),IFERROR(INDEX('計算'!$CR$6:$CR$405,MATCH(2,'計算'!$CT$6:$CT$405,0)),""),IFERROR(INDEX('計算'!$CR$6:$CR$405,MATCH(2-MAX('計算'!$CT$6:$CT$405),'計算'!$CU$6:$CU$405,0)),""))) | H12: =IF($B12="","",IF(2<=MAX('計算'!$CT$6:$CT$405),IFERROR(INDEX('計算'!$Q$6:$Q$405,MATCH(2,'計算'!$CT$6:$CT$405,0)),""),IFERROR(INDEX('計算'!$T$6:$T$405,MATCH(2-MAX('計算'!$CT$6:$CT$405),'計算'!$CU$6:$CU$405,0)),""))) | I12: =IF($B12="","",IF(2<=MAX('計算'!$CT$6:$CT$405),IFERROR(INDEX('計算'!$H$6:$H$405,MATCH(2,'計算'!$CT$6:$CT$405,0)),""),IFERROR(INDEX('計算'!$H$6:$H$405,MATCH(2-MAX('計算'!$CT$6:$CT$405),'計算'!$CU$6:$CU$405,0)),""))) | J12: =IF($B12="","",N($H12)*IFERROR(INDEX('計算'!$G$6:$G$405,IF(2<=MAX('計算'!$CT$6:$CT$405),MATCH(2,'計算'!$CT$6:$CT$405,0),MATCH(2-MAX('計算'!$CT$6:$CT$405),'計算'!$CU$6:$CU$405,0))),1)*N($I12))
B13: =IF(3<=MAX('計算'!$CT$6:$CT$405)+MAX('計算'!$CU$6:$CU$405),3,"") | C13: =IF($B13="","",IF(3<=MAX('計算'!$CT$6:$CT$405),IFERROR(INDEX('計算'!$F$6:$F$405,MATCH(3,'計算'!$CT$6:$CT$405,0)),""),IFERROR(INDEX('計算'!$F$6:$F$405,MATCH(3-MAX('計算'!$CT$6:$CT$405),'計算'!$CU$6:$CU$405,0)),""))) | D13: =IF($B13="","",IF(3<=MAX('計算'!$CT$6:$CT$405),IFERROR(INDEX('計算'!$C$6:$C$405,MATCH(3,'計算'!$CT$6:$CT$405,0))&"",""),IFERROR(INDEX('計算'!$C$6:$C$405,MATCH(3-MAX('計算'!$CT$6:$CT$405),'計算'!$CU$6:$CU$405,0))&"",""))) | E13: =IF($B13="","",IF(3<=MAX('計算'!$CT$6:$CT$405),IFERROR(INDEX('計算'!$D$6:$D$405,MATCH(3,'計算'!$CT$6:$CT$405,0)),""),IFERROR(INDEX('計算'!$D$6:$D$405,MATCH(3-MAX('計算'!$CT$6:$CT$405),'計算'!$CU$6:$CU$405,0)),""))) | F13: =IF($B13="","",IF(3<=MAX('計算'!$CT$6:$CT$405),IFERROR(INDEX('計算'!$P$6:$P$405,MATCH(3,'計算'!$CT$6:$CT$405,0)),""),IFERROR(INDEX('計算'!$S$6:$S$405,MATCH(3-MAX('計算'!$CT$6:$CT$405),'計算'!$CU$6:$CU$405,0)),""))) | G13: =IF($B13="","",IF(3<=MAX('計算'!$CT$6:$CT$405),IFERROR(INDEX('計算'!$CR$6:$CR$405,MATCH(3,'計算'!$CT$6:$CT$405,0)),""),IFERROR(INDEX('計算'!$CR$6:$CR$405,MATCH(3-MAX('計算'!$CT$6:$CT$405),'計算'!$CU$6:$CU$405,0)),""))) | H13: =IF($B13="","",IF(3<=MAX('計算'!$CT$6:$CT$405),IFERROR(INDEX('計算'!$Q$6:$Q$405,MATCH(3,'計算'!$CT$6:$CT$405,0)),""),IFERROR(INDEX('計算'!$T$6:$T$405,MATCH(3-MAX('計算'!$CT$6:$CT$405),'計算'!$CU$6:$CU$405,0)),""))) | I13: =IF($B13="","",IF(3<=MAX('計算'!$CT$6:$CT$405),IFERROR(INDEX('計算'!$H$6:$H$405,MATCH(3,'計算'!$CT$6:$CT$405,0)),""),IFERROR(INDEX('計算'!$H$6:$H$405,MATCH(3-MAX('計算'!$CT$6:$CT$405),'計算'!$CU$6:$CU$405,0)),""))) | J13: =IF($B13="","",N($H13)*IFERROR(INDEX('計算'!$G$6:$G$405,IF(3<=MAX('計算'!$CT$6:$CT$405),MATCH(3,'計算'!$CT$6:$CT$405,0),MATCH(3-MAX('計算'!$CT$6:$CT$405),'計算'!$CU$6:$CU$405,0))),1)*N($I13))
B14: =IF(4<=MAX('計算'!$CT$6:$CT$405)+MAX('計算'!$CU$6:$CU$405),4,"") | C14: =IF($B14="","",IF(4<=MAX('計算'!$CT$6:$CT$405),IFERROR(INDEX('計算'!$F$6:$F$405,MATCH(4,'計算'!$CT$6:$CT$405,0)),""),IFERROR(INDEX('計算'!$F$6:$F$405,MATCH(4-MAX('計算'!$CT$6:$CT$405),'計算'!$CU$6:$CU$405,0)),""))) | D14: =IF($B14="","",IF(4<=MAX('計算'!$CT$6:$CT$405),IFERROR(INDEX('計算'!$C$6:$C$405,MATCH(4,'計算'!$CT$6:$CT$405,0))&"",""),IFERROR(INDEX('計算'!$C$6:$C$405,MATCH(4-MAX('計算'!$CT$6:$CT$405),'計算'!$CU$6:$CU$405,0))&"",""))) | E14: =IF($B14="","",IF(4<=MAX('計算'!$CT$6:$CT$405),IFERROR(INDEX('計算'!$D$6:$D$405,MATCH(4,'計算'!$CT$6:$CT$405,0)),""),IFERROR(INDEX('計算'!$D$6:$D$405,MATCH(4-MAX('計算'!$CT$6:$CT$405),'計算'!$CU$6:$CU$405,0)),""))) | F14: =IF($B14="","",IF(4<=MAX('計算'!$CT$6:$CT$405),IFERROR(INDEX('計算'!$P$6:$P$405,MATCH(4,'計算'!$CT$6:$CT$405,0)),""),IFERROR(INDEX('計算'!$S$6:$S$405,MATCH(4-MAX('計算'!$CT$6:$CT$405),'計算'!$CU$6:$CU$405,0)),""))) | G14: =IF($B14="","",IF(4<=MAX('計算'!$CT$6:$CT$405),IFERROR(INDEX('計算'!$CR$6:$CR$405,MATCH(4,'計算'!$CT$6:$CT$405,0)),""),IFERROR(INDEX('計算'!$CR$6:$CR$405,MATCH(4-MAX('計算'!$CT$6:$CT$405),'計算'!$CU$6:$CU$405,0)),""))) | H14: =IF($B14="","",IF(4<=MAX('計算'!$CT$6:$CT$405),IFERROR(INDEX('計算'!$Q$6:$Q$405,MATCH(4,'計算'!$CT$6:$CT$405,0)),""),IFERROR(INDEX('計算'!$T$6:$T$405,MATCH(4-MAX('計算'!$CT$6:$CT$405),'計算'!$CU$6:$CU$405,0)),""))) | I14: =IF($B14="","",IF(4<=MAX('計算'!$CT$6:$CT$405),IFERROR(INDEX('計算'!$H$6:$H$405,MATCH(4,'計算'!$CT$6:$CT$405,0)),""),IFERROR(INDEX('計算'!$H$6:$H$405,MATCH(4-MAX('計算'!$CT$6:$CT$405),'計算'!$CU$6:$CU$405,0)),""))) | J14: =IF($B14="","",N($H14)*IFERROR(INDEX('計算'!$G$6:$G$405,IF(4<=MAX('計算'!$CT$6:$CT$405),MATCH(4,'計算'!$CT$6:$CT$405,0),MATCH(4-MAX('計算'!$CT$6:$CT$405),'計算'!$CU$6:$CU$405,0))),1)*N($I14))
B15: =IF(5<=MAX('計算'!$CT$6:$CT$405)+MAX('計算'!$CU$6:$CU$405),5,"") | C15: =IF($B15="","",IF(5<=MAX('計算'!$CT$6:$CT$405),IFERROR(INDEX('計算'!$F$6:$F$405,MATCH(5,'計算'!$CT$6:$CT$405,0)),""),IFERROR(INDEX('計算'!$F$6:$F$405,MATCH(5-MAX('計算'!$CT$6:$CT$405),'計算'!$CU$6:$CU$405,0)),""))) | D15: =IF($B15="","",IF(5<=MAX('計算'!$CT$6:$CT$405),IFERROR(INDEX('計算'!$C$6:$C$405,MATCH(5,'計算'!$CT$6:$CT$405,0))&"",""),IFERROR(INDEX('計算'!$C$6:$C$405,MATCH(5-MAX('計算'!$CT$6:$CT$405),'計算'!$CU$6:$CU$405,0))&"",""))) | E15: =IF($B15="","",IF(5<=MAX('計算'!$CT$6:$CT$405),IFERROR(INDEX('計算'!$D$6:$D$405,MATCH(5,'計算'!$CT$6:$CT$405,0)),""),IFERROR(INDEX('計算'!$D$6:$D$405,MATCH(5-MAX('計算'!$CT$6:$CT$405),'計算'!$CU$6:$CU$405,0)),""))) | F15: =IF($B15="","",IF(5<=MAX('計算'!$CT$6:$CT$405),IFERROR(INDEX('計算'!$P$6:$P$405,MATCH(5,'計算'!$CT$6:$CT$405,0)),""),IFERROR(INDEX('計算'!$S$6:$S$405,MATCH(5-MAX('計算'!$CT$6:$CT$405),'計算'!$CU$6:$CU$405,0)),""))) | G15: =IF($B15="","",IF(5<=MAX('計算'!$CT$6:$CT$405),IFERROR(INDEX('計算'!$CR$6:$CR$405,MATCH(5,'計算'!$CT$6:$CT$405,0)),""),IFERROR(INDEX('計算'!$CR$6:$CR$405,MATCH(5-MAX('計算'!$CT$6:$CT$405),'計算'!$CU$6:$CU$405,0)),""))) | H15: =IF($B15="","",IF(5<=MAX('計算'!$CT$6:$CT$405),IFERROR(INDEX('計算'!$Q$6:$Q$405,MATCH(5,'計算'!$CT$6:$CT$405,0)),""),IFERROR(INDEX('計算'!$T$6:$T$405,MATCH(5-MAX('計算'!$CT$6:$CT$405),'計算'!$CU$6:$CU$405,0)),""))) | I15: =IF($B15="","",IF(5<=MAX('計算'!$CT$6:$CT$405),IFERROR(INDEX('計算'!$H$6:$H$405,MATCH(5,'計算'!$CT$6:$CT$405,0)),""),IFERROR(INDEX('計算'!$H$6:$H$405,MATCH(5-MAX('計算'!$CT$6:$CT$405),'計算'!$CU$6:$CU$405,0)),""))) | J15: =IF($B15="","",N($H15)*IFERROR(INDEX('計算'!$G$6:$G$405,IF(5<=MAX('計算'!$CT$6:$CT$405),MATCH(5,'計算'!$CT$6:$CT$405,0),MATCH(5-MAX('計算'!$CT$6:$CT$405),'計算'!$CU$6:$CU$405,0))),1)*N($I15))
B16: =IF(6<=MAX('計算'!$CT$6:$CT$405)+MAX('計算'!$CU$6:$CU$405),6,"") | C16: =IF($B16="","",IF(6<=MAX('計算'!$CT$6:$CT$405),IFERROR(INDEX('計算'!$F$6:$F$405,MATCH(6,'計算'!$CT$6:$CT$405,0)),""),IFERROR(INDEX('計算'!$F$6:$F$405,MATCH(6-MAX('計算'!$CT$6:$CT$405),'計算'!$CU$6:$CU$405,0)),""))) | D16: =IF($B16="","",IF(6<=MAX('計算'!$CT$6:$CT$405),IFERROR(INDEX('計算'!$C$6:$C$405,MATCH(6,'計算'!$CT$6:$CT$405,0))&"",""),IFERROR(INDEX('計算'!$C$6:$C$405,MATCH(6-MAX('計算'!$CT$6:$CT$405),'計算'!$CU$6:$CU$405,0))&"",""))) | E16: =IF($B16="","",IF(6<=MAX('計算'!$CT$6:$CT$405),IFERROR(INDEX('計算'!$D$6:$D$405,MATCH(6,'計算'!$CT$6:$CT$405,0)),""),IFERROR(INDEX('計算'!$D$6:$D$405,MATCH(6-MAX('計算'!$CT$6:$CT$405),'計算'!$CU$6:$CU$405,0)),""))) | F16: =IF($B16="","",IF(6<=MAX('計算'!$CT$6:$CT$405),IFERROR(INDEX('計算'!$P$6:$P$405,MATCH(6,'計算'!$CT$6:$CT$405,0)),""),IFERROR(INDEX('計算'!$S$6:$S$405,MATCH(6-MAX('計算'!$CT$6:$CT$405),'計算'!$CU$6:$CU$405,0)),""))) | G16: =IF($B16="","",IF(6<=MAX('計算'!$CT$6:$CT$405),IFERROR(INDEX('計算'!$CR$6:$CR$405,MATCH(6,'計算'!$CT$6:$CT$405,0)),""),IFERROR(INDEX('計算'!$CR$6:$CR$405,MATCH(6-MAX('計算'!$CT$6:$CT$405),'計算'!$CU$6:$CU$405,0)),""))) | H16: =IF($B16="","",IF(6<=MAX('計算'!$CT$6:$CT$405),IFERROR(INDEX('計算'!$Q$6:$Q$405,MATCH(6,'計算'!$CT$6:$CT$405,0)),""),IFERROR(INDEX('計算'!$T$6:$T$405,MATCH(6-MAX('計算'!$CT$6:$CT$405),'計算'!$CU$6:$CU$405,0)),""))) | I16: =IF($B16="","",IF(6<=MAX('計算'!$CT$6:$CT$405),IFERROR(INDEX('計算'!$H$6:$H$405,MATCH(6,'計算'!$CT$6:$CT$405,0)),""),IFERROR(INDEX('計算'!$H$6:$H$405,MATCH(6-MAX('計算'!$CT$6:$CT$405),'計算'!$CU$6:$CU$405,0)),""))) | J16: =IF($B16="","",N($H16)*IFERROR(INDEX('計算'!$G$6:$G$405,IF(6<=MAX('計算'!$CT$6:$CT$405),MATCH(6,'計算'!$CT$6:$CT$405,0),MATCH(6-MAX('計算'!$CT$6:$CT$405),'計算'!$CU$6:$CU$405,0))),1)*N($I16))
B17: =IF(7<=MAX('計算'!$CT$6:$CT$405)+MAX('計算'!$CU$6:$CU$405),7,"") | C17: =IF($B17="","",IF(7<=MAX('計算'!$CT$6:$CT$405),IFERROR(INDEX('計算'!$F$6:$F$405,MATCH(7,'計算'!$CT$6:$CT$405,0)),""),IFERROR(INDEX('計算'!$F$6:$F$405,MATCH(7-MAX('計算'!$CT$6:$CT$405),'計算'!$CU$6:$CU$405,0)),""))) | D17: =IF($B17="","",IF(7<=MAX('計算'!$CT$6:$CT$405),IFERROR(INDEX('計算'!$C$6:$C$405,MATCH(7,'計算'!$CT$6:$CT$405,0))&"",""),IFERROR(INDEX('計算'!$C$6:$C$405,MATCH(7-MAX('計算'!$CT$6:$CT$405),'計算'!$CU$6:$CU$405,0))&"",""))) | E17: =IF($B17="","",IF(7<=MAX('計算'!$CT$6:$CT$405),IFERROR(INDEX('計算'!$D$6:$D$405,MATCH(7,'計算'!$CT$6:$CT$405,0)),""),IFERROR(INDEX('計算'!$D$6:$D$405,MATCH(7-MAX('計算'!$CT$6:$CT$405),'計算'!$CU$6:$CU$405,0)),""))) | F17: =IF($B17="","",IF(7<=MAX('計算'!$CT$6:$CT$405),IFERROR(INDEX('計算'!$P$6:$P$405,MATCH(7,'計算'!$CT$6:$CT$405,0)),""),IFERROR(INDEX('計算'!$S$6:$S$405,MATCH(7-MAX('計算'!$CT$6:$CT$405),'計算'!$CU$6:$CU$405,0)),""))) | G17: =IF($B17="","",IF(7<=MAX('計算'!$CT$6:$CT$405),IFERROR(INDEX('計算'!$CR$6:$CR$405,MATCH(7,'計算'!$CT$6:$CT$405,0)),""),IFERROR(INDEX('計算'!$CR$6:$CR$405,MATCH(7-MAX('計算'!$CT$6:$CT$405),'計算'!$CU$6:$CU$405,0)),""))) | H17: =IF($B17="","",IF(7<=MAX('計算'!$CT$6:$CT$405),IFERROR(INDEX('計算'!$Q$6:$Q$405,MATCH(7,'計算'!$CT$6:$CT$405,0)),""),IFERROR(INDEX('計算'!$T$6:$T$405,MATCH(7-MAX('計算'!$CT$6:$CT$405),'計算'!$CU$6:$CU$405,0)),""))) | I17: =IF($B17="","",IF(7<=MAX('計算'!$CT$6:$CT$405),IFERROR(INDEX('計算'!$H$6:$H$405,MATCH(7,'計算'!$CT$6:$CT$405,0)),""),IFERROR(INDEX('計算'!$H$6:$H$405,MATCH(7-MAX('計算'!$CT$6:$CT$405),'計算'!$CU$6:$CU$405,0)),""))) | J17: =IF($B17="","",N($H17)*IFERROR(INDEX('計算'!$G$6:$G$405,IF(7<=MAX('計算'!$CT$6:$CT$405),MATCH(7,'計算'!$CT$6:$CT$405,0),MATCH(7-MAX('計算'!$CT$6:$CT$405),'計算'!$CU$6:$CU$405,0))),1)*N($I17))
B18: =IF(8<=MAX('計算'!$CT$6:$CT$405)+MAX('計算'!$CU$6:$CU$405),8,"") | C18: =IF($B18="","",IF(8<=MAX('計算'!$CT$6:$CT$405),IFERROR(INDEX('計算'!$F$6:$F$405,MATCH(8,'計算'!$CT$6:$CT$405,0)),""),IFERROR(INDEX('計算'!$F$6:$F$405,MATCH(8-MAX('計算'!$CT$6:$CT$405),'計算'!$CU$6:$CU$405,0)),""))) | D18: =IF($B18="","",IF(8<=MAX('計算'!$CT$6:$CT$405),IFERROR(INDEX('計算'!$C$6:$C$405,MATCH(8,'計算'!$CT$6:$CT$405,0))&"",""),IFERROR(INDEX('計算'!$C$6:$C$405,MATCH(8-MAX('計算'!$CT$6:$CT$405),'計算'!$CU$6:$CU$405,0))&"",""))) | E18: =IF($B18="","",IF(8<=MAX('計算'!$CT$6:$CT$405),IFERROR(INDEX('計算'!$D$6:$D$405,MATCH(8,'計算'!$CT$6:$CT$405,0)),""),IFERROR(INDEX('計算'!$D$6:$D$405,MATCH(8-MAX('計算'!$CT$6:$CT$405),'計算'!$CU$6:$CU$405,0)),""))) | F18: =IF($B18="","",IF(8<=MAX('計算'!$CT$6:$CT$405),IFERROR(INDEX('計算'!$P$6:$P$405,MATCH(8,'計算'!$CT$6:$CT$405,0)),""),IFERROR(INDEX('計算'!$S$6:$S$405,MATCH(8-MAX('計算'!$CT$6:$CT$405),'計算'!$CU$6:$CU$405,0)),""))) | G18: =IF($B18="","",IF(8<=MAX('計算'!$CT$6:$CT$405),IFERROR(INDEX('計算'!$CR$6:$CR$405,MATCH(8,'計算'!$CT$6:$CT$405,0)),""),IFERROR(INDEX('計算'!$CR$6:$CR$405,MATCH(8-MAX('計算'!$CT$6:$CT$405),'計算'!$CU$6:$CU$405,0)),""))) | H18: =IF($B18="","",IF(8<=MAX('計算'!$CT$6:$CT$405),IFERROR(INDEX('計算'!$Q$6:$Q$405,MATCH(8,'計算'!$CT$6:$CT$405,0)),""),IFERROR(INDEX('計算'!$T$6:$T$405,MATCH(8-MAX('計算'!$CT$6:$CT$405),'計算'!$CU$6:$CU$405,0)),""))) | I18: =IF($B18="","",IF(8<=MAX('計算'!$CT$6:$CT$405),IFERROR(INDEX('計算'!$H$6:$H$405,MATCH(8,'計算'!$CT$6:$CT$405,0)),""),IFERROR(INDEX('計算'!$H$6:$H$405,MATCH(8-MAX('計算'!$CT$6:$CT$405),'計算'!$CU$6:$CU$405,0)),""))) | J18: =IF($B18="","",N($H18)*IFERROR(INDEX('計算'!$G$6:$G$405,IF(8<=MAX('計算'!$CT$6:$CT$405),MATCH(8,'計算'!$CT$6:$CT$405,0),MATCH(8-MAX('計算'!$CT$6:$CT$405),'計算'!$CU$6:$CU$405,0))),1)*N($I18))
B19: =IF(9<=MAX('計算'!$CT$6:$CT$405)+MAX('計算'!$CU$6:$CU$405),9,"") | C19: =IF($B19="","",IF(9<=MAX('計算'!$CT$6:$CT$405),IFERROR(INDEX('計算'!$F$6:$F$405,MATCH(9,'計算'!$CT$6:$CT$405,0)),""),IFERROR(INDEX('計算'!$F$6:$F$405,MATCH(9-MAX('計算'!$CT$6:$CT$405),'計算'!$CU$6:$CU$405,0)),""))) | D19: =IF($B19="","",IF(9<=MAX('計算'!$CT$6:$CT$405),IFERROR(INDEX('計算'!$C$6:$C$405,MATCH(9,'計算'!$CT$6:$CT$405,0))&"",""),IFERROR(INDEX('計算'!$C$6:$C$405,MATCH(9-MAX('計算'!$CT$6:$CT$405),'計算'!$CU$6:$CU$405,0))&"",""))) | E19: =IF($B19="","",IF(9<=MAX('計算'!$CT$6:$CT$405),IFERROR(INDEX('計算'!$D$6:$D$405,MATCH(9,'計算'!$CT$6:$CT$405,0)),""),IFERROR(INDEX('計算'!$D$6:$D$405,MATCH(9-MAX('計算'!$CT$6:$CT$405),'計算'!$CU$6:$CU$405,0)),""))) | F19: =IF($B19="","",IF(9<=MAX('計算'!$CT$6:$CT$405),IFERROR(INDEX('計算'!$P$6:$P$405,MATCH(9,'計算'!$CT$6:$CT$405,0)),""),IFERROR(INDEX('計算'!$S$6:$S$405,MATCH(9-MAX('計算'!$CT$6:$CT$405),'計算'!$CU$6:$CU$405,0)),""))) | G19: =IF($B19="","",IF(9<=MAX('計算'!$CT$6:$CT$405),IFERROR(INDEX('計算'!$CR$6:$CR$405,MATCH(9,'計算'!$CT$6:$CT$405,0)),""),IFERROR(INDEX('計算'!$CR$6:$CR$405,MATCH(9-MAX('計算'!$CT$6:$CT$405),'計算'!$CU$6:$CU$405,0)),""))) | H19: =IF($B19="","",IF(9<=MAX('計算'!$CT$6:$CT$405),IFERROR(INDEX('計算'!$Q$6:$Q$405,MATCH(9,'計算'!$CT$6:$CT$405,0)),""),IFERROR(INDEX('計算'!$T$6:$T$405,MATCH(9-MAX('計算'!$CT$6:$CT$405),'計算'!$CU$6:$CU$405,0)),""))) | I19: =IF($B19="","",IF(9<=MAX('計算'!$CT$6:$CT$405),IFERROR(INDEX('計算'!$H$6:$H$405,MATCH(9,'計算'!$CT$6:$CT$405,0)),""),IFERROR(INDEX('計算'!$H$6:$H$405,MATCH(9-MAX('計算'!$CT$6:$CT$405),'計算'!$CU$6:$CU$405,0)),""))) | J19: =IF($B19="","",N($H19)*IFERROR(INDEX('計算'!$G$6:$G$405,IF(9<=MAX('計算'!$CT$6:$CT$405),MATCH(9,'計算'!$CT$6:$CT$405,0),MATCH(9-MAX('計算'!$CT$6:$CT$405),'計算'!$CU$6:$CU$405,0))),1)*N($I19))
B20: =IF(10<=MAX('計算'!$CT$6:$CT$405)+MAX('計算'!$CU$6:$CU$405),10,"") | C20: =IF($B20="","",IF(10<=MAX('計算'!$CT$6:$CT$405),IFERROR(INDEX('計算'!$F$6:$F$405,MATCH(10,'計算'!$CT$6:$CT$405,0)),""),IFERROR(INDEX('計算'!$F$6:$F$405,MATCH(10-MAX('計算'!$CT$6:$CT$405),'計算'!$CU$6:$CU$405,0)),""))) | D20: =IF($B20="","",IF(10<=MAX('計算'!$CT$6:$CT$405),IFERROR(INDEX('計算'!$C$6:$C$405,MATCH(10,'計算'!$CT$6:$CT$405,0))&"",""),IFERROR(INDEX('計算'!$C$6:$C$405,MATCH(10-MAX('計算'!$CT$6:$CT$405),'計算'!$CU$6:$CU$405,0))&"",""))) | E20: =IF($B20="","",IF(10<=MAX('計算'!$CT$6:$CT$405),IFERROR(INDEX('計算'!$D$6:$D$405,MATCH(10,'計算'!$CT$6:$CT$405,0)),""),IFERROR(INDEX('計算'!$D$6:$D$405,MATCH(10-MAX('計算'!$CT$6:$CT$405),'計算'!$CU$6:$CU$405,0)),""))) | F20: =IF($B20="","",IF(10<=MAX('計算'!$CT$6:$CT$405),IFERROR(INDEX('計算'!$P$6:$P$405,MATCH(10,'計算'!$CT$6:$CT$405,0)),""),IFERROR(INDEX('計算'!$S$6:$S$405,MATCH(10-MAX('計算'!$CT$6:$CT$405),'計算'!$CU$6:$CU$405,0)),""))) | G20: =IF($B20="","",IF(10<=MAX('計算'!$CT$6:$CT$405),IFERROR(INDEX('計算'!$CR$6:$CR$405,MATCH(10,'計算'!$CT$6:$CT$405,0)),""),IFERROR(INDEX('計算'!$CR$6:$CR$405,MATCH(10-MAX('計算'!$CT$6:$CT$405),'計算'!$CU$6:$CU$405,0)),""))) | H20: =IF($B20="","",IF(10<=MAX('計算'!$CT$6:$CT$405),IFERROR(INDEX('計算'!$Q$6:$Q$405,MATCH(10,'計算'!$CT$6:$CT$405,0)),""),IFERROR(INDEX('計算'!$T$6:$T$405,MATCH(10-MAX('計算'!$CT$6:$CT$405),'計算'!$CU$6:$CU$405,0)),""))) | I20: =IF($B20="","",IF(10<=MAX('計算'!$CT$6:$CT$405),IFERROR(INDEX('計算'!$H$6:$H$405,MATCH(10,'計算'!$CT$6:$CT$405,0)),""),IFERROR(INDEX('計算'!$H$6:$H$405,MATCH(10-MAX('計算'!$CT$6:$CT$405),'計算'!$CU$6:$CU$405,0)),""))) | J20: =IF($B20="","",N($H20)*IFERROR(INDEX('計算'!$G$6:$G$405,IF(10<=MAX('計算'!$CT$6:$CT$405),MATCH(10,'計算'!$CT$6:$CT$405,0),MATCH(10-MAX('計算'!$CT$6:$CT$405),'計算'!$CU$6:$CU$405,0))),1)*N($I20))
B21: =IF(11<=MAX('計算'!$CT$6:$CT$405)+MAX('計算'!$CU$6:$CU$405),11,"") | C21: =IF($B21="","",IF(11<=MAX('計算'!$CT$6:$CT$405),IFERROR(INDEX('計算'!$F$6:$F$405,MATCH(11,'計算'!$CT$6:$CT$405,0)),""),IFERROR(INDEX('計算'!$F$6:$F$405,MATCH(11-MAX('計算'!$CT$6:$CT$405),'計算'!$CU$6:$CU$405,0)),""))) | D21: =IF($B21="","",IF(11<=MAX('計算'!$CT$6:$CT$405),IFERROR(INDEX('計算'!$C$6:$C$405,MATCH(11,'計算'!$CT$6:$CT$405,0))&"",""),IFERROR(INDEX('計算'!$C$6:$C$405,MATCH(11-MAX('計算'!$CT$6:$CT$405),'計算'!$CU$6:$CU$405,0))&"",""))) | E21: =IF($B21="","",IF(11<=MAX('計算'!$CT$6:$CT$405),IFERROR(INDEX('計算'!$D$6:$D$405,MATCH(11,'計算'!$CT$6:$CT$405,0)),""),IFERROR(INDEX('計算'!$D$6:$D$405,MATCH(11-MAX('計算'!$CT$6:$CT$405),'計算'!$CU$6:$CU$405,0)),""))) | F21: =IF($B21="","",IF(11<=MAX('計算'!$CT$6:$CT$405),IFERROR(INDEX('計算'!$P$6:$P$405,MATCH(11,'計算'!$CT$6:$CT$405,0)),""),IFERROR(INDEX('計算'!$S$6:$S$405,MATCH(11-MAX('計算'!$CT$6:$CT$405),'計算'!$CU$6:$CU$405,0)),""))) | G21: =IF($B21="","",IF(11<=MAX('計算'!$CT$6:$CT$405),IFERROR(INDEX('計算'!$CR$6:$CR$405,MATCH(11,'計算'!$CT$6:$CT$405,0)),""),IFERROR(INDEX('計算'!$CR$6:$CR$405,MATCH(11-MAX('計算'!$CT$6:$CT$405),'計算'!$CU$6:$CU$405,0)),""))) | H21: =IF($B21="","",IF(11<=MAX('計算'!$CT$6:$CT$405),IFERROR(INDEX('計算'!$Q$6:$Q$405,MATCH(11,'計算'!$CT$6:$CT$405,0)),""),IFERROR(INDEX('計算'!$T$6:$T$405,MATCH(11-MAX('計算'!$CT$6:$CT$405),'計算'!$CU$6:$CU$405,0)),""))) | I21: =IF($B21="","",IF(11<=MAX('計算'!$CT$6:$CT$405),IFERROR(INDEX('計算'!$H$6:$H$405,MATCH(11,'計算'!$CT$6:$CT$405,0)),""),IFERROR(INDEX('計算'!$H$6:$H$405,MATCH(11-MAX('計算'!$CT$6:$CT$405),'計算'!$CU$6:$CU$405,0)),""))) | J21: =IF($B21="","",N($H21)*IFERROR(INDEX('計算'!$G$6:$G$405,IF(11<=MAX('計算'!$CT$6:$CT$405),MATCH(11,'計算'!$CT$6:$CT$405,0),MATCH(11-MAX('計算'!$CT$6:$CT$405),'計算'!$CU$6:$CU$405,0))),1)*N($I21))
B22: =IF(12<=MAX('計算'!$CT$6:$CT$405)+MAX('計算'!$CU$6:$CU$405),12,"") | C22: =IF($B22="","",IF(12<=MAX('計算'!$CT$6:$CT$405),IFERROR(INDEX('計算'!$F$6:$F$405,MATCH(12,'計算'!$CT$6:$CT$405,0)),""),IFERROR(INDEX('計算'!$F$6:$F$405,MATCH(12-MAX('計算'!$CT$6:$CT$405),'計算'!$CU$6:$CU$405,0)),""))) | D22: =IF($B22="","",IF(12<=MAX('計算'!$CT$6:$CT$405),IFERROR(INDEX('計算'!$C$6:$C$405,MATCH(12,'計算'!$CT$6:$CT$405,0))&"",""),IFERROR(INDEX('計算'!$C$6:$C$405,MATCH(12-MAX('計算'!$CT$6:$CT$405),'計算'!$CU$6:$CU$405,0))&"",""))) | E22: =IF($B22="","",IF(12<=MAX('計算'!$CT$6:$CT$405),IFERROR(INDEX('計算'!$D$6:$D$405,MATCH(12,'計算'!$CT$6:$CT$405,0)),""),IFERROR(INDEX('計算'!$D$6:$D$405,MATCH(12-MAX('計算'!$CT$6:$CT$405),'計算'!$CU$6:$CU$405,0)),""))) | F22: =IF($B22="","",IF(12<=MAX('計算'!$CT$6:$CT$405),IFERROR(INDEX('計算'!$P$6:$P$405,MATCH(12,'計算'!$CT$6:$CT$405,0)),""),IFERROR(INDEX('計算'!$S$6:$S$405,MATCH(12-MAX('計算'!$CT$6:$CT$405),'計算'!$CU$6:$CU$405,0)),""))) | G22: =IF($B22="","",IF(12<=MAX('計算'!$CT$6:$CT$405),IFERROR(INDEX('計算'!$CR$6:$CR$405,MATCH(12,'計算'!$CT$6:$CT$405,0)),""),IFERROR(INDEX('計算'!$CR$6:$CR$405,MATCH(12-MAX('計算'!$CT$6:$CT$405),'計算'!$CU$6:$CU$405,0)),""))) | H22: =IF($B22="","",IF(12<=MAX('計算'!$CT$6:$CT$405),IFERROR(INDEX('計算'!$Q$6:$Q$405,MATCH(12,'計算'!$CT$6:$CT$405,0)),""),IFERROR(INDEX('計算'!$T$6:$T$405,MATCH(12-MAX('計算'!$CT$6:$CT$405),'計算'!$CU$6:$CU$405,0)),""))) | I22: =IF($B22="","",IF(12<=MAX('計算'!$CT$6:$CT$405),IFERROR(INDEX('計算'!$H$6:$H$405,MATCH(12,'計算'!$CT$6:$CT$405,0)),""),IFERROR(INDEX('計算'!$H$6:$H$405,MATCH(12-MAX('計算'!$CT$6:$CT$405),'計算'!$CU$6:$CU$405,0)),""))) | J22: =IF($B22="","",N($H22)*IFERROR(INDEX('計算'!$G$6:$G$405,IF(12<=MAX('計算'!$CT$6:$CT$405),MATCH(12,'計算'!$CT$6:$CT$405,0),MATCH(12-MAX('計算'!$CT$6:$CT$405),'計算'!$CU$6:$CU$405,0))),1)*N($I22))
B23: =IF(13<=MAX('計算'!$CT$6:$CT$405)+MAX('計算'!$CU$6:$CU$405),13,"") | C23: =IF($B23="","",IF(13<=MAX('計算'!$CT$6:$CT$405),IFERROR(INDEX('計算'!$F$6:$F$405,MATCH(13,'計算'!$CT$6:$CT$405,0)),""),IFERROR(INDEX('計算'!$F$6:$F$405,MATCH(13-MAX('計算'!$CT$6:$CT$405),'計算'!$CU$6:$CU$405,0)),""))) | D23: =IF($B23="","",IF(13<=MAX('計算'!$CT$6:$CT$405),IFERROR(INDEX('計算'!$C$6:$C$405,MATCH(13,'計算'!$CT$6:$CT$405,0))&"",""),IFERROR(INDEX('計算'!$C$6:$C$405,MATCH(13-MAX('計算'!$CT$6:$CT$405),'計算'!$CU$6:$CU$405,0))&"",""))) | E23: =IF($B23="","",IF(13<=MAX('計算'!$CT$6:$CT$405),IFERROR(INDEX('計算'!$D$6:$D$405,MATCH(13,'計算'!$CT$6:$CT$405,0)),""),IFERROR(INDEX('計算'!$D$6:$D$405,MATCH(13-MAX('計算'!$CT$6:$CT$405),'計算'!$CU$6:$CU$405,0)),""))) | F23: =IF($B23="","",IF(13<=MAX('計算'!$CT$6:$CT$405),IFERROR(INDEX('計算'!$P$6:$P$405,MATCH(13,'計算'!$CT$6:$CT$405,0)),""),IFERROR(INDEX('計算'!$S$6:$S$405,MATCH(13-MAX('計算'!$CT$6:$CT$405),'計算'!$CU$6:$CU$405,0)),""))) | G23: =IF($B23="","",IF(13<=MAX('計算'!$CT$6:$CT$405),IFERROR(INDEX('計算'!$CR$6:$CR$405,MATCH(13,'計算'!$CT$6:$CT$405,0)),""),IFERROR(INDEX('計算'!$CR$6:$CR$405,MATCH(13-MAX('計算'!$CT$6:$CT$405),'計算'!$CU$6:$CU$405,0)),""))) | H23: =IF($B23="","",IF(13<=MAX('計算'!$CT$6:$CT$405),IFERROR(INDEX('計算'!$Q$6:$Q$405,MATCH(13,'計算'!$CT$6:$CT$405,0)),""),IFERROR(INDEX('計算'!$T$6:$T$405,MATCH(13-MAX('計算'!$CT$6:$CT$405),'計算'!$CU$6:$CU$405,0)),""))) | I23: =IF($B23="","",IF(13<=MAX('計算'!$CT$6:$CT$405),IFERROR(INDEX('計算'!$H$6:$H$405,MATCH(13,'計算'!$CT$6:$CT$405,0)),""),IFERROR(INDEX('計算'!$H$6:$H$405,MATCH(13-MAX('計算'!$CT$6:$CT$405),'計算'!$CU$6:$CU$405,0)),""))) | J23: =IF($B23="","",N($H23)*IFERROR(INDEX('計算'!$G$6:$G$405,IF(13<=MAX('計算'!$CT$6:$CT$405),MATCH(13,'計算'!$CT$6:$CT$405,0),MATCH(13-MAX('計算'!$CT$6:$CT$405),'計算'!$CU$6:$CU$405,0))),1)*N($I23))
B24: =IF(14<=MAX('計算'!$CT$6:$CT$405)+MAX('計算'!$CU$6:$CU$405),14,"") | C24: =IF($B24="","",IF(14<=MAX('計算'!$CT$6:$CT$405),IFERROR(INDEX('計算'!$F$6:$F$405,MATCH(14,'計算'!$CT$6:$CT$405,0)),""),IFERROR(INDEX('計算'!$F$6:$F$405,MATCH(14-MAX('計算'!$CT$6:$CT$405),'計算'!$CU$6:$CU$405,0)),""))) | D24: =IF($B24="","",IF(14<=MAX('計算'!$CT$6:$CT$405),IFERROR(INDEX('計算'!$C$6:$C$405,MATCH(14,'計算'!$CT$6:$CT$405,0))&"",""),IFERROR(INDEX('計算'!$C$6:$C$405,MATCH(14-MAX('計算'!$CT$6:$CT$405),'計算'!$CU$6:$CU$405,0))&"",""))) | E24: =IF($B24="","",IF(14<=MAX('計算'!$CT$6:$CT$405),IFERROR(INDEX('計算'!$D$6:$D$405,MATCH(14,'計算'!$CT$6:$CT$405,0)),""),IFERROR(INDEX('計算'!$D$6:$D$405,MATCH(14-MAX('計算'!$CT$6:$CT$405),'計算'!$CU$6:$CU$405,0)),""))) | F24: =IF($B24="","",IF(14<=MAX('計算'!$CT$6:$CT$405),IFERROR(INDEX('計算'!$P$6:$P$405,MATCH(14,'計算'!$CT$6:$CT$405,0)),""),IFERROR(INDEX('計算'!$S$6:$S$405,MATCH(14-MAX('計算'!$CT$6:$CT$405),'計算'!$CU$6:$CU$405,0)),""))) | G24: =IF($B24="","",IF(14<=MAX('計算'!$CT$6:$CT$405),IFERROR(INDEX('計算'!$CR$6:$CR$405,MATCH(14,'計算'!$CT$6:$CT$405,0)),""),IFERROR(INDEX('計算'!$CR$6:$CR$405,MATCH(14-MAX('計算'!$CT$6:$CT$405),'計算'!$CU$6:$CU$405,0)),""))) | H24: =IF($B24="","",IF(14<=MAX('計算'!$CT$6:$CT$405),IFERROR(INDEX('計算'!$Q$6:$Q$405,MATCH(14,'計算'!$CT$6:$CT$405,0)),""),IFERROR(INDEX('計算'!$T$6:$T$405,MATCH(14-MAX('計算'!$CT$6:$CT$405),'計算'!$CU$6:$CU$405,0)),""))) | I24: =IF($B24="","",IF(14<=MAX('計算'!$CT$6:$CT$405),IFERROR(INDEX('計算'!$H$6:$H$405,MATCH(14,'計算'!$CT$6:$CT$405,0)),""),IFERROR(INDEX('計算'!$H$6:$H$405,MATCH(14-MAX('計算'!$CT$6:$CT$405),'計算'!$CU$6:$CU$405,0)),""))) | J24: =IF($B24="","",N($H24)*IFERROR(INDEX('計算'!$G$6:$G$405,IF(14<=MAX('計算'!$CT$6:$CT$405),MATCH(14,'計算'!$CT$6:$CT$405,0),MATCH(14-MAX('計算'!$CT$6:$CT$405),'計算'!$CU$6:$CU$405,0))),1)*N($I24))
B25: =IF(15<=MAX('計算'!$CT$6:$CT$405)+MAX('計算'!$CU$6:$CU$405),15,"") | C25: =IF($B25="","",IF(15<=MAX('計算'!$CT$6:$CT$405),IFERROR(INDEX('計算'!$F$6:$F$405,MATCH(15,'計算'!$CT$6:$CT$405,0)),""),IFERROR(INDEX('計算'!$F$6:$F$405,MATCH(15-MAX('計算'!$CT$6:$CT$405),'計算'!$CU$6:$CU$405,0)),""))) | D25: =IF($B25="","",IF(15<=MAX('計算'!$CT$6:$CT$405),IFERROR(INDEX('計算'!$C$6:$C$405,MATCH(15,'計算'!$CT$6:$CT$405,0))&"",""),IFERROR(INDEX('計算'!$C$6:$C$405,MATCH(15-MAX('計算'!$CT$6:$CT$405),'計算'!$CU$6:$CU$405,0))&"",""))) | E25: =IF($B25="","",IF(15<=MAX('計算'!$CT$6:$CT$405),IFERROR(INDEX('計算'!$D$6:$D$405,MATCH(15,'計算'!$CT$6:$CT$405,0)),""),IFERROR(INDEX('計算'!$D$6:$D$405,MATCH(15-MAX('計算'!$CT$6:$CT$405),'計算'!$CU$6:$CU$405,0)),""))) | F25: =IF($B25="","",IF(15<=MAX('計算'!$CT$6:$CT$405),IFERROR(INDEX('計算'!$P$6:$P$405,MATCH(15,'計算'!$CT$6:$CT$405,0)),""),IFERROR(INDEX('計算'!$S$6:$S$405,MATCH(15-MAX('計算'!$CT$6:$CT$405),'計算'!$CU$6:$CU$405,0)),""))) | G25: =IF($B25="","",IF(15<=MAX('計算'!$CT$6:$CT$405),IFERROR(INDEX('計算'!$CR$6:$CR$405,MATCH(15,'計算'!$CT$6:$CT$405,0)),""),IFERROR(INDEX('計算'!$CR$6:$CR$405,MATCH(15-MAX('計算'!$CT$6:$CT$405),'計算'!$CU$6:$CU$405,0)),""))) | H25: =IF($B25="","",IF(15<=MAX('計算'!$CT$6:$CT$405),IFERROR(INDEX('計算'!$Q$6:$Q$405,MATCH(15,'計算'!$CT$6:$CT$405,0)),""),IFERROR(INDEX('計算'!$T$6:$T$405,MATCH(15-MAX('計算'!$CT$6:$CT$405),'計算'!$CU$6:$CU$405,0)),""))) | I25: =IF($B25="","",IF(15<=MAX('計算'!$CT$6:$CT$405),IFERROR(INDEX('計算'!$H$6:$H$405,MATCH(15,'計算'!$CT$6:$CT$405,0)),""),IFERROR(INDEX('計算'!$H$6:$H$405,MATCH(15-MAX('計算'!$CT$6:$CT$405),'計算'!$CU$6:$CU$405,0)),""))) | J25: =IF($B25="","",N($H25)*IFERROR(INDEX('計算'!$G$6:$G$405,IF(15<=MAX('計算'!$CT$6:$CT$405),MATCH(15,'計算'!$CT$6:$CT$405,0),MATCH(15-MAX('計算'!$CT$6:$CT$405),'計算'!$CU$6:$CU$405,0))),1)*N($I25))
B26: =IF(16<=MAX('計算'!$CT$6:$CT$405)+MAX('計算'!$CU$6:$CU$405),16,"") | C26: =IF($B26="","",IF(16<=MAX('計算'!$CT$6:$CT$405),IFERROR(INDEX('計算'!$F$6:$F$405,MATCH(16,'計算'!$CT$6:$CT$405,0)),""),IFERROR(INDEX('計算'!$F$6:$F$405,MATCH(16-MAX('計算'!$CT$6:$CT$405),'計算'!$CU$6:$CU$405,0)),""))) | D26: =IF($B26="","",IF(16<=MAX('計算'!$CT$6:$CT$405),IFERROR(INDEX('計算'!$C$6:$C$405,MATCH(16,'計算'!$CT$6:$CT$405,0))&"",""),IFERROR(INDEX('計算'!$C$6:$C$405,MATCH(16-MAX('計算'!$CT$6:$CT$405),'計算'!$CU$6:$CU$405,0))&"",""))) | E26: =IF($B26="","",IF(16<=MAX('計算'!$CT$6:$CT$405),IFERROR(INDEX('計算'!$D$6:$D$405,MATCH(16,'計算'!$CT$6:$CT$405,0)),""),IFERROR(INDEX('計算'!$D$6:$D$405,MATCH(16-MAX('計算'!$CT$6:$CT$405),'計算'!$CU$6:$CU$405,0)),""))) | F26: =IF($B26="","",IF(16<=MAX('計算'!$CT$6:$CT$405),IFERROR(INDEX('計算'!$P$6:$P$405,MATCH(16,'計算'!$CT$6:$CT$405,0)),""),IFERROR(INDEX('計算'!$S$6:$S$405,MATCH(16-MAX('計算'!$CT$6:$CT$405),'計算'!$CU$6:$CU$405,0)),""))) | G26: =IF($B26="","",IF(16<=MAX('計算'!$CT$6:$CT$405),IFERROR(INDEX('計算'!$CR$6:$CR$405,MATCH(16,'計算'!$CT$6:$CT$405,0)),""),IFERROR(INDEX('計算'!$CR$6:$CR$405,MATCH(16-MAX('計算'!$CT$6:$CT$405),'計算'!$CU$6:$CU$405,0)),""))) | H26: =IF($B26="","",IF(16<=MAX('計算'!$CT$6:$CT$405),IFERROR(INDEX('計算'!$Q$6:$Q$405,MATCH(16,'計算'!$CT$6:$CT$405,0)),""),IFERROR(INDEX('計算'!$T$6:$T$405,MATCH(16-MAX('計算'!$CT$6:$CT$405),'計算'!$CU$6:$CU$405,0)),""))) | I26: =IF($B26="","",IF(16<=MAX('計算'!$CT$6:$CT$405),IFERROR(INDEX('計算'!$H$6:$H$405,MATCH(16,'計算'!$CT$6:$CT$405,0)),""),IFERROR(INDEX('計算'!$H$6:$H$405,MATCH(16-MAX('計算'!$CT$6:$CT$405),'計算'!$CU$6:$CU$405,0)),""))) | J26: =IF($B26="","",N($H26)*IFERROR(INDEX('計算'!$G$6:$G$405,IF(16<=MAX('計算'!$CT$6:$CT$405),MATCH(16,'計算'!$CT$6:$CT$405,0),MATCH(16-MAX('計算'!$CT$6:$CT$405),'計算'!$CU$6:$CU$405,0))),1)*N($I26))
B27: =IF(17<=MAX('計算'!$CT$6:$CT$405)+MAX('計算'!$CU$6:$CU$405),17,"") | C27: =IF($B27="","",IF(17<=MAX('計算'!$CT$6:$CT$405),IFERROR(INDEX('計算'!$F$6:$F$405,MATCH(17,'計算'!$CT$6:$CT$405,0)),""),IFERROR(INDEX('計算'!$F$6:$F$405,MATCH(17-MAX('計算'!$CT$6:$CT$405),'計算'!$CU$6:$CU$405,0)),""))) | D27: =IF($B27="","",IF(17<=MAX('計算'!$CT$6:$CT$405),IFERROR(INDEX('計算'!$C$6:$C$405,MATCH(17,'計算'!$CT$6:$CT$405,0))&"",""),IFERROR(INDEX('計算'!$C$6:$C$405,MATCH(17-MAX('計算'!$CT$6:$CT$405),'計算'!$CU$6:$CU$405,0))&"",""))) | E27: =IF($B27="","",IF(17<=MAX('計算'!$CT$6:$CT$405),IFERROR(INDEX('計算'!$D$6:$D$405,MATCH(17,'計算'!$CT$6:$CT$405,0)),""),IFERROR(INDEX('計算'!$D$6:$D$405,MATCH(17-MAX('計算'!$CT$6:$CT$405),'計算'!$CU$6:$CU$405,0)),""))) | F27: =IF($B27="","",IF(17<=MAX('計算'!$CT$6:$CT$405),IFERROR(INDEX('計算'!$P$6:$P$405,MATCH(17,'計算'!$CT$6:$CT$405,0)),""),IFERROR(INDEX('計算'!$S$6:$S$405,MATCH(17-MAX('計算'!$CT$6:$CT$405),'計算'!$CU$6:$CU$405,0)),""))) | G27: =IF($B27="","",IF(17<=MAX('計算'!$CT$6:$CT$405),IFERROR(INDEX('計算'!$CR$6:$CR$405,MATCH(17,'計算'!$CT$6:$CT$405,0)),""),IFERROR(INDEX('計算'!$CR$6:$CR$405,MATCH(17-MAX('計算'!$CT$6:$CT$405),'計算'!$CU$6:$CU$405,0)),""))) | H27: =IF($B27="","",IF(17<=MAX('計算'!$CT$6:$CT$405),IFERROR(INDEX('計算'!$Q$6:$Q$405,MATCH(17,'計算'!$CT$6:$CT$405,0)),""),IFERROR(INDEX('計算'!$T$6:$T$405,MATCH(17-MAX('計算'!$CT$6:$CT$405),'計算'!$CU$6:$CU$405,0)),""))) | I27: =IF($B27="","",IF(17<=MAX('計算'!$CT$6:$CT$405),IFERROR(INDEX('計算'!$H$6:$H$405,MATCH(17,'計算'!$CT$6:$CT$405,0)),""),IFERROR(INDEX('計算'!$H$6:$H$405,MATCH(17-MAX('計算'!$CT$6:$CT$405),'計算'!$CU$6:$CU$405,0)),""))) | J27: =IF($B27="","",N($H27)*IFERROR(INDEX('計算'!$G$6:$G$405,IF(17<=MAX('計算'!$CT$6:$CT$405),MATCH(17,'計算'!$CT$6:$CT$405,0),MATCH(17-MAX('計算'!$CT$6:$CT$405),'計算'!$CU$6:$CU$405,0))),1)*N($I27))
B28: =IF(18<=MAX('計算'!$CT$6:$CT$405)+MAX('計算'!$CU$6:$CU$405),18,"") | C28: =IF($B28="","",IF(18<=MAX('計算'!$CT$6:$CT$405),IFERROR(INDEX('計算'!$F$6:$F$405,MATCH(18,'計算'!$CT$6:$CT$405,0)),""),IFERROR(INDEX('計算'!$F$6:$F$405,MATCH(18-MAX('計算'!$CT$6:$CT$405),'計算'!$CU$6:$CU$405,0)),""))) | D28: =IF($B28="","",IF(18<=MAX('計算'!$CT$6:$CT$405),IFERROR(INDEX('計算'!$C$6:$C$405,MATCH(18,'計算'!$CT$6:$CT$405,0))&"",""),IFERROR(INDEX('計算'!$C$6:$C$405,MATCH(18-MAX('計算'!$CT$6:$CT$405),'計算'!$CU$6:$CU$405,0))&"",""))) | E28: =IF($B28="","",IF(18<=MAX('計算'!$CT$6:$CT$405),IFERROR(INDEX('計算'!$D$6:$D$405,MATCH(18,'計算'!$CT$6:$CT$405,0)),""),IFERROR(INDEX('計算'!$D$6:$D$405,MATCH(18-MAX('計算'!$CT$6:$CT$405),'計算'!$CU$6:$CU$405,0)),""))) | F28: =IF($B28="","",IF(18<=MAX('計算'!$CT$6:$CT$405),IFERROR(INDEX('計算'!$P$6:$P$405,MATCH(18,'計算'!$CT$6:$CT$405,0)),""),IFERROR(INDEX('計算'!$S$6:$S$405,MATCH(18-MAX('計算'!$CT$6:$CT$405),'計算'!$CU$6:$CU$405,0)),""))) | G28: =IF($B28="","",IF(18<=MAX('計算'!$CT$6:$CT$405),IFERROR(INDEX('計算'!$CR$6:$CR$405,MATCH(18,'計算'!$CT$6:$CT$405,0)),""),IFERROR(INDEX('計算'!$CR$6:$CR$405,MATCH(18-MAX('計算'!$CT$6:$CT$405),'計算'!$CU$6:$CU$405,0)),""))) | H28: =IF($B28="","",IF(18<=MAX('計算'!$CT$6:$CT$405),IFERROR(INDEX('計算'!$Q$6:$Q$405,MATCH(18,'計算'!$CT$6:$CT$405,0)),""),IFERROR(INDEX('計算'!$T$6:$T$405,MATCH(18-MAX('計算'!$CT$6:$CT$405),'計算'!$CU$6:$CU$405,0)),""))) | I28: =IF($B28="","",IF(18<=MAX('計算'!$CT$6:$CT$405),IFERROR(INDEX('計算'!$H$6:$H$405,MATCH(18,'計算'!$CT$6:$CT$405,0)),""),IFERROR(INDEX('計算'!$H$6:$H$405,MATCH(18-MAX('計算'!$CT$6:$CT$405),'計算'!$CU$6:$CU$405,0)),""))) | J28: =IF($B28="","",N($H28)*IFERROR(INDEX('計算'!$G$6:$G$405,IF(18<=MAX('計算'!$CT$6:$CT$405),MATCH(18,'計算'!$CT$6:$CT$405,0),MATCH(18-MAX('計算'!$CT$6:$CT$405),'計算'!$CU$6:$CU$405,0))),1)*N($I28))
B29: =IF(19<=MAX('計算'!$CT$6:$CT$405)+MAX('計算'!$CU$6:$CU$405),19,"") | C29: =IF($B29="","",IF(19<=MAX('計算'!$CT$6:$CT$405),IFERROR(INDEX('計算'!$F$6:$F$405,MATCH(19,'計算'!$CT$6:$CT$405,0)),""),IFERROR(INDEX('計算'!$F$6:$F$405,MATCH(19-MAX('計算'!$CT$6:$CT$405),'計算'!$CU$6:$CU$405,0)),""))) | D29: =IF($B29="","",IF(19<=MAX('計算'!$CT$6:$CT$405),IFERROR(INDEX('計算'!$C$6:$C$405,MATCH(19,'計算'!$CT$6:$CT$405,0))&"",""),IFERROR(INDEX('計算'!$C$6:$C$405,MATCH(19-MAX('計算'!$CT$6:$CT$405),'計算'!$CU$6:$CU$405,0))&"",""))) | E29: =IF($B29="","",IF(19<=MAX('計算'!$CT$6:$CT$405),IFERROR(INDEX('計算'!$D$6:$D$405,MATCH(19,'計算'!$CT$6:$CT$405,0)),""),IFERROR(INDEX('計算'!$D$6:$D$405,MATCH(19-MAX('計算'!$CT$6:$CT$405),'計算'!$CU$6:$CU$405,0)),""))) | F29: =IF($B29="","",IF(19<=MAX('計算'!$CT$6:$CT$405),IFERROR(INDEX('計算'!$P$6:$P$405,MATCH(19,'計算'!$CT$6:$CT$405,0)),""),IFERROR(INDEX('計算'!$S$6:$S$405,MATCH(19-MAX('計算'!$CT$6:$CT$405),'計算'!$CU$6:$CU$405,0)),""))) | G29: =IF($B29="","",IF(19<=MAX('計算'!$CT$6:$CT$405),IFERROR(INDEX('計算'!$CR$6:$CR$405,MATCH(19,'計算'!$CT$6:$CT$405,0)),""),IFERROR(INDEX('計算'!$CR$6:$CR$405,MATCH(19-MAX('計算'!$CT$6:$CT$405),'計算'!$CU$6:$CU$405,0)),""))) | H29: =IF($B29="","",IF(19<=MAX('計算'!$CT$6:$CT$405),IFERROR(INDEX('計算'!$Q$6:$Q$405,MATCH(19,'計算'!$CT$6:$CT$405,0)),""),IFERROR(INDEX('計算'!$T$6:$T$405,MATCH(19-MAX('計算'!$CT$6:$CT$405),'計算'!$CU$6:$CU$405,0)),""))) | I29: =IF($B29="","",IF(19<=MAX('計算'!$CT$6:$CT$405),IFERROR(INDEX('計算'!$H$6:$H$405,MATCH(19,'計算'!$CT$6:$CT$405,0)),""),IFERROR(INDEX('計算'!$H$6:$H$405,MATCH(19-MAX('計算'!$CT$6:$CT$405),'計算'!$CU$6:$CU$405,0)),""))) | J29: =IF($B29="","",N($H29)*IFERROR(INDEX('計算'!$G$6:$G$405,IF(19<=MAX('計算'!$CT$6:$CT$405),MATCH(19,'計算'!$CT$6:$CT$405,0),MATCH(19-MAX('計算'!$CT$6:$CT$405),'計算'!$CU$6:$CU$405,0))),1)*N($I29))
